Workbook

Sheet Universo DEJAyAM
A1: Codigo | B1: Tipo | C1: Región Educativa | D1: Código Distrito DGCyE | E1: Nombre de Distrito - Partido | F1: CUE | G1: Anexo | H1: Clave | I1: Dependencia | J1: Tipo de Organización | K1: Sede Anexo Extensión | L1: Escuela Sede | M1: Nombre | N1: Ámbito Geográfico | O1: Matrícula Estimada | P1: Modalidad | Q1: Nivel | R1: Matricula Total | S1: Secciones | T1: Universo | U1: Universo_Excl. | V1: Estrato_Oferta | W1: Estrato_GEO | X1: Estrato | Y1: IVSE_T | Z1: ECE | AA1: Distrito _Boleto | AB1: criterios_seleccion_sede | AC1: Casos_Seleccionar_Lista | AD1: Fines_Direccion
A2: =+H2 -> 0043DS0011 | B2: Un.Serv. | C2: 19 | D2: 043 | E2: General Pueyrredón | F2: 609259 | G2: 0 | H2: 0043DS0011 | I2: Oficial | J2: CENTRO ESPECIALIZADO PARA ADULTOS CON ORIENTACIÓN EN SALUD (CEBAS) | K2: SEDE | M2: C.E.B.A.S. N 11 | N2: Urbano | O2: No | P2: Educación de Jóvenes y Adultos | Q2: Nivel Secundario | R2: 97 | S2: 6 | T2: 1 | V2: CEBAS | W2: =+IF(V2="","",IF(MID(V2,1,3)="ECE","UNICO",IF(V2="FINES",CONCATENATE("R",IF(OR(C2="16",C2="21",C2="22",C2="23"),"16212223",IF(OR(C2="15",C2="17",C2="24",C2="25"),"15172425",C2))),IF(V2="CEBAS","UNICO",IF(VALUE(C2)<=11,"AMBA","INTERIOR"))))) -> UNICO | X2: =+IF(V2="","-",CONCATENATE(V2,"_",W2)) -> CEBAS_UNICO | Y2: 0.063379868 | Z2: =+IFERROR(VLOOKUP(H2,#REF!,2,FALSE),"-") -> - | AA2: SIN | AB2: =+IF(W2="","-",IF(W2="UNICO","CENSO","MUESTRA")) -> CENSO | AC2: PRIMEROS | AD2: -
A3: =+H3 -> 0008DS0030 | B3: Un.Serv. | C3: 22 | D3: 008 | E3: Bahía Blanca | F3: 616446 | G3: 0 | H3: 0008DS0030 | I3: Oficial | J3: CENTRO ESPECIALIZADO PARA ADULTOS CON ORIENTACIÓN EN SALUD (CEBAS) | K3: SEDE | M3: C.E.B.A.S. N 30 "ENFERMERAS 1982 POR MALVINAS" | N3: Urbano | O3: No | P3: Educación de Jóvenes y Adultos | Q3: Nivel Secundario | R3: 48 | S3: 3 | T3: 1 | V3: CEBAS | W3: =+IF(V3="","",IF(MID(V3,1,3)="ECE","UNICO",IF(V3="FINES",CONCATENATE("R",IF(OR(C3="16",C3="21",C3="22",C3="23"),"16212223",IF(OR(C3="15",C3="17",C3="24",C3="25"),"15172425",C3))),IF(V3="CEBAS","UNICO",IF(VALUE(C3)<=11,"AMBA","INTERIOR"))))) -> UNICO | X3: =+IF(V3="","-",CONCATENATE(V3,"_",W3)) -> CEBAS_UNICO | Y3: 0.094380705 | Z3: =+IFERROR(VLOOKUP(H3,#REF!,2,FALSE),"-") -> - | AA3: SIN | AB3: =+IF(W3="","-",IF(W3="UNICO","CENSO","MUESTRA")) -> CENSO | AC3: PRIMEROS | AD3: -
A4: =+H4 -> 0062DS0016 | B4: Un.Serv. | C4: 02 | D4: 062 | E4: Lomas de Zamora | F4: 614623 | G4: 0 | H4: 0062DS0016 | I4: Oficial | J4: CENTRO ESPECIALIZADO PARA ADULTOS CON ORIENTACIÓN EN SALUD (CEBAS) | K4: SEDE | M4: C.E.B.A.S N 16 | N4: Urbano | O4: No | P4: Educación de Jóvenes y Adultos | Q4: Nivel Secundario | R4: 63 | S4: 6 | T4: 1 | V4: CEBAS | W4: =+IF(V4="","",IF(MID(V4,1,3)="ECE","UNICO",IF(V4="FINES",CONCATENATE("R",IF(OR(C4="16",C4="21",C4="22",C4="23"),"16212223",IF(OR(C4="15",C4="17",C4="24",C4="25"),"15172425",C4))),IF(V4="CEBAS","UNICO",IF(VALUE(C4)<=11,"AMBA","INTERIOR"))))) -> UNICO | X4: =+IF(V4="","-",CONCATENATE(V4,"_",W4)) -> CEBAS_UNICO | Y4: 0.096115828 | Z4: =+IFERROR(VLOOKUP(H4,#REF!,2,FALSE),"-") -> - | AA4: CON | AB4: =+IF(W4="","-",IF(W4="UNICO","CENSO","MUESTRA")) -> CENSO | AC4: PRIMEROS | AD4: -
A5: =+H5 -> 0111DS0049 | B5: Un.Serv. | C5: 02 | D5: 111 | E5: Lanús | F5: 620507 | G5: 0 | H5: 0111DS0049 | I5: Oficial | J5: CENTRO ESPECIALIZADO PARA ADULTOS CON ORIENTACIÓN EN SALUD (CEBAS) | K5: SEDE | M5: C.E.B.A.S. N 49 | N5: Urbano | O5: No | P5: Educación de Jóvenes y Adultos | Q5: Nivel Secundario | R5: 43 | S5: 3 | T5: 1 | V5: CEBAS | W5: =+IF(V5="","",IF(MID(V5,1,3)="ECE","UNICO",IF(V5="FINES",CONCATENATE("R",IF(OR(C5="16",C5="21",C5="22",C5="23"),"16212223",IF(OR(C5="15",C5="17",C5="24",C5="25"),"15172425",C5))),IF(V5="CEBAS","UNICO",IF(VALUE(C5)<=11,"AMBA","INTERIOR"))))) -> UNICO | X5: =+IF(V5="","-",CONCATENATE(V5,"_",W5)) -> CEBAS_UNICO | Y5: 0.14383187 | Z5: =+IFERROR(VLOOKUP(H5,#REF!,2,FALSE),"-") -> - | AA5: CON | AB5: =+IF(W5="","-",IF(W5="UNICO","CENSO","MUESTRA")) -> CENSO | AC5: ULTIMOS | AD5: -
A6: =+H6 -> 0100DS0028 | B6: Un.Serv. | C6: 08 | D6: 100 | E6: Morón | F6: 616437 | G6: 0 | H6: 0100DS0028 | I6: Oficial | J6: CENTRO ESPECIALIZADO PARA ADULTOS CON ORIENTACIÓN EN SALUD (CEBAS) | K6: SEDE | M6: C.E.B.A.S. N 28 | N6: Urbano | O6: No | P6: Educación de Jóvenes y Adultos | Q6: Nivel Secundario | R6: 109 | S6: 6 | T6: 1 | V6: CEBAS | W6: =+IF(V6="","",IF(MID(V6,1,3)="ECE","UNICO",IF(V6="FINES",CONCATENATE("R",IF(OR(C6="16",C6="21",C6="22",C6="23"),"16212223",IF(OR(C6="15",C6="17",C6="24",C6="25"),"15172425",C6))),IF(V6="CEBAS","UNICO",IF(VALUE(C6)<=11,"AMBA","INTERIOR"))))) -> UNICO | X6: =+IF(V6="","-",CONCATENATE(V6,"_",W6)) -> CEBAS_UNICO | Y6: 0.15550203 | Z6: =+IFERROR(VLOOKUP(H6,#REF!,2,FALSE),"-") -> - | AA6: CON | AB6: =+IF(W6="","-",IF(W6="UNICO","CENSO","MUESTRA")) -> CENSO | AC6: ULTIMOS | AD6: -
A7: =+H7 -> 0032DS0013 | B7: Un.Serv. | C7: 04 | D7: 032 | E7: Florencio Varela | F7: 608715 | G7: 0 | H7: 0032DS0013 | I7: Oficial | J7: CENTRO ESPECIALIZADO PARA ADULTOS CON ORIENTACIÓN EN SALUD (CEBAS) | K7: SEDE | M7: C.E.B.A.S. N 13 | N7: Urbano | O7: No | P7: Educación de Jóvenes y Adultos | Q7: Nivel Secundario | R7: 82 | S7: 3 | T7: 1 | V7: CEBAS | W7: =+IF(V7="","",IF(MID(V7,1,3)="ECE","UNICO",IF(V7="FINES",CONCATENATE("R",IF(OR(C7="16",C7="21",C7="22",C7="23"),"16212223",IF(OR(C7="15",C7="17",C7="24",C7="25"),"15172425",C7))),IF(V7="CEBAS","UNICO",IF(VALUE(C7)<=11,"AMBA","INTERIOR"))))) -> UNICO | X7: =+IF(V7="","-",CONCATENATE(V7,"_",W7)) -> CEBAS_UNICO | Y7: 0.17282251 | Z7: =+IFERROR(VLOOKUP(H7,#REF!,2,FALSE),"-") -> - | AA7: CON | AB7: =+IF(W7="","-",IF(W7="UNICO","CENSO","MUESTRA")) -> CENSO | AC7: PRIMEROS | AD7: -
A8: =+H8 -> 0001DS0001 | B8: Un.Serv. | C8: 01 | D8: 001 | E8: La Plata | F8: 609006 | G8: 0 | H8: 0001DS0001 | I8: Oficial | J8: CENTRO ESPECIALIZADO PARA ADULTOS CON ORIENTACIÓN EN SALUD (CEBAS) | K8: SEDE | M8: C.E.B.A.S. N 1 "FLOREAL FERRARA" | N8: Urbano | O8: No | P8: Educación de Jóvenes y Adultos | Q8: Nivel Secundario | R8: 256 | S8: 9 | T8: 1 | V8: CEBAS | W8: =+IF(V8="","",IF(MID(V8,1,3)="ECE","UNICO",IF(V8="FINES",CONCATENATE("R",IF(OR(C8="16",C8="21",C8="22",C8="23"),"16212223",IF(OR(C8="15",C8="17",C8="24",C8="25"),"15172425",C8))),IF(V8="CEBAS","UNICO",IF(VALUE(C8)<=11,"AMBA","INTERIOR"))))) -> UNICO | X8: =+IF(V8="","-",CONCATENATE(V8,"_",W8)) -> CEBAS_UNICO | Y8: 0.17714942 | Z8: =+IFERROR(VLOOKUP(H8,#REF!,2,FALSE),"-") -> - | AA8: CON | AB8: =+IF(W8="","-",IF(W8="UNICO","CENSO","MUESTRA")) -> CENSO | AC8: PRIMEROS | AD8: -
A9: =+H9 -> 0030DS0041 | B9: Un.Serv. | C9: 05 | D9: 030 | E9: Esteban Echeverría | F9: 620534 | G9: 0 | H9: 0030DS0041 | I9: Oficial | J9: CENTRO ESPECIALIZADO PARA ADULTOS CON ORIENTACIÓN EN SALUD (CEBAS) | K9: SEDE | M9: C.E.B.A.S. N 41 | N9: Urbano | O9: No | P9: Educación de Jóvenes y Adultos | Q9: Nivel Secundario | R9: 33 | S9: 3 | T9: 1 | V9: CEBAS | W9: =+IF(V9="","",IF(MID(V9,1,3)="ECE","UNICO",IF(V9="FINES",CONCATENATE("R",IF(OR(C9="16",C9="21",C9="22",C9="23"),"16212223",IF(OR(C9="15",C9="17",C9="24",C9="25"),"15172425",C9))),IF(V9="CEBAS","UNICO",IF(VALUE(C9)<=11,"AMBA","INTERIOR"))))) -> UNICO | X9: =+IF(V9="","-",CONCATENATE(V9,"_",W9)) -> CEBAS_UNICO | Y9: 0.18888588 | Z9: =+IFERROR(VLOOKUP(H9,#REF!,2,FALSE),"-") -> - | AA9: CON | AB9: =+IF(W9="","-",IF(W9="UNICO","CENSO","MUESTRA")) -> CENSO | AC9: ULTIMOS | AD9: -
A10: =+H10 -> 0094DS0047 | B10: Un.Serv. | C10: 13 | D10: 094 | E10: San Antonio de Areco | F10: 619088 | G10: 0 | H10: 0094DS0047 | I10: Oficial | J10: CENTRO ESPECIALIZADO PARA ADULTOS CON ORIENTACIÓN EN SALUD (CEBAS) | K10: SEDE | M10: C.E.B.A.S. N 47 | N10: Urbano | O10: No | P10: Educación de Jóvenes y Adultos | Q10: Nivel Secundario | R10: 33 | S10: 2 | T10: 1 | V10: CEBAS | W10: =+IF(V10="","",IF(MID(V10,1,3)="ECE","UNICO",IF(V10="FINES",CONCATENATE("R",IF(OR(C10="16",C10="21",C10="22",C10="23"),"16212223",IF(OR(C10="15",C10="17",C10="24",C10="25"),"15172425",C10))),IF(V10="CEBAS","UNICO",IF(VALUE(C10)<=11,"AMBA","INTERIOR"))))) -> UNICO | X10: =+IF(V10="","-",CONCATENATE(V10,"_",W10)) -> CEBAS_UNICO | Y10: 0.18974226 | Z10: =+IFERROR(VLOOKUP(H10,#REF!,2,FALSE),"-") -> - | AA10: SIN | AB10: =+IF(W10="","-",IF(W10="UNICO","CENSO","MUESTRA")) -> CENSO | AC10: ULTIMOS | AD10: -
A11: =+H11 -> 0076DS0019 | B11: Un.Serv. | C11: 15 | D11: 076 | E11: 9 de Julio | F11: 615601 | G11: 0 | H11: 0076DS0019 | I11: Oficial | J11: CENTRO ESPECIALIZADO PARA ADULTOS CON ORIENTACIÓN EN SALUD (CEBAS) | K11: SEDE | M11: C.E.B.A.S. N 19 | N11: Urbano | O11: No | P11: Educación de Jóvenes y Adultos | Q11: Nivel Secundario | R11: 39 | S11: 3 | T11: 1 | V11: CEBAS | W11: =+IF(V11="","",IF(MID(V11,1,3)="ECE","UNICO",IF(V11="FINES",CONCATENATE("R",IF(OR(C11="16",C11="21",C11="22",C11="23"),"16212223",IF(OR(C11="15",C11="17",C11="24",C11="25"),"15172425",C11))),IF(V11="CEBAS","UNICO",IF(VALUE(C11)<=11,"AMBA","INTERIOR"))))) -> UNICO | X11: =+IF(V11="","-",CONCATENATE(V11,"_",W11)) -> CEBAS_UNICO | Y11: 0.19851275 | Z11: =+IFERROR(VLOOKUP(H11,#REF!,2,FALSE),"-") -> - | AA11: SIN | AB11: =+IF(W11="","-",IF(W11="UNICO","CENSO","MUESTRA")) -> CENSO | AC11: ULTIMOS | AD11: -
A12: =+H12 -> 0055DS2370 | B12: Un.Serv. | C12: 06 | D12: 055 | E12: Tigre | F12: 616870 | G12: 1 | H12: 0055DS2370 | I12: Oficial | J12: CENTRO ESPECIALIZADO PARA ADULTOS CON ORIENTACIÓN EN SALUD (CEBAS) | K12: EXTENSION | L12: 0116DS0037 | M12: C.E.B.A.S. N°37 - EXTENSIÓN | N12: Urbano | O12: No | P12: Educación de Jóvenes y Adultos | Q12: Nivel Secundario | R12: 61 | S12: 3 | T12: 1 | V12: CEBAS | W12: =+IF(V12="","",IF(MID(V12,1,3)="ECE","UNICO",IF(V12="FINES",CONCATENATE("R",IF(OR(C12="16",C12="21",C12="22",C12="23"),"16212223",IF(OR(C12="15",C12="17",C12="24",C12="25"),"15172425",C12))),IF(V12="CEBAS","UNICO",IF(VALUE(C12)<=11,"AMBA","INTERIOR"))))) -> UNICO | X12: =+IF(V12="","-",CONCATENATE(V12,"_",W12)) -> CEBAS_UNICO | Y12: 0.20705157 | Z12: =+IFERROR(VLOOKUP(H12,#REF!,2,FALSE),"-") -> - | AA12: CON | AB12: =+IF(W12="","-",IF(W12="UNICO","CENSO","MUESTRA")) -> CENSO | AC12: ULTIMOS | AD12: -
A13: =+H13 -> 0001DS0048 | B13: Un.Serv. | C13: 01 | D13: 001 | E13: La Plata | F13: 620508 | G13: 0 | H13: 0001DS0048 | I13: Oficial | J13: CENTRO ESPECIALIZADO PARA ADULTOS CON ORIENTACIÓN EN SALUD (CEBAS) | K13: SEDE | M13: C.E.B.A.S. N 48 "DR. RENÉ FAVALORO" | N13: Urbano | O13: No | P13: Educación de Jóvenes y Adultos | Q13: Nivel Secundario | R13: 16 | S13: 1 | T13: 1 | V13: CEBAS | W13: =+IF(V13="","",IF(MID(V13,1,3)="ECE","UNICO",IF(V13="FINES",CONCATENATE("R",IF(OR(C13="16",C13="21",C13="22",C13="23"),"16212223",IF(OR(C13="15",C13="17",C13="24",C13="25"),"15172425",C13))),IF(V13="CEBAS","UNICO",IF(VALUE(C13)<=11,"AMBA","INTERIOR"))))) -> UNICO | X13: =+IF(V13="","-",CONCATENATE(V13,"_",W13)) -> CEBAS_UNICO | Y13: 0.25350336 | Z13: =+IFERROR(VLOOKUP(H13,#REF!,2,FALSE),"-") -> - | AA13: CON | AB13: =+IF(W13="","-",IF(W13="UNICO","CENSO","MUESTRA")) -> CENSO | AC13: ULTIMOS | AD13: -
A14: =+H14 -> 0045DS0002 | B14: Un.Serv. | C14: 07 | D14: 045 | E14: General San Martín | F14: 609445 | G14: 0 | H14: 0045DS0002 | I14: Oficial | J14: CENTRO ESPECIALIZADO PARA ADULTOS CON ORIENTACIÓN EN SALUD (CEBAS) | K14: SEDE | M14: C.E.B.A.S. N 2 "EDUCADOR PAULO FREIRE" | N14: Urbano | O14: No | P14: Educación de Jóvenes y Adultos | Q14: Nivel Secundario | R14: 89 | S14: 6 | T14: 1 | V14: CEBAS | W14: =+IF(V14="","",IF(MID(V14,1,3)="ECE","UNICO",IF(V14="FINES",CONCATENATE("R",IF(OR(C14="16",C14="21",C14="22",C14="23"),"16212223",IF(OR(C14="15",C14="17",C14="24",C14="25"),"15172425",C14))),IF(V14="CEBAS","UNICO",IF(VALUE(C14)<=11,"AMBA","INTERIOR"))))) -> UNICO | X14: =+IF(V14="","-",CONCATENATE(V14,"_",W14)) -> CEBAS_UNICO | Y14: 0.28876384 | Z14: =+IFERROR(VLOOKUP(H14,#REF!,2,FALSE),"-") -> - | AA14: CON | AB14: =+IF(W14="","-",IF(W14="UNICO","CENSO","MUESTRA")) -> CENSO | AC14: ULTIMOS | AD14: -
A15: =+H15 -> 0005DS0010 | B15: Un.Serv. | C15: 02 | D15: 005 | E15: Avellaneda | F15: 610303 | G15: 0 | H15: 0005DS0010 | I15: Oficial | J15: CENTRO ESPECIALIZADO PARA ADULTOS CON ORIENTACIÓN EN SALUD (CEBAS) | K15: SEDE | M15: C.E.B.A.S. N 10 | N15: Urbano | O15: No | P15: Educación de Jóvenes y Adultos | Q15: Nivel Secundario | R15: 124 | S15: 6 | T15: 1 | V15: CEBAS | W15: =+IF(V15="","",IF(MID(V15,1,3)="ECE","UNICO",IF(V15="FINES",CONCATENATE("R",IF(OR(C15="16",C15="21",C15="22",C15="23"),"16212223",IF(OR(C15="15",C15="17",C15="24",C15="25"),"15172425",C15))),IF(V15="CEBAS","UNICO",IF(VALUE(C15)<=11,"AMBA","INTERIOR"))))) -> UNICO | X15: =+IF(V15="","-",CONCATENATE(V15,"_",W15)) -> CEBAS_UNICO | Y15: 0.29353985 | Z15: =+IFERROR(VLOOKUP(H15,#REF!,2,FALSE),"-") -> - | AA15: CON | AB15: =+IF(W15="","-",IF(W15="UNICO","CENSO","MUESTRA")) -> CENSO | AC15: PRIMEROS | AD15: -
A16: =+H16 -> 0071DS0029 | B16: Un.Serv. | C16: 08 | D16: 071 | E16: Merlo | F16: 616233 | G16: 0 | H16: 0071DS0029 | I16: Oficial | J16: CENTRO ESPECIALIZADO PARA ADULTOS CON ORIENTACIÓN EN SALUD (CEBAS) | K16: SEDE | M16: C.E.B.A.S. N 29 | N16: Urbano | O16: No | P16: Educación de Jóvenes y Adultos | Q16: Nivel Secundario | R16: 102 | S16: 6 | T16: 1 | V16: CEBAS | W16: =+IF(V16="","",IF(MID(V16,1,3)="ECE","UNICO",IF(V16="FINES",CONCATENATE("R",IF(OR(C16="16",C16="21",C16="22",C16="23"),"16212223",IF(OR(C16="15",C16="17",C16="24",C16="25"),"15172425",C16))),IF(V16="CEBAS","UNICO",IF(VALUE(C16)<=11,"AMBA","INTERIOR"))))) -> UNICO | X16: =+IF(V16="","-",CONCATENATE(V16,"_",W16)) -> CEBAS_UNICO | Y16: 0.3499111 | Z16: =+IFERROR(VLOOKUP(H16,#REF!,2,FALSE),"-") -> - | AA16: CON | AB16: =+IF(W16="","-",IF(W16="UNICO","CENSO","MUESTRA")) -> CENSO | AC16: ULTIMOS | AD16: -
A17: =+H17 -> 0132DS0039 | B17: Un.Serv. | C17: 09 | D17: 132 | E17: José C. Paz | F17: 619103 | G17: 0 | H17: 0132DS0039 | I17: Oficial | J17: CENTRO ESPECIALIZADO PARA ADULTOS CON ORIENTACIÓN EN SALUD (CEBAS) | K17: SEDE | M17: C.E.B.A.S. N 39 | N17: Urbano | O17: No | P17: Educación de Jóvenes y Adultos | Q17: Nivel Secundario | R17: 96 | S17: 6 | T17: 1 | V17: CEBAS | W17: =+IF(V17="","",IF(MID(V17,1,3)="ECE","UNICO",IF(V17="FINES",CONCATENATE("R",IF(OR(C17="16",C17="21",C17="22",C17="23"),"16212223",IF(OR(C17="15",C17="17",C17="24",C17="25"),"15172425",C17))),IF(V17="CEBAS","UNICO",IF(VALUE(C17)<=11,"AMBA","INTERIOR"))))) -> UNICO | X17: =+IF(V17="","-",CONCATENATE(V17,"_",W17)) -> CEBAS_UNICO | Y17: 0.41227043 | Z17: =+IFERROR(VLOOKUP(H17,#REF!,2,FALSE),"-") -> - | AA17: CON | AB17: =+IF(W17="","-",IF(W17="UNICO","CENSO","MUESTRA")) -> CENSO | AC17: PRIMEROS | AD17: -
A18: =+H18 -> 0116DS0037 | B18: Un.Serv. | C18: 11 | D18: 116 | E18: Escobar | F18: 616870 | G18: 0 | H18: 0116DS0037 | I18: Oficial | J18: CENTRO ESPECIALIZADO PARA ADULTOS CON ORIENTACIÓN EN SALUD (CEBAS) | K18: SEDE | M18: C.E.B.A.S. N 37 | N18: Urbano | O18: No | P18: Educación de Jóvenes y Adultos | Q18: Nivel Secundario | R18: 54 | S18: 3 | T18: 1 | V18: CEBAS | W18: =+IF(V18="","",IF(MID(V18,1,3)="ECE","UNICO",IF(V18="FINES",CONCATENATE("R",IF(OR(C18="16",C18="21",C18="22",C18="23"),"16212223",IF(OR(C18="15",C18="17",C18="24",C18="25"),"15172425",C18))),IF(V18="CEBAS","UNICO",IF(VALUE(C18)<=11,"AMBA","INTERIOR"))))) -> UNICO | X18: =+IF(V18="","-",CONCATENATE(V18,"_",W18)) -> CEBAS_UNICO | Y18: 0.46929595 | Z18: =+IFERROR(VLOOKUP(H18,#REF!,2,FALSE),"-") -> - | AA18: CON | AB18: =+IF(W18="","-",IF(W18="UNICO","CENSO","MUESTRA")) -> CENSO | AC18: ULTIMOS | AD18: -
A19: =+H19 -> 0119DS0017 | B19: Un.Serv. | C19: 04 | D19: 119 | E19: Berazategui | F19: 614624 | G19: 0 | H19: 0119DS0017 | I19: Oficial | J19: CENTRO ESPECIALIZADO PARA ADULTOS CON ORIENTACIÓN EN SALUD (CEBAS) | K19: SEDE | M19: C.E.B.A.S. N 17 | N19: Urbano | O19: No | P19: Educación de Jóvenes y Adultos | Q19: Nivel Secundario | R19: 86 | S19: 6 | T19: 1 | V19: CEBAS | W19: =+IF(V19="","",IF(MID(V19,1,3)="ECE","UNICO",IF(V19="FINES",CONCATENATE("R",IF(OR(C19="16",C19="21",C19="22",C19="23"),"16212223",IF(OR(C19="15",C19="17",C19="24",C19="25"),"15172425",C19))),IF(V19="CEBAS","UNICO",IF(VALUE(C19)<=11,"AMBA","INTERIOR"))))) -> UNICO | X19: =+IF(V19="","-",CONCATENATE(V19,"_",W19)) -> CEBAS_UNICO | Y19: 0.47318311 | Z19: =+IFERROR(VLOOKUP(H19,#REF!,2,FALSE),"-") -> - | AA19: CON | AB19: =+IF(W19="","-",IF(W19="UNICO","CENSO","MUESTRA")) -> CENSO | AC19: PRIMEROS | AD19: -
A20: =+H20 -> 0001DS2480 | B20: Un.Serv. | C20: 01 | D20: 001 | E20: La Plata | F20: 620508 | G20: 1 | H20: 0001DS2480 | I20: Oficial | J20: CENTRO ESPECIALIZADO PARA ADULTOS CON ORIENTACIÓN EN SALUD (CEBAS) | K20: EXTENSION | L20: 0001DS0048 | M20: C.E.B.A.S. N 48 - EXTENSIÓN N 2480 | N20: Urbano | O20: No | P20: Educación de Jóvenes y Adultos | Q20: Nivel Secundario | R20: 77 | S20: 3 | T20: 1 | V20: CEBAS | W20: =+IF(V20="","",IF(MID(V20,1,3)="ECE","UNICO",IF(V20="FINES",CONCATENATE("R",IF(OR(C20="16",C20="21",C20="22",C20="23"),"16212223",IF(OR(C20="15",C20="17",C20="24",C20="25"),"15172425",C20))),IF(V20="CEBAS","UNICO",IF(VALUE(C20)<=11,"AMBA","INTERIOR"))))) -> UNICO | X20: =+IF(V20="","-",CONCATENATE(V20,"_",W20)) -> CEBAS_UNICO | Y20: 0.62820226 | Z20: =+IFERROR(VLOOKUP(H20,#REF!,2,FALSE),"-") -> - | AA20: CON | AB20: =+IF(W20="","-",IF(W20="UNICO","CENSO","MUESTRA")) -> CENSO | AC20: PRIMEROS | AD20: -
A21: =+H21 -> 0069DS0004 | B21: Un.Serv. | C21: 03 | D21: 069 | E21: La Matanza | F21: 607939 | G21: 0 | H21: 0069DS0004 | I21: Oficial | J21: CENTRO ESPECIALIZADO PARA ADULTOS CON ORIENTACIÓN EN SALUD (CEBAS) | K21: SEDE | M21: C.E.B.A.S. N 4 "IRMA LACIAR" | N21: Urbano | O21: No | P21: Educación de Jóvenes y Adultos | Q21: Nivel Secundario | R21: 82 | S21: 6 | T21: 1 | V21: CEBAS | W21: =+IF(V21="","",IF(MID(V21,1,3)="ECE","UNICO",IF(V21="FINES",CONCATENATE("R",IF(OR(C21="16",C21="21",C21="22",C21="23"),"16212223",IF(OR(C21="15",C21="17",C21="24",C21="25"),"15172425",C21))),IF(V21="CEBAS","UNICO",IF(VALUE(C21)<=11,"AMBA","INTERIOR"))))) -> UNICO | X21: =+IF(V21="","-",CONCATENATE(V21,"_",W21)) -> CEBAS_UNICO | Y21: 0.6792475 | Z21: =+IFERROR(VLOOKUP(H21,#REF!,2,FALSE),"-") -> - | AA21: CON | AB21: =+IF(W21="","-",IF(W21="UNICO","CENSO","MUESTRA")) -> CENSO | AC21: ULTIMOS | AD21: -
A22: =+H22 -> 0109DM0452 | B22: Un.Serv. | C22: 06 | D22: 109 | E22: Vicente López | F22: 623684 | G22: 0 | H22: 0109DM0452 | I22: Oficial | J22: CENTRO EDUCATIVO DE NIVEL SECUNDARIO (C.E.N.S.) | K22: SEDE | M22: CENS 452 "JORGE ALBERTO TAIANA" | N22: Urbano | O22: No | P22: Educación de Jóvenes y Adultos | Q22: Nivel Secundario | R22: 118 | S22: 9 | T22: 1 | V22: CENS | W22: =+IF(V22="","",IF(MID(V22,1,3)="ECE","UNICO",IF(V22="FINES",CONCATENATE("R",IF(OR(C22="16",C22="21",C22="22",C22="23"),"16212223",IF(OR(C22="15",C22="17",C22="24",C22="25"),"15172425",C22))),IF(V22="CEBAS","UNICO",IF(VALUE(C22)<=11,"AMBA","INTERIOR"))))) -> AMBA | X22: =+IF(V22="","-",CONCATENATE(V22,"_",W22)) -> CENS_AMBA | Y22: 0.018129991 | Z22: =+IFERROR(VLOOKUP(H22,#REF!,2,FALSE),"-") -> - | AA22: CON | AB22: =+IF(W22="","-",IF(W22="UNICO","CENSO","MUESTRA")) -> MUESTRA | AC22: PRIMEROS | AD22: -
A23: =+H23 -> 0062DM0456 | B23: Un.Serv. | C23: 02 | D23: 062 | E23: Lomas de Zamora | F23: 602517 | G23: 0 | H23: 0062DM0456 | I23: Oficial | J23: CENTRO EDUCATIVO DE NIVEL SECUNDARIO (C.E.N.S.) | K23: SEDE | M23: CENS 456 | N23: Urbano | O23: No | P23: Educación de Jóvenes y Adultos | Q23: Nivel Secundario | R23: 398 | S23: 24 | T23: 1 | V23: CENS | W23: =+IF(V23="","",IF(MID(V23,1,3)="ECE","UNICO",IF(V23="FINES",CONCATENATE("R",IF(OR(C23="16",C23="21",C23="22",C23="23"),"16212223",IF(OR(C23="15",C23="17",C23="24",C23="25"),"15172425",C23))),IF(V23="CEBAS","UNICO",IF(VALUE(C23)<=11,"AMBA","INTERIOR"))))) -> AMBA | X23: =+IF(V23="","-",CONCATENATE(V23,"_",W23)) -> CENS_AMBA | Y23: 0.078160366 | Z23: =+IFERROR(VLOOKUP(H23,#REF!,2,FALSE),"-") -> - | AA23: CON | AB23: =+IF(W23="","-",IF(W23="UNICO","CENSO","MUESTRA")) -> MUESTRA | AC23: PRIMEROS | AD23: -
A24: =+H24 -> 0045DM0452 | B24: Un.Serv. | C24: 07 | D24: 045 | E24: General San Martín | F24: 604217 | G24: 0 | H24: 0045DM0452 | I24: Oficial | J24: CENTRO EDUCATIVO DE NIVEL SECUNDARIO (C.E.N.S.) | K24: SEDE | M24: CENS 452 | N24: Urbano | O24: Sí | P24: Educación de Jóvenes y Adultos | Q24: Nivel Secundario | R24: 238 | S24: 13 | T24: 1 | V24: CENS | W24: =+IF(V24="","",IF(MID(V24,1,3)="ECE","UNICO",IF(V24="FINES",CONCATENATE("R",IF(OR(C24="16",C24="21",C24="22",C24="23"),"16212223",IF(OR(C24="15",C24="17",C24="24",C24="25"),"15172425",C24))),IF(V24="CEBAS","UNICO",IF(VALUE(C24)<=11,"AMBA","INTERIOR"))))) -> AMBA | X24: =+IF(V24="","-",CONCATENATE(V24,"_",W24)) -> CENS_AMBA | Y24: 0.079491764 | Z24: =+IFERROR(VLOOKUP(H24,#REF!,2,FALSE),"-") -> - | AA24: CON | AB24: =+IF(W24="","-",IF(W24="UNICO","CENSO","MUESTRA")) -> MUESTRA | AC24: ULTIMOS | AD24: -
A25: =+H25 -> 0100DM0458 | B25: Un.Serv. | C25: 08 | D25: 100 | E25: Morón | F25: 623719 | G25: 0 | H25: 0100DM0458 | I25: Oficial | J25: CENTRO EDUCATIVO DE NIVEL SECUNDARIO (C.E.N.S.) | K25: SEDE | M25: CENS 458 | N25: Urbano | O25: No | P25: Educación de Jóvenes y Adultos | Q25: Nivel Secundario | R25: 123 | S25: 11 | T25: 1 | V25: CENS | W25: =+IF(V25="","",IF(MID(V25,1,3)="ECE","UNICO",IF(V25="FINES",CONCATENATE("R",IF(OR(C25="16",C25="21",C25="22",C25="23"),"16212223",IF(OR(C25="15",C25="17",C25="24",C25="25"),"15172425",C25))),IF(V25="CEBAS","UNICO",IF(VALUE(C25)<=11,"AMBA","INTERIOR"))))) -> AMBA | X25: =+IF(V25="","-",CONCATENATE(V25,"_",W25)) -> CENS_AMBA | Y25: 0.09014573 | Z25: =+IFERROR(VLOOKUP(H25,#REF!,2,FALSE),"-") -> - | AA25: CON | AB25: =+IF(W25="","-",IF(W25="UNICO","CENSO","MUESTRA")) -> MUESTRA | AC25: PRIMEROS | AD25: -
A26: =+H26 -> 0096DM0458 | B26: Un.Serv. | C26: 06 | D26: 096 | E26: San Isidro | F26: 623674 | G26: 0 | H26: 0096DM0458 | I26: Oficial | J26: CENTRO EDUCATIVO DE NIVEL SECUNDARIO (C.E.N.S.) | K26: SEDE | M26: CENS 458 | N26: Urbano | O26: No | P26: Educación de Jóvenes y Adultos | Q26: Nivel Secundario | R26: 201 | S26: 9 | T26: 1 | V26: CENS | W26: =+IF(V26="","",IF(MID(V26,1,3)="ECE","UNICO",IF(V26="FINES",CONCATENATE("R",IF(OR(C26="16",C26="21",C26="22",C26="23"),"16212223",IF(OR(C26="15",C26="17",C26="24",C26="25"),"15172425",C26))),IF(V26="CEBAS","UNICO",IF(VALUE(C26)<=11,"AMBA","INTERIOR"))))) -> AMBA | X26: =+IF(V26="","-",CONCATENATE(V26,"_",W26)) -> CENS_AMBA | Y26: 0.094259013 | Z26: =+IFERROR(VLOOKUP(H26,#REF!,2,FALSE),"-") -> - | AA26: CON | AB26: =+IF(W26="","-",IF(W26="UNICO","CENSO","MUESTRA")) -> MUESTRA | AC26: PRIMEROS | AD26: -
A27: =+H27 -> 0001DM0465 | B27: Un.Serv. | C27: 01 | D27: 001 | E27: La Plata | F27: 623591 | G27: 0 | H27: 0001DM0465 | I27: Oficial | J27: CENTRO EDUCATIVO DE NIVEL SECUNDARIO (C.E.N.S.) | K27: SEDE | M27: CENS 465 | N27: Urbano | O27: No | P27: Educación de Jóvenes y Adultos | Q27: Nivel Secundario | R27: 63 | S27: 8 | T27: 1 | V27: CENS | W27: =+IF(V27="","",IF(MID(V27,1,3)="ECE","UNICO",IF(V27="FINES",CONCATENATE("R",IF(OR(C27="16",C27="21",C27="22",C27="23"),"16212223",IF(OR(C27="15",C27="17",C27="24",C27="25"),"15172425",C27))),IF(V27="CEBAS","UNICO",IF(VALUE(C27)<=11,"AMBA","INTERIOR"))))) -> AMBA | X27: =+IF(V27="","-",CONCATENATE(V27,"_",W27)) -> CENS_AMBA | Y27: 0.099921968 | Z27: =+IFERROR(VLOOKUP(H27,#REF!,2,FALSE),"-") -> - | AA27: CON | AB27: =+IF(W27="","-",IF(W27="UNICO","CENSO","MUESTRA")) -> MUESTRA | AC27: PRIMEROS | AD27: -
A28: =+H28 -> 0111DM0457 | B28: Un.Serv. | C28: 02 | D28: 111 | E28: Lanús | F28: 623599 | G28: 0 | H28: 0111DM0457 | I28: Oficial | J28: CENTRO EDUCATIVO DE NIVEL SECUNDARIO (C.E.N.S.) | K28: SEDE | M28: CENS 457 "MARY SÁNCHEZ" | N28: Urbano | O28: No | P28: Educación de Jóvenes y Adultos | Q28: Nivel Secundario | R28: 299 | S28: 12 | T28: 1 | V28: CENS | W28: =+IF(V28="","",IF(MID(V28,1,3)="ECE","UNICO",IF(V28="FINES",CONCATENATE("R",IF(OR(C28="16",C28="21",C28="22",C28="23"),"16212223",IF(OR(C28="15",C28="17",C28="24",C28="25"),"15172425",C28))),IF(V28="CEBAS","UNICO",IF(VALUE(C28)<=11,"AMBA","INTERIOR"))))) -> AMBA | X28: =+IF(V28="","-",CONCATENATE(V28,"_",W28)) -> CENS_AMBA | Y28: 0.10202887 | Z28: =+IFERROR(VLOOKUP(H28,#REF!,2,FALSE),"-") -> - | AA28: CON | AB28: =+IF(W28="","-",IF(W28="UNICO","CENSO","MUESTRA")) -> MUESTRA | AC28: PRIMEROS | AD28: -
A29: =+H29 -> 0001DM0476 | B29: Un.Serv. | C29: 01 | D29: 001 | E29: La Plata | F29: 624407 | G29: 0 | H29: 0001DM0476 | I29: Oficial | J29: CENTRO EDUCATIVO DE NIVEL SECUNDARIO (C.E.N.S.) | K29: SEDE | M29: CENS 476 | N29: Urbano | O29: No | P29: Educación de Jóvenes y Adultos | Q29: Nivel Secundario | R29: 64 | S29: 9 | T29: 1 | V29: CENS | W29: =+IF(V29="","",IF(MID(V29,1,3)="ECE","UNICO",IF(V29="FINES",CONCATENATE("R",IF(OR(C29="16",C29="21",C29="22",C29="23"),"16212223",IF(OR(C29="15",C29="17",C29="24",C29="25"),"15172425",C29))),IF(V29="CEBAS","UNICO",IF(VALUE(C29)<=11,"AMBA","INTERIOR"))))) -> AMBA | X29: =+IF(V29="","-",CONCATENATE(V29,"_",W29)) -> CENS_AMBA | Y29: 0.10650747 | Z29: =+IFERROR(VLOOKUP(H29,#REF!,2,FALSE),"-") -> - | AA29: CON | AB29: =+IF(W29="","-",IF(W29="UNICO","CENSO","MUESTRA")) -> MUESTRA | AC29: ULTIMOS | AD29: -
A30: =+H30 -> 0062DM0452 | B30: Un.Serv. | C30: 02 | D30: 062 | E30: Lomas de Zamora | F30: 602730 | G30: 0 | H30: 0062DM0452 | I30: Oficial | J30: CENTRO EDUCATIVO DE NIVEL SECUNDARIO (C.E.N.S.) | K30: SEDE | M30: CENS 452 | N30: Urbano | O30: No | P30: Educación de Jóvenes y Adultos | Q30: Nivel Secundario | R30: 252 | S30: 21 | T30: 1 | V30: CENS | W30: =+IF(V30="","",IF(MID(V30,1,3)="ECE","UNICO",IF(V30="FINES",CONCATENATE("R",IF(OR(C30="16",C30="21",C30="22",C30="23"),"16212223",IF(OR(C30="15",C30="17",C30="24",C30="25"),"15172425",C30))),IF(V30="CEBAS","UNICO",IF(VALUE(C30)<=11,"AMBA","INTERIOR"))))) -> AMBA | X30: =+IF(V30="","-",CONCATENATE(V30,"_",W30)) -> CENS_AMBA | Y30: 0.11244939 | Z30: =+IFERROR(VLOOKUP(H30,#REF!,2,FALSE),"-") -> - | AA30: CON | AB30: =+IF(W30="","-",IF(W30="UNICO","CENSO","MUESTRA")) -> MUESTRA | AC30: ULTIMOS | AD30: -
A31: =+H31 -> 0062DM3724 | B31: Un.Serv. | C31: 02 | D31: 062 | E31: Lomas de Zamora | F31: 624645 | G31: 4 | H31: 0062DM3724 | I31: Oficial | J31: CENTRO EDUCATIVO DE NIVEL SECUNDARIO (C.E.N.S.) | K31: ANEXO | L31: 0062DM0472 | M31: CENS 472 - ANEXO 4 | N31: Urbano | O31: No | P31: Educación de Jóvenes y Adultos | Q31: Nivel Secundario | R31: 39 | S31: 3 | T31: 1 | V31: CENS | W31: =+IF(V31="","",IF(MID(V31,1,3)="ECE","UNICO",IF(V31="FINES",CONCATENATE("R",IF(OR(C31="16",C31="21",C31="22",C31="23"),"16212223",IF(OR(C31="15",C31="17",C31="24",C31="25"),"15172425",C31))),IF(V31="CEBAS","UNICO",IF(VALUE(C31)<=11,"AMBA","INTERIOR"))))) -> AMBA | X31: =+IF(V31="","-",CONCATENATE(V31,"_",W31)) -> CENS_AMBA | Y31: 0.11556709 | Z31: =+IFERROR(VLOOKUP(H31,#REF!,2,FALSE),"-") -> - | AA31: CON | AB31: =+IF(W31="","-",IF(W31="UNICO","CENSO","MUESTRA")) -> MUESTRA | AC31: ULTIMOS | AD31: -
A32: =+H32 -> 0001DM0469 | B32: Un.Serv. | C32: 01 | D32: 001 | E32: La Plata | F32: 606407 | G32: 0 | H32: 0001DM0469 | I32: Oficial | J32: CENTRO EDUCATIVO DE NIVEL SECUNDARIO (C.E.N.S.) | K32: SEDE | M32: CENS 469 "ALICIA MOREAU DE JUSTO" | N32: Urbano | O32: No | P32: Educación de Jóvenes y Adultos | Q32: Nivel Secundario | R32: 167 | S32: 11 | T32: 1 | V32: CENS | W32: =+IF(V32="","",IF(MID(V32,1,3)="ECE","UNICO",IF(V32="FINES",CONCATENATE("R",IF(OR(C32="16",C32="21",C32="22",C32="23"),"16212223",IF(OR(C32="15",C32="17",C32="24",C32="25"),"15172425",C32))),IF(V32="CEBAS","UNICO",IF(VALUE(C32)<=11,"AMBA","INTERIOR"))))) -> AMBA | X32: =+IF(V32="","-",CONCATENATE(V32,"_",W32)) -> CENS_AMBA | Y32: 0.11938538 | Z32: =+IFERROR(VLOOKUP(H32,#REF!,2,FALSE),"-") -> - | AA32: CON | AB32: =+IF(W32="","-",IF(W32="UNICO","CENSO","MUESTRA")) -> MUESTRA | AC32: ULTIMOS | AD32: -
A33: =+H33 -> 0001DM0453 | B33: Un.Serv. | C33: 01 | D33: 001 | E33: La Plata | F33: 620391 | G33: 0 | H33: 0001DM0453 | I33: Oficial | J33: CENTRO EDUCATIVO DE NIVEL SECUNDARIO (C.E.N.S.) | K33: SEDE | M33: CENS 453 | N33: Urbano | O33: No | P33: Educación de Jóvenes y Adultos | Q33: Nivel Secundario | R33: 234 | S33: 11 | T33: 1 | V33: CENS | W33: =+IF(V33="","",IF(MID(V33,1,3)="ECE","UNICO",IF(V33="FINES",CONCATENATE("R",IF(OR(C33="16",C33="21",C33="22",C33="23"),"16212223",IF(OR(C33="15",C33="17",C33="24",C33="25"),"15172425",C33))),IF(V33="CEBAS","UNICO",IF(VALUE(C33)<=11,"AMBA","INTERIOR"))))) -> AMBA | X33: =+IF(V33="","-",CONCATENATE(V33,"_",W33)) -> CENS_AMBA | Y33: 0.12524939 | Z33: =+IFERROR(VLOOKUP(H33,#REF!,2,FALSE),"-") -> - | AA33: CON | AB33: =+IF(W33="","-",IF(W33="UNICO","CENSO","MUESTRA")) -> MUESTRA | AC33: ULTIMOS | AD33: -
A34: =+H34 -> 0045DM0458 | B34: Un.Serv. | C34: 07 | D34: 045 | E34: General San Martín | F34: 614694 | G34: 0 | H34: 0045DM0458 | I34: Oficial | J34: CENTRO EDUCATIVO DE NIVEL SECUNDARIO (C.E.N.S.) | K34: SEDE | M34: CENS 458 "PROFESOR RAMÓN CARRILLO" | N34: Urbano | O34: No | P34: Educación de Jóvenes y Adultos | Q34: Nivel Secundario | R34: 142 | S34: 8 | T34: 1 | V34: CENS | W34: =+IF(V34="","",IF(MID(V34,1,3)="ECE","UNICO",IF(V34="FINES",CONCATENATE("R",IF(OR(C34="16",C34="21",C34="22",C34="23"),"16212223",IF(OR(C34="15",C34="17",C34="24",C34="25"),"15172425",C34))),IF(V34="CEBAS","UNICO",IF(VALUE(C34)<=11,"AMBA","INTERIOR"))))) -> AMBA | X34: =+IF(V34="","-",CONCATENATE(V34,"_",W34)) -> CENS_AMBA | Y34: 0.12557191 | Z34: =+IFERROR(VLOOKUP(H34,#REF!,2,FALSE),"-") -> - | AA34: CON | AB34: =+IF(W34="","-",IF(W34="UNICO","CENSO","MUESTRA")) -> MUESTRA | AC34: PRIMEROS | AD34: -
A35: =+H35 -> 0001DM0463 | B35: Un.Serv. | C35: 01 | D35: 001 | E35: La Plata | F35: 602865 | G35: 0 | H35: 0001DM0463 | I35: Oficial | J35: CENTRO EDUCATIVO DE NIVEL SECUNDARIO (C.E.N.S.) | K35: SEDE | M35: CENS 463 | N35: Urbano | O35: No | P35: Educación de Jóvenes y Adultos | Q35: Nivel Secundario | R35: 136 | S35: 17 | T35: 1 | V35: CENS | W35: =+IF(V35="","",IF(MID(V35,1,3)="ECE","UNICO",IF(V35="FINES",CONCATENATE("R",IF(OR(C35="16",C35="21",C35="22",C35="23"),"16212223",IF(OR(C35="15",C35="17",C35="24",C35="25"),"15172425",C35))),IF(V35="CEBAS","UNICO",IF(VALUE(C35)<=11,"AMBA","INTERIOR"))))) -> AMBA | X35: =+IF(V35="","-",CONCATENATE(V35,"_",W35)) -> CENS_AMBA | Y35: 0.12561181 | Z35: =+IFERROR(VLOOKUP(H35,#REF!,2,FALSE),"-") -> - | AA35: CON | AB35: =+IF(W35="","-",IF(W35="UNICO","CENSO","MUESTRA")) -> MUESTRA | AC35: PRIMEROS | AD35: -
A36: =+H36 -> 0001DM0468 | B36: Un.Serv. | C36: 01 | D36: 001 | E36: La Plata | F36: 608823 | G36: 0 | H36: 0001DM0468 | I36: Oficial | J36: CENTRO EDUCATIVO DE NIVEL SECUNDARIO (C.E.N.S.) | K36: SEDE | M36: CENS 468 | N36: Urbano | O36: No | P36: Educación de Jóvenes y Adultos | Q36: Nivel Secundario | R36: 83 | S36: 6 | T36: 1 | V36: CENS | W36: =+IF(V36="","",IF(MID(V36,1,3)="ECE","UNICO",IF(V36="FINES",CONCATENATE("R",IF(OR(C36="16",C36="21",C36="22",C36="23"),"16212223",IF(OR(C36="15",C36="17",C36="24",C36="25"),"15172425",C36))),IF(V36="CEBAS","UNICO",IF(VALUE(C36)<=11,"AMBA","INTERIOR"))))) -> AMBA | X36: =+IF(V36="","-",CONCATENATE(V36,"_",W36)) -> CENS_AMBA | Y36: 0.12627655 | Z36: =+IFERROR(VLOOKUP(H36,#REF!,2,FALSE),"-") -> - | AA36: CON | AB36: =+IF(W36="","-",IF(W36="UNICO","CENSO","MUESTRA")) -> MUESTRA | AC36: PRIMEROS | AD36: -
A37: =+H37 -> 0069DM0485 | B37: Un.Serv. | C37: 03 | D37: 069 | E37: La Matanza | F37: 623614 | G37: 0 | H37: 0069DM0485 | I37: Oficial | J37: CENTRO EDUCATIVO DE NIVEL SECUNDARIO (C.E.N.S.) | K37: SEDE | M37: CENS 485 "CLAUDIA FALCONE" | N37: Urbano | O37: No | P37: Educación de Jóvenes y Adultos | Q37: Nivel Secundario | R37: 115 | S37: 9 | T37: 1 | V37: CENS | W37: =+IF(V37="","",IF(MID(V37,1,3)="ECE","UNICO",IF(V37="FINES",CONCATENATE("R",IF(OR(C37="16",C37="21",C37="22",C37="23"),"16212223",IF(OR(C37="15",C37="17",C37="24",C37="25"),"15172425",C37))),IF(V37="CEBAS","UNICO",IF(VALUE(C37)<=11,"AMBA","INTERIOR"))))) -> AMBA | X37: =+IF(V37="","-",CONCATENATE(V37,"_",W37)) -> CENS_AMBA | Y37: 0.12728534 | Z37: =+IFERROR(VLOOKUP(H37,#REF!,2,FALSE),"-") -> - | AA37: CON | AB37: =+IF(W37="","-",IF(W37="UNICO","CENSO","MUESTRA")) -> MUESTRA | AC37: ULTIMOS | AD37: -
A38: =+H38 -> 0117DM0452 | B38: Un.Serv. | C38: 07 | D38: 117 | E38: Tres de Febrero | F38: 623693 | G38: 0 | H38: 0117DM0452 | I38: Oficial | J38: CENTRO EDUCATIVO DE NIVEL SECUNDARIO (C.E.N.S.) | K38: SEDE | M38: CENS 452 "RENÉ FAVALORO" | N38: Urbano | O38: Sí | P38: Educación de Jóvenes y Adultos | Q38: Nivel Secundario | R38: 165 | S38: 8 | T38: 1 | V38: CENS | W38: =+IF(V38="","",IF(MID(V38,1,3)="ECE","UNICO",IF(V38="FINES",CONCATENATE("R",IF(OR(C38="16",C38="21",C38="22",C38="23"),"16212223",IF(OR(C38="15",C38="17",C38="24",C38="25"),"15172425",C38))),IF(V38="CEBAS","UNICO",IF(VALUE(C38)<=11,"AMBA","INTERIOR"))))) -> AMBA | X38: =+IF(V38="","-",CONCATENATE(V38,"_",W38)) -> CENS_AMBA | Y38: 0.12868268 | Z38: =+IFERROR(VLOOKUP(H38,#REF!,2,FALSE),"-") -> - | AA38: CON | AB38: =+IF(W38="","-",IF(W38="UNICO","CENSO","MUESTRA")) -> MUESTRA | AC38: ULTIMOS | AD38: -
A39: =+H39 -> 0111DM0452 | B39: Un.Serv. | C39: 02 | D39: 111 | E39: Lanús | F39: 605065 | G39: 0 | H39: 0111DM0452 | I39: Oficial | J39: CENTRO EDUCATIVO DE NIVEL SECUNDARIO (C.E.N.S.) | K39: SEDE | M39: CENS 452 | N39: Urbano | O39: No | P39: Educación de Jóvenes y Adultos | Q39: Nivel Secundario | R39: 556 | S39: 64 | T39: 1 | V39: CENS | W39: =+IF(V39="","",IF(MID(V39,1,3)="ECE","UNICO",IF(V39="FINES",CONCATENATE("R",IF(OR(C39="16",C39="21",C39="22",C39="23"),"16212223",IF(OR(C39="15",C39="17",C39="24",C39="25"),"15172425",C39))),IF(V39="CEBAS","UNICO",IF(VALUE(C39)<=11,"AMBA","INTERIOR"))))) -> AMBA | X39: =+IF(V39="","-",CONCATENATE(V39,"_",W39)) -> CENS_AMBA | Y39: 0.13554969 | Z39: =+IFERROR(VLOOKUP(H39,#REF!,2,FALSE),"-") -> - | AA39: CON | AB39: =+IF(W39="","-",IF(W39="UNICO","CENSO","MUESTRA")) -> MUESTRA | AC39: PRIMEROS | AD39: -
A40: =+H40 -> 0096DM0452 | B40: Un.Serv. | C40: 06 | D40: 096 | E40: San Isidro | F40: 614309 | G40: 0 | H40: 0096DM0452 | I40: Oficial | J40: CENTRO EDUCATIVO DE NIVEL SECUNDARIO (C.E.N.S.) | K40: SEDE | M40: CENS 452 "DR. RAÚL RICARDO ALFONSÍN" | N40: Urbano | O40: No | P40: Educación de Jóvenes y Adultos | Q40: Nivel Secundario | R40: 146 | S40: 9 | T40: 1 | V40: CENS | W40: =+IF(V40="","",IF(MID(V40,1,3)="ECE","UNICO",IF(V40="FINES",CONCATENATE("R",IF(OR(C40="16",C40="21",C40="22",C40="23"),"16212223",IF(OR(C40="15",C40="17",C40="24",C40="25"),"15172425",C40))),IF(V40="CEBAS","UNICO",IF(VALUE(C40)<=11,"AMBA","INTERIOR"))))) -> AMBA | X40: =+IF(V40="","-",CONCATENATE(V40,"_",W40)) -> CENS_AMBA | Y40: 0.13575546 | Z40: =+IFERROR(VLOOKUP(H40,#REF!,2,FALSE),"-") -> - | AA40: CON | AB40: =+IF(W40="","-",IF(W40="UNICO","CENSO","MUESTRA")) -> MUESTRA | AC40: PRIMEROS | AD40: -
...

Sheet MARCO
A1: Codigo | B1: Tipo | C1: Región Educativa | D1: Código Distrito DGCyE | E1: Nombre de Distrito - Partido | F1: CUE | G1: Anexo | H1: Clave | I1: Dependencia | J1: Tipo de Organización | K1: Sede Anexo Extensión | L1: Escuela Sede | M1: Nombre | N1: Ámbito Geográfico | O1: Matrícula Estimada | P1: Modalidad | Q1: Nivel | R1: Matricula Total | S1: Secciones | T1: Universo | U1: Universo_Excl. | V1: Estrato_Oferta | W1: Estrato_GEO | X1: Estrato | Y1: IVSE_T | Z1: ECE | AA1: Distrito _Boleto | AB1: criterios_seleccion_sede | AC1: Casos_Seleccionar_Lista | AD1: Fines_Direccion | AE1: Fines_Módulo | AF1: Prueba_Piloto
A2: =+H2 -> 0043DS0011 | B2: Un.Serv. | C2: 19 | D2: 043 | E2: General Pueyrredón | F2: 609259 | G2: 0 | H2: 0043DS0011 | I2: Oficial | J2: CENTRO ESPECIALIZADO PARA ADULTOS CON ORIENTACIÓN EN SALUD (CEBAS) | K2: SEDE | M2: C.E.B.A.S. N 11 | N2: Urbano | O2: No | P2: Educación de Jóvenes y Adultos | Q2: Nivel Secundario | R2: 97 | S2: 6 | T2: 1 | V2: CEBAS | W2: =+IF(V2="","",IF(MID(V2,1,3)="ECE","UNICO",IF(V2="FINES",CONCATENATE("R",IF(OR(C2="16",C2="21",C2="22",C2="23"),"16212223",IF(OR(C2="15",C2="17",C2="24",C2="25"),"15172425",C2))),IF(V2="CEBAS","UNICO",IF(VALUE(C2)<=11,"AMBA","INTERIOR"))))) -> UNICO | X2: =+IF(V2="","-",CONCATENATE(V2,"_",W2)) -> CEBAS_UNICO | Y2: 0.063379868 | Z2: =+IFERROR(VLOOKUP(H2,#REF!,2,FALSE),"-") -> - | AA2: SIN | AB2: =+IF(W2="","-",IF(W2="UNICO","CENSO","MUESTRA")) -> CENSO | AC2: PRIMEROS | AD2: - | AF2: =+COUNTIF(Piloto!C:C,MARCO!A2) -> 0
A3: =+H3 -> 0008DS0030 | B3: Un.Serv. | C3: 22 | D3: 008 | E3: Bahía Blanca | F3: 616446 | G3: 0 | H3: 0008DS0030 | I3: Oficial | J3: CENTRO ESPECIALIZADO PARA ADULTOS CON ORIENTACIÓN EN SALUD (CEBAS) | K3: SEDE | M3: C.E.B.A.S. N 30 "ENFERMERAS 1982 POR MALVINAS" | N3: Urbano | O3: No | P3: Educación de Jóvenes y Adultos | Q3: Nivel Secundario | R3: 48 | S3: 3 | T3: 1 | V3: CEBAS | W3: =+IF(V3="","",IF(MID(V3,1,3)="ECE","UNICO",IF(V3="FINES",CONCATENATE("R",IF(OR(C3="16",C3="21",C3="22",C3="23"),"16212223",IF(OR(C3="15",C3="17",C3="24",C3="25"),"15172425",C3))),IF(V3="CEBAS","UNICO",IF(VALUE(C3)<=11,"AMBA","INTERIOR"))))) -> UNICO | X3: =+IF(V3="","-",CONCATENATE(V3,"_",W3)) -> CEBAS_UNICO | Y3: 0.094380705 | Z3: =+IFERROR(VLOOKUP(H3,#REF!,2,FALSE),"-") -> - | AA3: SIN | AB3: =+IF(W3="","-",IF(W3="UNICO","CENSO","MUESTRA")) -> CENSO | AC3: PRIMEROS | AD3: - | AF3: =+COUNTIF(Piloto!C:C,MARCO!A3) -> 0
A4: =+H4 -> 0062DS0016 | B4: Un.Serv. | C4: 02 | D4: 062 | E4: Lomas de Zamora | F4: 614623 | G4: 0 | H4: 0062DS0016 | I4: Oficial | J4: CENTRO ESPECIALIZADO PARA ADULTOS CON ORIENTACIÓN EN SALUD (CEBAS) | K4: SEDE | M4: C.E.B.A.S N 16 | N4: Urbano | O4: No | P4: Educación de Jóvenes y Adultos | Q4: Nivel Secundario | R4: 63 | S4: 6 | T4: 1 | V4: CEBAS | W4: =+IF(V4="","",IF(MID(V4,1,3)="ECE","UNICO",IF(V4="FINES",CONCATENATE("R",IF(OR(C4="16",C4="21",C4="22",C4="23"),"16212223",IF(OR(C4="15",C4="17",C4="24",C4="25"),"15172425",C4))),IF(V4="CEBAS","UNICO",IF(VALUE(C4)<=11,"AMBA","INTERIOR"))))) -> UNICO | X4: =+IF(V4="","-",CONCATENATE(V4,"_",W4)) -> CEBAS_UNICO | Y4: 0.096115828 | Z4: =+IFERROR(VLOOKUP(H4,#REF!,2,FALSE),"-") -> - | AA4: CON | AB4: =+IF(W4="","-",IF(W4="UNICO","CENSO","MUESTRA")) -> CENSO | AC4: PRIMEROS | AD4: - | AF4: =+COUNTIF(Piloto!C:C,MARCO!A4) -> 0
A5: =+H5 -> 0111DS0049 | B5: Un.Serv. | C5: 02 | D5: 111 | E5: Lanús | F5: 620507 | G5: 0 | H5: 0111DS0049 | I5: Oficial | J5: CENTRO ESPECIALIZADO PARA ADULTOS CON ORIENTACIÓN EN SALUD (CEBAS) | K5: SEDE | M5: C.E.B.A.S. N 49 | N5: Urbano | O5: No | P5: Educación de Jóvenes y Adultos | Q5: Nivel Secundario | R5: 43 | S5: 3 | T5: 1 | V5: CEBAS | W5: =+IF(V5="","",IF(MID(V5,1,3)="ECE","UNICO",IF(V5="FINES",CONCATENATE("R",IF(OR(C5="16",C5="21",C5="22",C5="23"),"16212223",IF(OR(C5="15",C5="17",C5="24",C5="25"),"15172425",C5))),IF(V5="CEBAS","UNICO",IF(VALUE(C5)<=11,"AMBA","INTERIOR"))))) -> UNICO | X5: =+IF(V5="","-",CONCATENATE(V5,"_",W5)) -> CEBAS_UNICO | Y5: 0.14383187 | Z5: =+IFERROR(VLOOKUP(H5,#REF!,2,FALSE),"-") -> - | AA5: CON | AB5: =+IF(W5="","-",IF(W5="UNICO","CENSO","MUESTRA")) -> CENSO | AC5: ULTIMOS | AD5: - | AF5: =+COUNTIF(Piloto!C:C,MARCO!A5) -> 0
A6: =+H6 -> 0100DS0028 | B6: Un.Serv. | C6: 08 | D6: 100 | E6: Morón | F6: 616437 | G6: 0 | H6: 0100DS0028 | I6: Oficial | J6: CENTRO ESPECIALIZADO PARA ADULTOS CON ORIENTACIÓN EN SALUD (CEBAS) | K6: SEDE | M6: C.E.B.A.S. N 28 | N6: Urbano | O6: No | P6: Educación de Jóvenes y Adultos | Q6: Nivel Secundario | R6: 109 | S6: 6 | T6: 1 | V6: CEBAS | W6: =+IF(V6="","",IF(MID(V6,1,3)="ECE","UNICO",IF(V6="FINES",CONCATENATE("R",IF(OR(C6="16",C6="21",C6="22",C6="23"),"16212223",IF(OR(C6="15",C6="17",C6="24",C6="25"),"15172425",C6))),IF(V6="CEBAS","UNICO",IF(VALUE(C6)<=11,"AMBA","INTERIOR"))))) -> UNICO | X6: =+IF(V6="","-",CONCATENATE(V6,"_",W6)) -> CEBAS_UNICO | Y6: 0.15550203 | Z6: =+IFERROR(VLOOKUP(H6,#REF!,2,FALSE),"-") -> - | AA6: CON | AB6: =+IF(W6="","-",IF(W6="UNICO","CENSO","MUESTRA")) -> CENSO | AC6: ULTIMOS | AD6: - | AF6: =+COUNTIF(Piloto!C:C,MARCO!A6) -> 0
A7: =+H7 -> 0032DS0013 | B7: Un.Serv. | C7: 04 | D7: 032 | E7: Florencio Varela | F7: 608715 | G7: 0 | H7: 0032DS0013 | I7: Oficial | J7: CENTRO ESPECIALIZADO PARA ADULTOS CON ORIENTACIÓN EN SALUD (CEBAS) | K7: SEDE | M7: C.E.B.A.S. N 13 | N7: Urbano | O7: No | P7: Educación de Jóvenes y Adultos | Q7: Nivel Secundario | R7: 82 | S7: 3 | T7: 1 | V7: CEBAS | W7: =+IF(V7="","",IF(MID(V7,1,3)="ECE","UNICO",IF(V7="FINES",CONCATENATE("R",IF(OR(C7="16",C7="21",C7="22",C7="23"),"16212223",IF(OR(C7="15",C7="17",C7="24",C7="25"),"15172425",C7))),IF(V7="CEBAS","UNICO",IF(VALUE(C7)<=11,"AMBA","INTERIOR"))))) -> UNICO | X7: =+IF(V7="","-",CONCATENATE(V7,"_",W7)) -> CEBAS_UNICO | Y7: 0.17282251 | Z7: =+IFERROR(VLOOKUP(H7,#REF!,2,FALSE),"-") -> - | AA7: CON | AB7: =+IF(W7="","-",IF(W7="UNICO","CENSO","MUESTRA")) -> CENSO | AC7: PRIMEROS | AD7: - | AF7: =+COUNTIF(Piloto!C:C,MARCO!A7) -> 0
A8: =+H8 -> 0001DS0001 | B8: Un.Serv. | C8: 01 | D8: 001 | E8: La Plata | F8: 609006 | G8: 0 | H8: 0001DS0001 | I8: Oficial | J8: CENTRO ESPECIALIZADO PARA ADULTOS CON ORIENTACIÓN EN SALUD (CEBAS) | K8: SEDE | M8: C.E.B.A.S. N 1 "FLOREAL FERRARA" | N8: Urbano | O8: No | P8: Educación de Jóvenes y Adultos | Q8: Nivel Secundario | R8: 256 | S8: 9 | T8: 1 | V8: CEBAS | W8: =+IF(V8="","",IF(MID(V8,1,3)="ECE","UNICO",IF(V8="FINES",CONCATENATE("R",IF(OR(C8="16",C8="21",C8="22",C8="23"),"16212223",IF(OR(C8="15",C8="17",C8="24",C8="25"),"15172425",C8))),IF(V8="CEBAS","UNICO",IF(VALUE(C8)<=11,"AMBA","INTERIOR"))))) -> UNICO | X8: =+IF(V8="","-",CONCATENATE(V8,"_",W8)) -> CEBAS_UNICO | Y8: 0.17714942 | Z8: =+IFERROR(VLOOKUP(H8,#REF!,2,FALSE),"-") -> - | AA8: CON | AB8: =+IF(W8="","-",IF(W8="UNICO","CENSO","MUESTRA")) -> CENSO | AC8: PRIMEROS | AD8: - | AF8: =+COUNTIF(Piloto!C:C,MARCO!A8) -> 0
A9: =+H9 -> 0030DS0041 | B9: Un.Serv. | C9: 05 | D9: 030 | E9: Esteban Echeverría | F9: 620534 | G9: 0 | H9: 0030DS0041 | I9: Oficial | J9: CENTRO ESPECIALIZADO PARA ADULTOS CON ORIENTACIÓN EN SALUD (CEBAS) | K9: SEDE | M9: C.E.B.A.S. N 41 | N9: Urbano | O9: No | P9: Educación de Jóvenes y Adultos | Q9: Nivel Secundario | R9: 33 | S9: 3 | T9: 1 | V9: CEBAS | W9: =+IF(V9="","",IF(MID(V9,1,3)="ECE","UNICO",IF(V9="FINES",CONCATENATE("R",IF(OR(C9="16",C9="21",C9="22",C9="23"),"16212223",IF(OR(C9="15",C9="17",C9="24",C9="25"),"15172425",C9))),IF(V9="CEBAS","UNICO",IF(VALUE(C9)<=11,"AMBA","INTERIOR"))))) -> UNICO | X9: =+IF(V9="","-",CONCATENATE(V9,"_",W9)) -> CEBAS_UNICO | Y9: 0.18888588 | Z9: =+IFERROR(VLOOKUP(H9,#REF!,2,FALSE),"-") -> - | AA9: CON | AB9: =+IF(W9="","-",IF(W9="UNICO","CENSO","MUESTRA")) -> CENSO | AC9: ULTIMOS | AD9: - | AF9: =+COUNTIF(Piloto!C:C,MARCO!A9) -> 0
A10: =+H10 -> 0094DS0047 | B10: Un.Serv. | C10: 13 | D10: 094 | E10: San Antonio de Areco | F10: 619088 | G10: 0 | H10: 0094DS0047 | I10: Oficial | J10: CENTRO ESPECIALIZADO PARA ADULTOS CON ORIENTACIÓN EN SALUD (CEBAS) | K10: SEDE | M10: C.E.B.A.S. N 47 | N10: Urbano | O10: No | P10: Educación de Jóvenes y Adultos | Q10: Nivel Secundario | R10: 33 | S10: 2 | T10: 1 | V10: CEBAS | W10: =+IF(V10="","",IF(MID(V10,1,3)="ECE","UNICO",IF(V10="FINES",CONCATENATE("R",IF(OR(C10="16",C10="21",C10="22",C10="23"),"16212223",IF(OR(C10="15",C10="17",C10="24",C10="25"),"15172425",C10))),IF(V10="CEBAS","UNICO",IF(VALUE(C10)<=11,"AMBA","INTERIOR"))))) -> UNICO | X10: =+IF(V10="","-",CONCATENATE(V10,"_",W10)) -> CEBAS_UNICO | Y10: 0.18974226 | Z10: =+IFERROR(VLOOKUP(H10,#REF!,2,FALSE),"-") -> - | AA10: SIN | AB10: =+IF(W10="","-",IF(W10="UNICO","CENSO","MUESTRA")) -> CENSO | AC10: ULTIMOS | AD10: - | AF10: =+COUNTIF(Piloto!C:C,MARCO!A10) -> 0
A11: =+H11 -> 0076DS0019 | B11: Un.Serv. | C11: 15 | D11: 076 | E11: 9 de Julio | F11: 615601 | G11: 0 | H11: 0076DS0019 | I11: Oficial | J11: CENTRO ESPECIALIZADO PARA ADULTOS CON ORIENTACIÓN EN SALUD (CEBAS) | K11: SEDE | M11: C.E.B.A.S. N 19 | N11: Urbano | O11: No | P11: Educación de Jóvenes y Adultos | Q11: Nivel Secundario | R11: 39 | S11: 3 | T11: 1 | V11: CEBAS | W11: =+IF(V11="","",IF(MID(V11,1,3)="ECE","UNICO",IF(V11="FINES",CONCATENATE("R",IF(OR(C11="16",C11="21",C11="22",C11="23"),"16212223",IF(OR(C11="15",C11="17",C11="24",C11="25"),"15172425",C11))),IF(V11="CEBAS","UNICO",IF(VALUE(C11)<=11,"AMBA","INTERIOR"))))) -> UNICO | X11: =+IF(V11="","-",CONCATENATE(V11,"_",W11)) -> CEBAS_UNICO | Y11: 0.19851275 | Z11: =+IFERROR(VLOOKUP(H11,#REF!,2,FALSE),"-") -> - | AA11: SIN | AB11: =+IF(W11="","-",IF(W11="UNICO","CENSO","MUESTRA")) -> CENSO | AC11: ULTIMOS | AD11: - | AF11: =+COUNTIF(Piloto!C:C,MARCO!A11) -> 0
A12: =+H12 -> 0055DS2370 | B12: Un.Serv. | C12: 06 | D12: 055 | E12: Tigre | F12: 616870 | G12: 1 | H12: 0055DS2370 | I12: Oficial | J12: CENTRO ESPECIALIZADO PARA ADULTOS CON ORIENTACIÓN EN SALUD (CEBAS) | K12: EXTENSION | L12: 0116DS0037 | M12: C.E.B.A.S. N°37 - EXTENSIÓN | N12: Urbano | O12: No | P12: Educación de Jóvenes y Adultos | Q12: Nivel Secundario | R12: 61 | S12: 3 | T12: 1 | V12: CEBAS | W12: =+IF(V12="","",IF(MID(V12,1,3)="ECE","UNICO",IF(V12="FINES",CONCATENATE("R",IF(OR(C12="16",C12="21",C12="22",C12="23"),"16212223",IF(OR(C12="15",C12="17",C12="24",C12="25"),"15172425",C12))),IF(V12="CEBAS","UNICO",IF(VALUE(C12)<=11,"AMBA","INTERIOR"))))) -> UNICO | X12: =+IF(V12="","-",CONCATENATE(V12,"_",W12)) -> CEBAS_UNICO | Y12: 0.20705157 | Z12: =+IFERROR(VLOOKUP(H12,#REF!,2,FALSE),"-") -> - | AA12: CON | AB12: =+IF(W12="","-",IF(W12="UNICO","CENSO","MUESTRA")) -> CENSO | AC12: ULTIMOS | AD12: - | AF12: =+COUNTIF(Piloto!C:C,MARCO!A12) -> 0
A13: =+H13 -> 0001DS0048 | B13: Un.Serv. | C13: 01 | D13: 001 | E13: La Plata | F13: 620508 | G13: 0 | H13: 0001DS0048 | I13: Oficial | J13: CENTRO ESPECIALIZADO PARA ADULTOS CON ORIENTACIÓN EN SALUD (CEBAS) | K13: SEDE | M13: C.E.B.A.S. N 48 "DR. RENÉ FAVALORO" | N13: Urbano | O13: No | P13: Educación de Jóvenes y Adultos | Q13: Nivel Secundario | R13: 16 | S13: 1 | T13: 1 | V13: CEBAS | W13: =+IF(V13="","",IF(MID(V13,1,3)="ECE","UNICO",IF(V13="FINES",CONCATENATE("R",IF(OR(C13="16",C13="21",C13="22",C13="23"),"16212223",IF(OR(C13="15",C13="17",C13="24",C13="25"),"15172425",C13))),IF(V13="CEBAS","UNICO",IF(VALUE(C13)<=11,"AMBA","INTERIOR"))))) -> UNICO | X13: =+IF(V13="","-",CONCATENATE(V13,"_",W13)) -> CEBAS_UNICO | Y13: 0.25350336 | Z13: =+IFERROR(VLOOKUP(H13,#REF!,2,FALSE),"-") -> - | AA13: CON | AB13: =+IF(W13="","-",IF(W13="UNICO","CENSO","MUESTRA")) -> CENSO | AC13: ULTIMOS | AD13: - | AF13: =+COUNTIF(Piloto!C:C,MARCO!A13) -> 1
A14: =+H14 -> 0045DS0002 | B14: Un.Serv. | C14: 07 | D14: 045 | E14: General San Martín | F14: 609445 | G14: 0 | H14: 0045DS0002 | I14: Oficial | J14: CENTRO ESPECIALIZADO PARA ADULTOS CON ORIENTACIÓN EN SALUD (CEBAS) | K14: SEDE | M14: C.E.B.A.S. N 2 "EDUCADOR PAULO FREIRE" | N14: Urbano | O14: No | P14: Educación de Jóvenes y Adultos | Q14: Nivel Secundario | R14: 89 | S14: 6 | T14: 1 | V14: CEBAS | W14: =+IF(V14="","",IF(MID(V14,1,3)="ECE","UNICO",IF(V14="FINES",CONCATENATE("R",IF(OR(C14="16",C14="21",C14="22",C14="23"),"16212223",IF(OR(C14="15",C14="17",C14="24",C14="25"),"15172425",C14))),IF(V14="CEBAS","UNICO",IF(VALUE(C14)<=11,"AMBA","INTERIOR"))))) -> UNICO | X14: =+IF(V14="","-",CONCATENATE(V14,"_",W14)) -> CEBAS_UNICO | Y14: 0.28876384 | Z14: =+IFERROR(VLOOKUP(H14,#REF!,2,FALSE),"-") -> - | AA14: CON | AB14: =+IF(W14="","-",IF(W14="UNICO","CENSO","MUESTRA")) -> CENSO | AC14: ULTIMOS | AD14: - | AF14: =+COUNTIF(Piloto!C:C,MARCO!A14) -> 0
A15: =+H15 -> 0005DS0010 | B15: Un.Serv. | C15: 02 | D15: 005 | E15: Avellaneda | F15: 610303 | G15: 0 | H15: 0005DS0010 | I15: Oficial | J15: CENTRO ESPECIALIZADO PARA ADULTOS CON ORIENTACIÓN EN SALUD (CEBAS) | K15: SEDE | M15: C.E.B.A.S. N 10 | N15: Urbano | O15: No | P15: Educación de Jóvenes y Adultos | Q15: Nivel Secundario | R15: 124 | S15: 6 | T15: 1 | V15: CEBAS | W15: =+IF(V15="","",IF(MID(V15,1,3)="ECE","UNICO",IF(V15="FINES",CONCATENATE("R",IF(OR(C15="16",C15="21",C15="22",C15="23"),"16212223",IF(OR(C15="15",C15="17",C15="24",C15="25"),"15172425",C15))),IF(V15="CEBAS","UNICO",IF(VALUE(C15)<=11,"AMBA","INTERIOR"))))) -> UNICO | X15: =+IF(V15="","-",CONCATENATE(V15,"_",W15)) -> CEBAS_UNICO | Y15: 0.29353985 | Z15: =+IFERROR(VLOOKUP(H15,#REF!,2,FALSE),"-") -> - | AA15: CON | AB15: =+IF(W15="","-",IF(W15="UNICO","CENSO","MUESTRA")) -> CENSO | AC15: PRIMEROS | AD15: - | AF15: =+COUNTIF(Piloto!C:C,MARCO!A15) -> 0
A16: =+H16 -> 0071DS0029 | B16: Un.Serv. | C16: 08 | D16: 071 | E16: Merlo | F16: 616233 | G16: 0 | H16: 0071DS0029 | I16: Oficial | J16: CENTRO ESPECIALIZADO PARA ADULTOS CON ORIENTACIÓN EN SALUD (CEBAS) | K16: SEDE | M16: C.E.B.A.S. N 29 | N16: Urbano | O16: No | P16: Educación de Jóvenes y Adultos | Q16: Nivel Secundario | R16: 102 | S16: 6 | T16: 1 | V16: CEBAS | W16: =+IF(V16="","",IF(MID(V16,1,3)="ECE","UNICO",IF(V16="FINES",CONCATENATE("R",IF(OR(C16="16",C16="21",C16="22",C16="23"),"16212223",IF(OR(C16="15",C16="17",C16="24",C16="25"),"15172425",C16))),IF(V16="CEBAS","UNICO",IF(VALUE(C16)<=11,"AMBA","INTERIOR"))))) -> UNICO | X16: =+IF(V16="","-",CONCATENATE(V16,"_",W16)) -> CEBAS_UNICO | Y16: 0.3499111 | Z16: =+IFERROR(VLOOKUP(H16,#REF!,2,FALSE),"-") -> - | AA16: CON | AB16: =+IF(W16="","-",IF(W16="UNICO","CENSO","MUESTRA")) -> CENSO | AC16: ULTIMOS | AD16: - | AF16: =+COUNTIF(Piloto!C:C,MARCO!A16) -> 0
A17: =+H17 -> 0132DS0039 | B17: Un.Serv. | C17: 09 | D17: 132 | E17: José C. Paz | F17: 619103 | G17: 0 | H17: 0132DS0039 | I17: Oficial | J17: CENTRO ESPECIALIZADO PARA ADULTOS CON ORIENTACIÓN EN SALUD (CEBAS) | K17: SEDE | M17: C.E.B.A.S. N 39 | N17: Urbano | O17: No | P17: Educación de Jóvenes y Adultos | Q17: Nivel Secundario | R17: 96 | S17: 6 | T17: 1 | V17: CEBAS | W17: =+IF(V17="","",IF(MID(V17,1,3)="ECE","UNICO",IF(V17="FINES",CONCATENATE("R",IF(OR(C17="16",C17="21",C17="22",C17="23"),"16212223",IF(OR(C17="15",C17="17",C17="24",C17="25"),"15172425",C17))),IF(V17="CEBAS","UNICO",IF(VALUE(C17)<=11,"AMBA","INTERIOR"))))) -> UNICO | X17: =+IF(V17="","-",CONCATENATE(V17,"_",W17)) -> CEBAS_UNICO | Y17: 0.41227043 | Z17: =+IFERROR(VLOOKUP(H17,#REF!,2,FALSE),"-") -> - | AA17: CON | AB17: =+IF(W17="","-",IF(W17="UNICO","CENSO","MUESTRA")) -> CENSO | AC17: PRIMEROS | AD17: - | AF17: =+COUNTIF(Piloto!C:C,MARCO!A17) -> 0
A18: =+H18 -> 0116DS0037 | B18: Un.Serv. | C18: 11 | D18: 116 | E18: Escobar | F18: 616870 | G18: 0 | H18: 0116DS0037 | I18: Oficial | J18: CENTRO ESPECIALIZADO PARA ADULTOS CON ORIENTACIÓN EN SALUD (CEBAS) | K18: SEDE | M18: C.E.B.A.S. N 37 | N18: Urbano | O18: No | P18: Educación de Jóvenes y Adultos | Q18: Nivel Secundario | R18: 54 | S18: 3 | T18: 1 | V18: CEBAS | W18: =+IF(V18="","",IF(MID(V18,1,3)="ECE","UNICO",IF(V18="FINES",CONCATENATE("R",IF(OR(C18="16",C18="21",C18="22",C18="23"),"16212223",IF(OR(C18="15",C18="17",C18="24",C18="25"),"15172425",C18))),IF(V18="CEBAS","UNICO",IF(VALUE(C18)<=11,"AMBA","INTERIOR"))))) -> UNICO | X18: =+IF(V18="","-",CONCATENATE(V18,"_",W18)) -> CEBAS_UNICO | Y18: 0.46929595 | Z18: =+IFERROR(VLOOKUP(H18,#REF!,2,FALSE),"-") -> - | AA18: CON | AB18: =+IF(W18="","-",IF(W18="UNICO","CENSO","MUESTRA")) -> CENSO | AC18: ULTIMOS | AD18: - | AF18: =+COUNTIF(Piloto!C:C,MARCO!A18) -> 0
A19: =+H19 -> 0119DS0017 | B19: Un.Serv. | C19: 04 | D19: 119 | E19: Berazategui | F19: 614624 | G19: 0 | H19: 0119DS0017 | I19: Oficial | J19: CENTRO ESPECIALIZADO PARA ADULTOS CON ORIENTACIÓN EN SALUD (CEBAS) | K19: SEDE | M19: C.E.B.A.S. N 17 | N19: Urbano | O19: No | P19: Educación de Jóvenes y Adultos | Q19: Nivel Secundario | R19: 86 | S19: 6 | T19: 1 | V19: CEBAS | W19: =+IF(V19="","",IF(MID(V19,1,3)="ECE","UNICO",IF(V19="FINES",CONCATENATE("R",IF(OR(C19="16",C19="21",C19="22",C19="23"),"16212223",IF(OR(C19="15",C19="17",C19="24",C19="25"),"15172425",C19))),IF(V19="CEBAS","UNICO",IF(VALUE(C19)<=11,"AMBA","INTERIOR"))))) -> UNICO | X19: =+IF(V19="","-",CONCATENATE(V19,"_",W19)) -> CEBAS_UNICO | Y19: 0.47318311 | Z19: =+IFERROR(VLOOKUP(H19,#REF!,2,FALSE),"-") -> - | AA19: CON | AB19: =+IF(W19="","-",IF(W19="UNICO","CENSO","MUESTRA")) -> CENSO | AC19: PRIMEROS | AD19: - | AF19: =+COUNTIF(Piloto!C:C,MARCO!A19) -> 0
A20: =+H20 -> 0001DS2480 | B20: Un.Serv. | C20: 01 | D20: 001 | E20: La Plata | F20: 620508 | G20: 1 | H20: 0001DS2480 | I20: Oficial | J20: CENTRO ESPECIALIZADO PARA ADULTOS CON ORIENTACIÓN EN SALUD (CEBAS) | K20: EXTENSION | L20: 0001DS0048 | M20: C.E.B.A.S. N 48 - EXTENSIÓN N 2480 | N20: Urbano | O20: No | P20: Educación de Jóvenes y Adultos | Q20: Nivel Secundario | R20: 77 | S20: 3 | T20: 1 | V20: CEBAS | W20: =+IF(V20="","",IF(MID(V20,1,3)="ECE","UNICO",IF(V20="FINES",CONCATENATE("R",IF(OR(C20="16",C20="21",C20="22",C20="23"),"16212223",IF(OR(C20="15",C20="17",C20="24",C20="25"),"15172425",C20))),IF(V20="CEBAS","UNICO",IF(VALUE(C20)<=11,"AMBA","INTERIOR"))))) -> UNICO | X20: =+IF(V20="","-",CONCATENATE(V20,"_",W20)) -> CEBAS_UNICO | Y20: 0.62820226 | Z20: =+IFERROR(VLOOKUP(H20,#REF!,2,FALSE),"-") -> - | AA20: CON | AB20: =+IF(W20="","-",IF(W20="UNICO","CENSO","MUESTRA")) -> CENSO | AC20: PRIMEROS | AD20: - | AF20: =+COUNTIF(Piloto!C:C,MARCO!A20) -> 0
A21: =+H21 -> 0069DS0004 | B21: Un.Serv. | C21: 03 | D21: 069 | E21: La Matanza | F21: 607939 | G21: 0 | H21: 0069DS0004 | I21: Oficial | J21: CENTRO ESPECIALIZADO PARA ADULTOS CON ORIENTACIÓN EN SALUD (CEBAS) | K21: SEDE | M21: C.E.B.A.S. N 4 "IRMA LACIAR" | N21: Urbano | O21: No | P21: Educación de Jóvenes y Adultos | Q21: Nivel Secundario | R21: 82 | S21: 6 | T21: 1 | V21: CEBAS | W21: =+IF(V21="","",IF(MID(V21,1,3)="ECE","UNICO",IF(V21="FINES",CONCATENATE("R",IF(OR(C21="16",C21="21",C21="22",C21="23"),"16212223",IF(OR(C21="15",C21="17",C21="24",C21="25"),"15172425",C21))),IF(V21="CEBAS","UNICO",IF(VALUE(C21)<=11,"AMBA","INTERIOR"))))) -> UNICO | X21: =+IF(V21="","-",CONCATENATE(V21,"_",W21)) -> CEBAS_UNICO | Y21: 0.6792475 | Z21: =+IFERROR(VLOOKUP(H21,#REF!,2,FALSE),"-") -> - | AA21: CON | AB21: =+IF(W21="","-",IF(W21="UNICO","CENSO","MUESTRA")) -> CENSO | AC21: ULTIMOS | AD21: - | AF21: =+COUNTIF(Piloto!C:C,MARCO!A21) -> 0
A22: =+H22 -> 0109DM0452 | B22: Un.Serv. | C22: 06 | D22: 109 | E22: Vicente López | F22: 623684 | G22: 0 | H22: 0109DM0452 | I22: Oficial | J22: CENTRO EDUCATIVO DE NIVEL SECUNDARIO (C.E.N.S.) | K22: SEDE | M22: CENS 452 "JORGE ALBERTO TAIANA" | N22: Urbano | O22: No | P22: Educación de Jóvenes y Adultos | Q22: Nivel Secundario | R22: 118 | S22: 9 | T22: 1 | V22: CENS | W22: =+IF(V22="","",IF(MID(V22,1,3)="ECE","UNICO",IF(V22="FINES",CONCATENATE("R",IF(OR(C22="16",C22="21",C22="22",C22="23"),"16212223",IF(OR(C22="15",C22="17",C22="24",C22="25"),"15172425",C22))),IF(V22="CEBAS","UNICO",IF(VALUE(C22)<=11,"AMBA","INTERIOR"))))) -> AMBA | X22: =+IF(V22="","-",CONCATENATE(V22,"_",W22)) -> CENS_AMBA | Y22: 0.018129991 | Z22: =+IFERROR(VLOOKUP(H22,#REF!,2,FALSE),"-") -> - | AA22: CON | AB22: =+IF(W22="","-",IF(W22="UNICO","CENSO","MUESTRA")) -> MUESTRA | AC22: PRIMEROS | AD22: - | AF22: =+COUNTIF(Piloto!C:C,MARCO!A22) -> 0
A23: =+H23 -> 0062DM0456 | B23: Un.Serv. | C23: 02 | D23: 062 | E23: Lomas de Zamora | F23: 602517 | G23: 0 | H23: 0062DM0456 | I23: Oficial | J23: CENTRO EDUCATIVO DE NIVEL SECUNDARIO (C.E.N.S.) | K23: SEDE | M23: CENS 456 | N23: Urbano | O23: No | P23: Educación de Jóvenes y Adultos | Q23: Nivel Secundario | R23: 398 | S23: 24 | T23: 1 | V23: CENS | W23: =+IF(V23="","",IF(MID(V23,1,3)="ECE","UNICO",IF(V23="FINES",CONCATENATE("R",IF(OR(C23="16",C23="21",C23="22",C23="23"),"16212223",IF(OR(C23="15",C23="17",C23="24",C23="25"),"15172425",C23))),IF(V23="CEBAS","UNICO",IF(VALUE(C23)<=11,"AMBA","INTERIOR"))))) -> AMBA | X23: =+IF(V23="","-",CONCATENATE(V23,"_",W23)) -> CENS_AMBA | Y23: 0.078160366 | Z23: =+IFERROR(VLOOKUP(H23,#REF!,2,FALSE),"-") -> - | AA23: CON | AB23: =+IF(W23="","-",IF(W23="UNICO","CENSO","MUESTRA")) -> MUESTRA | AC23: PRIMEROS | AD23: - | AF23: =+COUNTIF(Piloto!C:C,MARCO!A23) -> 0
A24: =+H24 -> 0045DM0452 | B24: Un.Serv. | C24: 07 | D24: 045 | E24: General San Martín | F24: 604217 | G24: 0 | H24: 0045DM0452 | I24: Oficial | J24: CENTRO EDUCATIVO DE NIVEL SECUNDARIO (C.E.N.S.) | K24: SEDE | M24: CENS 452 | N24: Urbano | O24: Sí | P24: Educación de Jóvenes y Adultos | Q24: Nivel Secundario | R24: 238 | S24: 13 | T24: 1 | V24: CENS | W24: =+IF(V24="","",IF(MID(V24,1,3)="ECE","UNICO",IF(V24="FINES",CONCATENATE("R",IF(OR(C24="16",C24="21",C24="22",C24="23"),"16212223",IF(OR(C24="15",C24="17",C24="24",C24="25"),"15172425",C24))),IF(V24="CEBAS","UNICO",IF(VALUE(C24)<=11,"AMBA","INTERIOR"))))) -> AMBA | X24: =+IF(V24="","-",CONCATENATE(V24,"_",W24)) -> CENS_AMBA | Y24: 0.079491764 | Z24: =+IFERROR(VLOOKUP(H24,#REF!,2,FALSE),"-") -> - | AA24: CON | AB24: =+IF(W24="","-",IF(W24="UNICO","CENSO","MUESTRA")) -> MUESTRA | AC24: ULTIMOS | AD24: - | AF24: =+COUNTIF(Piloto!C:C,MARCO!A24) -> 0
A25: =+H25 -> 0100DM0458 | B25: Un.Serv. | C25: 08 | D25: 100 | E25: Morón | F25: 623719 | G25: 0 | H25: 0100DM0458 | I25: Oficial | J25: CENTRO EDUCATIVO DE NIVEL SECUNDARIO (C.E.N.S.) | K25: SEDE | M25: CENS 458 | N25: Urbano | O25: No | P25: Educación de Jóvenes y Adultos | Q25: Nivel Secundario | R25: 123 | S25: 11 | T25: 1 | V25: CENS | W25: =+IF(V25="","",IF(MID(V25,1,3)="ECE","UNICO",IF(V25="FINES",CONCATENATE("R",IF(OR(C25="16",C25="21",C25="22",C25="23"),"16212223",IF(OR(C25="15",C25="17",C25="24",C25="25"),"15172425",C25))),IF(V25="CEBAS","UNICO",IF(VALUE(C25)<=11,"AMBA","INTERIOR"))))) -> AMBA | X25: =+IF(V25="","-",CONCATENATE(V25,"_",W25)) -> CENS_AMBA | Y25: 0.09014573 | Z25: =+IFERROR(VLOOKUP(H25,#REF!,2,FALSE),"-") -> - | AA25: CON | AB25: =+IF(W25="","-",IF(W25="UNICO","CENSO","MUESTRA")) -> MUESTRA | AC25: PRIMEROS | AD25: - | AF25: =+COUNTIF(Piloto!C:C,MARCO!A25) -> 0
A26: =+H26 -> 0096DM0458 | B26: Un.Serv. | C26: 06 | D26: 096 | E26: San Isidro | F26: 623674 | G26: 0 | H26: 0096DM0458 | I26: Oficial | J26: CENTRO EDUCATIVO DE NIVEL SECUNDARIO (C.E.N.S.) | K26: SEDE | M26: CENS 458 | N26: Urbano | O26: No | P26: Educación de Jóvenes y Adultos | Q26: Nivel Secundario | R26: 201 | S26: 9 | T26: 1 | V26: CENS | W26: =+IF(V26="","",IF(MID(V26,1,3)="ECE","UNICO",IF(V26="FINES",CONCATENATE("R",IF(OR(C26="16",C26="21",C26="22",C26="23"),"16212223",IF(OR(C26="15",C26="17",C26="24",C26="25"),"15172425",C26))),IF(V26="CEBAS","UNICO",IF(VALUE(C26)<=11,"AMBA","INTERIOR"))))) -> AMBA | X26: =+IF(V26="","-",CONCATENATE(V26,"_",W26)) -> CENS_AMBA | Y26: 0.094259013 | Z26: =+IFERROR(VLOOKUP(H26,#REF!,2,FALSE),"-") -> - | AA26: CON | AB26: =+IF(W26="","-",IF(W26="UNICO","CENSO","MUESTRA")) -> MUESTRA | AC26: PRIMEROS | AD26: - | AF26: =+COUNTIF(Piloto!C:C,MARCO!A26) -> 0
A27: =+H27 -> 0001DM0465 | B27: Un.Serv. | C27: 01 | D27: 001 | E27: La Plata | F27: 623591 | G27: 0 | H27: 0001DM0465 | I27: Oficial | J27: CENTRO EDUCATIVO DE NIVEL SECUNDARIO (C.E.N.S.) | K27: SEDE | M27: CENS 465 | N27: Urbano | O27: No | P27: Educación de Jóvenes y Adultos | Q27: Nivel Secundario | R27: 63 | S27: 8 | T27: 1 | V27: CENS | W27: =+IF(V27="","",IF(MID(V27,1,3)="ECE","UNICO",IF(V27="FINES",CONCATENATE("R",IF(OR(C27="16",C27="21",C27="22",C27="23"),"16212223",IF(OR(C27="15",C27="17",C27="24",C27="25"),"15172425",C27))),IF(V27="CEBAS","UNICO",IF(VALUE(C27)<=11,"AMBA","INTERIOR"))))) -> AMBA | X27: =+IF(V27="","-",CONCATENATE(V27,"_",W27)) -> CENS_AMBA | Y27: 0.099921968 | Z27: =+IFERROR(VLOOKUP(H27,#REF!,2,FALSE),"-") -> - | AA27: CON | AB27: =+IF(W27="","-",IF(W27="UNICO","CENSO","MUESTRA")) -> MUESTRA | AC27: PRIMEROS | AD27: - | AF27: =+COUNTIF(Piloto!C:C,MARCO!A27) -> 0
