Workbook

Sheet Nómina
A1: Tipo | B1: Región Educativa | C1: Código Distrito DGCyE | D1: Nombre de Distrito - Partido | E1: CUE | F1: Anexo | G1: Clave Provincial | H1: Dependencia | I1: Tipo de Organización | J1: Sede Anexo Extensión | K1: Escuela Sede | L1: Nombre del Establecimiento | M1: Nombre del Establecimiento_fines | N1: Ámbito Geográfico | O1: Matrícula Estimada | P1: Modalidad | Q1: Nivel | R1: Matricula Total | S1: Secciones | T1: Universo | U1: Universo_Excl. | V1: Estrato_Oferta | W1: Estrato_GEO | X1: Estrato | Y1: IVSE_T (ficticio) | Z1: IVSE_T (punto) (real)
A2: Un.Serv. | B2: 01 | C2: 113 | D2: Berisso | E2: 602838 | F2: 2 | G2: 0113DC0708 | H2: Oficial | I2: CENTRO DE EDUCACIÓN PRIMARIA DE ADULTOS | J2: EXTENSION | K2: 0113DE0703 | L2: CENTRO DE ADULTOS Nº708/03 "DARDO ROCHA" | N2: Urbano | O2: No | P2: Educación de Jóvenes y Adultos | Q2: Nivel Primario | R2: 24 | S2: 2 | T2: 0 | U2: Prim. NO EPA | W2: =+IF(V2="","",IF(V2="FINES",CONCATENATE("R",IF(OR(B2="16",B2="21",B2="22",B2="23"),"16212223",IF(OR(B2="15",B2="17",B2="24",B2="25"),"15172425",B2))),IF(V2="CEBAS","UNICO",IF(VALUE(B2)<=11,"AMBA","INTERIOR")))) | X2: =+IF(V2="","-",CONCATENATE(V2,"_",W2)) -> - | Y2: 0 | Z2: =IFERROR(IFERROR(VLOOKUP(G2,'IVSET-Escuelas'!A:F,4,FALSE),VLOOKUP(M2,'IVSET-Fines'!F:L,7,FALSE)),"-") -> 0.57156479
A3: Un.Serv. | B3: 04 | C3: 032 | D3: Florencio Varela | E3: 608473 | F3: 1 | G3: 0032DC0717 | H3: Oficial | I3: CENTRO DE EDUCACIÓN PRIMARIA DE ADULTOS | J3: EXTENSION | K3: 0032DE0721 | L3: CENTRO DE ADULTOS Nº717/21 | N3: Urbano | O3: No | P3: Educación de Jóvenes y Adultos | Q3: Nivel Primario | R3: 55 | S3: 4 | T3: 0 | U3: Prim. NO EPA | W3: =+IF(V3="","",IF(V3="FINES",CONCATENATE("R",IF(OR(B3="16",B3="21",B3="22",B3="23"),"16212223",IF(OR(B3="15",B3="17",B3="24",B3="25"),"15172425",B3))),IF(V3="CEBAS","UNICO",IF(VALUE(B3)<=11,"AMBA","INTERIOR")))) | X3: =+IF(V3="","-",CONCATENATE(V3,"_",W3)) -> - | Y3: 0 | Z3: =IFERROR(IFERROR(VLOOKUP(G3,'IVSET-Escuelas'!A:F,4,FALSE),VLOOKUP(M3,'IVSET-Fines'!F:L,7,FALSE)),"-") -> 0.58211553
A4: Un.Serv. | B4: 20 | C4: 060 | D4: Lobería | E4: 600691 | F4: 0 | G4: 0060DC0703 | H4: Oficial | I4: CENTRO DE EDUCACIÓN PRIMARIA DE ADULTOS | J4: SEDE | L4: CENTRO DE ADULTOS Nº703 "VILLA ERCILIA" | N4: Urbano | O4: No | P4: Educación de Jóvenes y Adultos | Q4: Nivel Primario | R4: 11 | S4: 1 | T4: 0 | U4: Prim. NO EPA | W4: =+IF(V4="","",IF(V4="FINES",CONCATENATE("R",IF(OR(B4="16",B4="21",B4="22",B4="23"),"16212223",IF(OR(B4="15",B4="17",B4="24",B4="25"),"15172425",B4))),IF(V4="CEBAS","UNICO",IF(VALUE(B4)<=11,"AMBA","INTERIOR")))) | X4: =+IF(V4="","-",CONCATENATE(V4,"_",W4)) -> - | Y4: 0.001 | Z4: =IFERROR(IFERROR(VLOOKUP(G4,'IVSET-Escuelas'!A:F,4,FALSE),VLOOKUP(M4,'IVSET-Fines'!F:L,7,FALSE)),"-") -> 0.60423279
A5: Un.Serv. | B5: 02 | C5: 111 | D5: Lanús | E5: 608243 | F5: 1 | G5: 0111DC0727 | H5: Oficial | I5: CENTRO DE EDUCACIÓN PRIMARIA DE ADULTOS | J5: EXTENSION | K5: 0111DE0712 | L5: CENTRO DE ADULTOS Nº727/12 | N5: Urbano | O5: No | P5: Educación de Jóvenes y Adultos | Q5: Nivel Primario | R5: 46 | S5: 3 | T5: 0 | U5: Prim. NO EPA | W5: =+IF(V5="","",IF(V5="FINES",CONCATENATE("R",IF(OR(B5="16",B5="21",B5="22",B5="23"),"16212223",IF(OR(B5="15",B5="17",B5="24",B5="25"),"15172425",B5))),IF(V5="CEBAS","UNICO",IF(VALUE(B5)<=11,"AMBA","INTERIOR")))) | X5: =+IF(V5="","-",CONCATENATE(V5,"_",W5)) -> - | Y5: 0.001 | Z5: =IFERROR(IFERROR(VLOOKUP(G5,'IVSET-Escuelas'!A:F,4,FALSE),VLOOKUP(M5,'IVSET-Fines'!F:L,7,FALSE)),"-") -> 0.57851213
A6: Un.Serv. | B6: 19 | C6: 043 | D6: General Pueyrredón | E6: 613572 | F6: 1 | G6: 0043DC0739 | H6: Oficial | I6: CENTRO DE EDUCACIÓN PRIMARIA DE ADULTOS | J6: EXTENSION | K6: 0043DE0743 | L6: CENTRO DE ADULTOS Nº739/06 | N6: Urbano | O6: No | P6: Educación de Jóvenes y Adultos | Q6: Nivel Primario | R6: 36 | S6: 3 | T6: 0 | U6: Prim. NO EPA | W6: =+IF(V6="","",IF(V6="FINES",CONCATENATE("R",IF(OR(B6="16",B6="21",B6="22",B6="23"),"16212223",IF(OR(B6="15",B6="17",B6="24",B6="25"),"15172425",B6))),IF(V6="CEBAS","UNICO",IF(VALUE(B6)<=11,"AMBA","INTERIOR")))) | X6: =+IF(V6="","-",CONCATENATE(V6,"_",W6)) -> - | Y6: 0.002 | Z6: =IFERROR(IFERROR(VLOOKUP(G6,'IVSET-Escuelas'!A:F,4,FALSE),VLOOKUP(M6,'IVSET-Fines'!F:L,7,FALSE)),"-") -> 0.5861389
A7: Un.Serv. | B7: 08 | C7: 071 | D7: Merlo | E7: 609955 | F7: 4 | G7: 0071DC0714 | H7: Oficial | I7: CENTRO DE EDUCACIÓN PRIMARIA DE ADULTOS | J7: EXTENSION | K7: 0071DE0703 | L7: CENTRO DE ADULTOS Nº714/03 | N7: Urbano | O7: No | P7: Educación de Jóvenes y Adultos | Q7: Nivel Primario | R7: 40 | S7: 3 | T7: 0 | U7: Prim. NO EPA | W7: =+IF(V7="","",IF(V7="FINES",CONCATENATE("R",IF(OR(B7="16",B7="21",B7="22",B7="23"),"16212223",IF(OR(B7="15",B7="17",B7="24",B7="25"),"15172425",B7))),IF(V7="CEBAS","UNICO",IF(VALUE(B7)<=11,"AMBA","INTERIOR")))) | X7: =+IF(V7="","-",CONCATENATE(V7,"_",W7)) -> - | Y7: 0.004 | Z7: =IFERROR(IFERROR(VLOOKUP(G7,'IVSET-Escuelas'!A:F,4,FALSE),VLOOKUP(M7,'IVSET-Fines'!F:L,7,FALSE)),"-") -> 0.67768568
A8: Un.Serv. | B8: 04 | C8: 032 | D8: Florencio Varela | E8: 608473 | F8: 2 | G8: 0032DC0718 | H8: Oficial | I8: CENTRO DE EDUCACIÓN PRIMARIA DE ADULTOS | J8: EXTENSION | K8: 0032DE0721 | L8: CENTRO DE ADULTOS Nº718/21 | N8: Urbano | O8: No | P8: Educación de Jóvenes y Adultos | Q8: Nivel Primario | R8: 38 | S8: 3 | T8: 0 | U8: Prim. NO EPA | W8: =+IF(V8="","",IF(V8="FINES",CONCATENATE("R",IF(OR(B8="16",B8="21",B8="22",B8="23"),"16212223",IF(OR(B8="15",B8="17",B8="24",B8="25"),"15172425",B8))),IF(V8="CEBAS","UNICO",IF(VALUE(B8)<=11,"AMBA","INTERIOR")))) | X8: =+IF(V8="","-",CONCATENATE(V8,"_",W8)) -> - | Y8: 0.004 | Z8: =IFERROR(IFERROR(VLOOKUP(G8,'IVSET-Escuelas'!A:F,4,FALSE),VLOOKUP(M8,'IVSET-Fines'!F:L,7,FALSE)),"-") -> 0.57331204
A9: Un.Serv. | B9: 11 | C9: 047 | D9: Zárate | E9: 605769 | F9: 1 | G9: 0047DC0708 | H9: Oficial | I9: CENTRO DE EDUCACIÓN PRIMARIA DE ADULTOS | J9: EXTENSION | K9: 0047DE0703 | L9: CENTRO DE ADULTOS Nº708/03 | N9: Urbano | O9: No | P9: Educación de Jóvenes y Adultos | Q9: Nivel Primario | R9: 32 | S9: 2 | T9: 0 | U9: Prim. NO EPA | W9: =+IF(V9="","",IF(V9="FINES",CONCATENATE("R",IF(OR(B9="16",B9="21",B9="22",B9="23"),"16212223",IF(OR(B9="15",B9="17",B9="24",B9="25"),"15172425",B9))),IF(V9="CEBAS","UNICO",IF(VALUE(B9)<=11,"AMBA","INTERIOR")))) | X9: =+IF(V9="","-",CONCATENATE(V9,"_",W9)) -> - | Y9: 0.006 | Z9: =IFERROR(IFERROR(VLOOKUP(G9,'IVSET-Escuelas'!A:F,4,FALSE),VLOOKUP(M9,'IVSET-Fines'!F:L,7,FALSE)),"-") -> 0.22091849
A10: Un.Serv. | B10: 07 | C10: 135 | D10: Hurlingham | E10: 600021 | F10: 1 | G10: 0135DC0707 | H10: Oficial | I10: CENTRO DE EDUCACIÓN PRIMARIA DE ADULTOS | J10: EXTENSION | K10: 0135DE0701 | L10: CENTRO DE ADULTOS Nº707/01 | N10: Urbano | O10: No | P10: Educación de Jóvenes y Adultos | Q10: Nivel Primario | R10: 30 | S10: 2 | T10: 0 | U10: Prim. NO EPA | W10: =+IF(V10="","",IF(V10="FINES",CONCATENATE("R",IF(OR(B10="16",B10="21",B10="22",B10="23"),"16212223",IF(OR(B10="15",B10="17",B10="24",B10="25"),"15172425",B10))),IF(V10="CEBAS","UNICO",IF(VALUE(B10)<=11,"AMBA","INTERIOR")))) | X10: =+IF(V10="","-",CONCATENATE(V10,"_",W10)) -> - | Y10: 0.007 | Z10: =IFERROR(IFERROR(VLOOKUP(G10,'IVSET-Escuelas'!A:F,4,FALSE),VLOOKUP(M10,'IVSET-Fines'!F:L,7,FALSE)),"-") -> 0.41915533
A11: Un.Serv. | B11: 22 | C11: 078 | D11: Patagones | E11: 603157 | F11: 3 | G11: 0078DC0704 | H11: Oficial | I11: CENTRO DE EDUCACIÓN PRIMARIA DE ADULTOS | J11: EXTENSION | K11: 0078DE0701 | L11: CENTRO DE ADULTOS Nº704/01 | N11: Urbano | O11: No | P11: Educación de Jóvenes y Adultos | Q11: Nivel Primario | R11: 36 | S11: 3 | T11: 0 | U11: Prim. NO EPA | W11: =+IF(V11="","",IF(V11="FINES",CONCATENATE("R",IF(OR(B11="16",B11="21",B11="22",B11="23"),"16212223",IF(OR(B11="15",B11="17",B11="24",B11="25"),"15172425",B11))),IF(V11="CEBAS","UNICO",IF(VALUE(B11)<=11,"AMBA","INTERIOR")))) | X11: =+IF(V11="","-",CONCATENATE(V11,"_",W11)) -> - | Y11: 0.009 | Z11: =IFERROR(IFERROR(VLOOKUP(G11,'IVSET-Escuelas'!A:F,4,FALSE),VLOOKUP(M11,'IVSET-Fines'!F:L,7,FALSE)),"-") -> 0.38167584
A12: Un.Serv. | B12: 18 | C12: 125 | D12: Villa Gesell | E12: 613151 | F12: 1 | G12: 0125DC0702 | H12: Oficial | I12: CENTRO DE EDUCACIÓN PRIMARIA DE ADULTOS | J12: EXTENSION | K12: 0125DE0701 | L12: CENTRO DE ADULTOS Nº702/01 | N12: Urbano | O12: No | P12: Educación de Jóvenes y Adultos | Q12: Nivel Primario | R12: 38 | S12: 3 | T12: 0 | U12: Prim. NO EPA | W12: =+IF(V12="","",IF(V12="FINES",CONCATENATE("R",IF(OR(B12="16",B12="21",B12="22",B12="23"),"16212223",IF(OR(B12="15",B12="17",B12="24",B12="25"),"15172425",B12))),IF(V12="CEBAS","UNICO",IF(VALUE(B12)<=11,"AMBA","INTERIOR")))) | X12: =+IF(V12="","-",CONCATENATE(V12,"_",W12)) -> - | Y12: 0.013 | Z12: =IFERROR(IFERROR(VLOOKUP(G12,'IVSET-Escuelas'!A:F,4,FALSE),VLOOKUP(M12,'IVSET-Fines'!F:L,7,FALSE)),"-") -> 0.40243295
A13: Un.Serv. | B13: 03 | C13: 069 | D13: La Matanza | E13: 602154 | F13: 1 | G13: 0069DC0715 | H13: Oficial | I13: CENTRO DE EDUCACIÓN PRIMARIA DE ADULTOS | J13: EXTENSION | K13: 0069DE0716 | L13: CENTRO DE ADULTOS Nº715/16 | N13: Urbano | O13: No | P13: Educación de Jóvenes y Adultos | Q13: Nivel Primario | R13: 21 | S13: 2 | T13: 0 | U13: Prim. NO EPA | W13: =+IF(V13="","",IF(V13="FINES",CONCATENATE("R",IF(OR(B13="16",B13="21",B13="22",B13="23"),"16212223",IF(OR(B13="15",B13="17",B13="24",B13="25"),"15172425",B13))),IF(V13="CEBAS","UNICO",IF(VALUE(B13)<=11,"AMBA","INTERIOR")))) | X13: =+IF(V13="","-",CONCATENATE(V13,"_",W13)) -> - | Y13: 0.016 | Z13: =IFERROR(IFERROR(VLOOKUP(G13,'IVSET-Escuelas'!A:F,4,FALSE),VLOOKUP(M13,'IVSET-Fines'!F:L,7,FALSE)),"-") -> 0.46857023
A14: Un.Serv. | B14: 05 | C14: 004 | D14: Almirante Brown | E14: 613277 | F14: 3 | G14: 0004DC0738 | H14: Oficial | I14: CENTRO DE EDUCACIÓN PRIMARIA DE ADULTOS | J14: EXTENSION | K14: 0004DE0701 | L14: CENTRO DE ADULTOS Nº738/01 | N14: Urbano | O14: No | P14: Educación de Jóvenes y Adultos | Q14: Nivel Primario | R14: 32 | S14: 2 | T14: 0 | U14: Prim. NO EPA | W14: =+IF(V14="","",IF(V14="FINES",CONCATENATE("R",IF(OR(B14="16",B14="21",B14="22",B14="23"),"16212223",IF(OR(B14="15",B14="17",B14="24",B14="25"),"15172425",B14))),IF(V14="CEBAS","UNICO",IF(VALUE(B14)<=11,"AMBA","INTERIOR")))) | X14: =+IF(V14="","-",CONCATENATE(V14,"_",W14)) -> - | Y14: 0.017 | Z14: =IFERROR(IFERROR(VLOOKUP(G14,'IVSET-Escuelas'!A:F,4,FALSE),VLOOKUP(M14,'IVSET-Fines'!F:L,7,FALSE)),"-") -> 0.49061516
A15: Un.Serv. | B15: 02 | C15: 005 | D15: Avellaneda | E15: 624498 | F15: 0 | G15: 2005DM9000 | H15: Nacional | I15: CENTRO EDUCATIVO DE NIVEL SECUNDARIO (C.E.N.S.) | J15: SEDE | L15: ESCUELA SECUNDARIA DE JÓVENES Y ADULTOS DE LA UNIVERSIDAD NACIONAL DE AVELLANEDA | N15: Urbano | O15: Sí | P15: Educación de Jóvenes y Adultos | Q15: Nivel Secundario | R15: 36 | S15: 2 | T15: 0 | U15: No Oficial | W15: =+IF(V15="","",IF(V15="FINES",CONCATENATE("R",IF(OR(B15="16",B15="21",B15="22",B15="23"),"16212223",IF(OR(B15="15",B15="17",B15="24",B15="25"),"15172425",B15))),IF(V15="CEBAS","UNICO",IF(VALUE(B15)<=11,"AMBA","INTERIOR")))) | X15: =+IF(V15="","-",CONCATENATE(V15,"_",W15)) -> - | Y15: 0.017 | Z15: =IFERROR(IFERROR(VLOOKUP(G15,'IVSET-Escuelas'!A:F,4,FALSE),VLOOKUP(M15,'IVSET-Fines'!F:L,7,FALSE)),"-") -> 0.089544587
A16: Un.Serv. | B16: 11 | C16: 015 | D16: Campana | E16: 605809 | F16: 1 | G16: 0015DC0703 | H16: Oficial | I16: CENTRO DE EDUCACIÓN PRIMARIA DE ADULTOS | J16: EXTENSION | K16: 0015DE0701 | L16: CENTRO DE ADULTOS Nº703/01 "RAFAEL OBLIGADO" | N16: Urbano | O16: No | P16: Educación de Jóvenes y Adultos | Q16: Nivel Primario | R16: 60 | S16: 4 | T16: 0 | U16: Prim. NO EPA | W16: =+IF(V16="","",IF(V16="FINES",CONCATENATE("R",IF(OR(B16="16",B16="21",B16="22",B16="23"),"16212223",IF(OR(B16="15",B16="17",B16="24",B16="25"),"15172425",B16))),IF(V16="CEBAS","UNICO",IF(VALUE(B16)<=11,"AMBA","INTERIOR")))) | X16: =+IF(V16="","-",CONCATENATE(V16,"_",W16)) -> - | Y16: 0.018 | Z16: =IFERROR(IFERROR(VLOOKUP(G16,'IVSET-Escuelas'!A:F,4,FALSE),VLOOKUP(M16,'IVSET-Fines'!F:L,7,FALSE)),"-") -> 0.42958769
A17: Un.Serv. | B17: 08 | C17: 071 | D17: Merlo | E17: 614527 | F17: 0 | G17: 0071DA0099 | H17: Oficial | I17: CENTRO DE ALFABETIZACIÓN | J17: SEDE | L17: CENTRO DE ALFABETIZACION Nº799/99 | N17: Urbano | O17: No | P17: Educación de Jóvenes y Adultos | Q17: Nivel Primario | R17: 10 | S17: 1 | T17: 0 | U17: Prim. NO EPA | W17: =+IF(V17="","",IF(V17="FINES",CONCATENATE("R",IF(OR(B17="16",B17="21",B17="22",B17="23"),"16212223",IF(OR(B17="15",B17="17",B17="24",B17="25"),"15172425",B17))),IF(V17="CEBAS","UNICO",IF(VALUE(B17)<=11,"AMBA","INTERIOR")))) | X17: =+IF(V17="","-",CONCATENATE(V17,"_",W17)) -> - | Y17: 0.019 | Z17: =IFERROR(IFERROR(VLOOKUP(G17,'IVSET-Escuelas'!A:F,4,FALSE),VLOOKUP(M17,'IVSET-Fines'!F:L,7,FALSE)),"-") -> 0.62854052
A18: Un.Serv. | B18: 05 | C18: 030 | D18: Esteban Echeverría | E18: 609164 | F18: 2 | G18: 0030DC0707 | H18: Oficial | I18: CENTRO DE EDUCACIÓN PRIMARIA DE ADULTOS | J18: EXTENSION | K18: 0030DE0701 | L18: CENTRO DE ADULTOS Nº707/01 | N18: Urbano | O18: No | P18: Educación de Jóvenes y Adultos | Q18: Nivel Primario | R18: 42 | S18: 3 | T18: 0 | U18: Prim. NO EPA | W18: =+IF(V18="","",IF(V18="FINES",CONCATENATE("R",IF(OR(B18="16",B18="21",B18="22",B18="23"),"16212223",IF(OR(B18="15",B18="17",B18="24",B18="25"),"15172425",B18))),IF(V18="CEBAS","UNICO",IF(VALUE(B18)<=11,"AMBA","INTERIOR")))) | X18: =+IF(V18="","-",CONCATENATE(V18,"_",W18)) -> - | Y18: 0.021 | Z18: =IFERROR(IFERROR(VLOOKUP(G18,'IVSET-Escuelas'!A:F,4,FALSE),VLOOKUP(M18,'IVSET-Fines'!F:L,7,FALSE)),"-") -> 0.62222159
A19: Un.Serv. | B19: 01 | C19: 001 | D19: La Plata | E19: 609115 | F19: 2 | G19: 0001DC0720 | H19: Oficial | I19: CENTRO DE EDUCACIÓN PRIMARIA DE ADULTOS | J19: EXTENSION | K19: 0001DE0713 | L19: CENTRO DE ADULTOS Nº720/13 | N19: Urbano | O19: No | P19: Educación de Jóvenes y Adultos | Q19: Nivel Primario | R19: 28 | S19: 2 | T19: 0 | U19: Prim. NO EPA | W19: =+IF(V19="","",IF(V19="FINES",CONCATENATE("R",IF(OR(B19="16",B19="21",B19="22",B19="23"),"16212223",IF(OR(B19="15",B19="17",B19="24",B19="25"),"15172425",B19))),IF(V19="CEBAS","UNICO",IF(VALUE(B19)<=11,"AMBA","INTERIOR")))) | X19: =+IF(V19="","-",CONCATENATE(V19,"_",W19)) -> - | Y19: 0.021 | Z19: =IFERROR(IFERROR(VLOOKUP(G19,'IVSET-Escuelas'!A:F,4,FALSE),VLOOKUP(M19,'IVSET-Fines'!F:L,7,FALSE)),"-") -> 0.31114101
A20: Un.Serv. | B20: 12 | C20: 098 | D20: San Pedro | E20: 613674 | F20: 0 | G20: 0098DC0702 | H20: Oficial | I20: CENTRO DE EDUCACIÓN PRIMARIA DE ADULTOS | J20: SEDE | L20: CENTRO DE ADULTOS Nº702 | N20: Urbano | O20: No | P20: Educación de Jóvenes y Adultos | Q20: Nivel Primario | R20: 21 | S20: 2 | T20: 0 | U20: Prim. NO EPA | W20: =+IF(V20="","",IF(V20="FINES",CONCATENATE("R",IF(OR(B20="16",B20="21",B20="22",B20="23"),"16212223",IF(OR(B20="15",B20="17",B20="24",B20="25"),"15172425",B20))),IF(V20="CEBAS","UNICO",IF(VALUE(B20)<=11,"AMBA","INTERIOR")))) | X20: =+IF(V20="","-",CONCATENATE(V20,"_",W20)) -> - | Y20: 0.022 | Z20: =IFERROR(IFERROR(VLOOKUP(G20,'IVSET-Escuelas'!A:F,4,FALSE),VLOOKUP(M20,'IVSET-Fines'!F:L,7,FALSE)),"-") -> 0.4542442
A21: Un.Serv. | B21: 02 | C21: 111 | D21: Lanús | E21: 608243 | F21: 4 | G21: 0111DC0715 | H21: Oficial | I21: CENTRO DE EDUCACIÓN PRIMARIA DE ADULTOS | J21: EXTENSION | K21: 0111DE0712 | L21: CENTRO DE ADULTOS Nº715/12 | N21: Urbano | O21: No | P21: Educación de Jóvenes y Adultos | Q21: Nivel Primario | R21: 31 | S21: 2 | T21: 0 | U21: Prim. NO EPA | W21: =+IF(V21="","",IF(V21="FINES",CONCATENATE("R",IF(OR(B21="16",B21="21",B21="22",B21="23"),"16212223",IF(OR(B21="15",B21="17",B21="24",B21="25"),"15172425",B21))),IF(V21="CEBAS","UNICO",IF(VALUE(B21)<=11,"AMBA","INTERIOR")))) | X21: =+IF(V21="","-",CONCATENATE(V21,"_",W21)) -> - | Y21: 0.023 | Z21: =IFERROR(IFERROR(VLOOKUP(G21,'IVSET-Escuelas'!A:F,4,FALSE),VLOOKUP(M21,'IVSET-Fines'!F:L,7,FALSE)),"-") -> 0.49882898
A22: Un.Serv. | B22: 12 | C22: 097 | D22: San Nicolás | E22: 600849 | F22: 1 | G22: 0097DC0711 | H22: Oficial | I22: CENTRO DE EDUCACIÓN PRIMARIA DE ADULTOS | J22: EXTENSION | K22: 0097DE0704 | L22: CENTRO DE ADULTOS Nº711/04 | N22: Urbano | O22: No | P22: Educación de Jóvenes y Adultos | Q22: Nivel Primario | R22: 23 | S22: 2 | T22: 0 | U22: Prim. NO EPA | W22: =+IF(V22="","",IF(V22="FINES",CONCATENATE("R",IF(OR(B22="16",B22="21",B22="22",B22="23"),"16212223",IF(OR(B22="15",B22="17",B22="24",B22="25"),"15172425",B22))),IF(V22="CEBAS","UNICO",IF(VALUE(B22)<=11,"AMBA","INTERIOR")))) | X22: =+IF(V22="","-",CONCATENATE(V22,"_",W22)) -> - | Y22: 0.027 | Z22: =IFERROR(IFERROR(VLOOKUP(G22,'IVSET-Escuelas'!A:F,4,FALSE),VLOOKUP(M22,'IVSET-Fines'!F:L,7,FALSE)),"-") -> 0.22675502
A23: Un.Serv. | B23: 03 | C23: 069 | D23: La Matanza | E23: 608696 | F23: 1 | G23: 0069DC0751 | H23: Oficial | I23: CENTRO DE EDUCACIÓN PRIMARIA DE ADULTOS | J23: EXTENSION | K23: 0069DE0705 | L23: CENTRO DE ADULTOS Nº751/05 | N23: Urbano | O23: No | P23: Educación de Jóvenes y Adultos | Q23: Nivel Primario | R23: 38 | S23: 3 | T23: 0 | U23: Prim. NO EPA | W23: =+IF(V23="","",IF(V23="FINES",CONCATENATE("R",IF(OR(B23="16",B23="21",B23="22",B23="23"),"16212223",IF(OR(B23="15",B23="17",B23="24",B23="25"),"15172425",B23))),IF(V23="CEBAS","UNICO",IF(VALUE(B23)<=11,"AMBA","INTERIOR")))) | X23: =+IF(V23="","-",CONCATENATE(V23,"_",W23)) -> - | Y23: 0.028 | Z23: =IFERROR(IFERROR(VLOOKUP(G23,'IVSET-Escuelas'!A:F,4,FALSE),VLOOKUP(M23,'IVSET-Fines'!F:L,7,FALSE)),"-") -> 0.47052127
A24: Un.Serv. | B24: 19 | C24: 033 | D24: General Alvarado | E24: 609292 | F24: 4 | G24: 0033DC0703 | H24: Oficial | I24: CENTRO DE EDUCACIÓN PRIMARIA DE ADULTOS | J24: EXTENSION | K24: 0033DE0701 | L24: CENTRO DE ADULTOS Nº703 "DR. EMILIO GALLINA" | N24: Urbano | O24: No | P24: Educación de Jóvenes y Adultos | Q24: Nivel Primario | R24: 35 | S24: 2 | T24: 0 | U24: Prim. NO EPA | W24: =+IF(V24="","",IF(V24="FINES",CONCATENATE("R",IF(OR(B24="16",B24="21",B24="22",B24="23"),"16212223",IF(OR(B24="15",B24="17",B24="24",B24="25"),"15172425",B24))),IF(V24="CEBAS","UNICO",IF(VALUE(B24)<=11,"AMBA","INTERIOR")))) | X24: =+IF(V24="","-",CONCATENATE(V24,"_",W24)) -> - | Y24: 0.029 | Z24: =IFERROR(IFERROR(VLOOKUP(G24,'IVSET-Escuelas'!A:F,4,FALSE),VLOOKUP(M24,'IVSET-Fines'!F:L,7,FALSE)),"-") -> 0.30283928
A25: Un.Serv. | B25: 13 | C25: 022 | D25: Colón | E25: 606543 | F25: 2 | G25: 0022DC0706 | H25: Oficial | I25: CENTRO DE EDUCACIÓN PRIMARIA DE ADULTOS | J25: EXTENSION | K25: 0022DE0701 | L25: CENTRO DE ADULTOS Nº706/01 | N25: Urbano | O25: No | P25: Educación de Jóvenes y Adultos | Q25: Nivel Primario | R25: 30 | S25: 3 | T25: 0 | U25: Prim. NO EPA | W25: =+IF(V25="","",IF(V25="FINES",CONCATENATE("R",IF(OR(B25="16",B25="21",B25="22",B25="23"),"16212223",IF(OR(B25="15",B25="17",B25="24",B25="25"),"15172425",B25))),IF(V25="CEBAS","UNICO",IF(VALUE(B25)<=11,"AMBA","INTERIOR")))) | X25: =+IF(V25="","-",CONCATENATE(V25,"_",W25)) -> - | Y25: 0.03 | Z25: =IFERROR(IFERROR(VLOOKUP(G25,'IVSET-Escuelas'!A:F,4,FALSE),VLOOKUP(M25,'IVSET-Fines'!F:L,7,FALSE)),"-") -> 0.32116765
A26: Un.Serv. | B26: 20 | C26: 075 | D26: Necochea | E26: 611210 | F26: 2 | G26: 0075DC0708 | H26: Oficial | I26: CENTRO DE EDUCACIÓN PRIMARIA DE ADULTOS | J26: EXTENSION | K26: 0075DE0702 | L26: CENTRO DE ADULTOS Nº708/02 | N26: Urbano | O26: No | P26: Educación de Jóvenes y Adultos | Q26: Nivel Primario | R26: 17 | S26: 1 | T26: 0 | U26: Prim. NO EPA | W26: =+IF(V26="","",IF(V26="FINES",CONCATENATE("R",IF(OR(B26="16",B26="21",B26="22",B26="23"),"16212223",IF(OR(B26="15",B26="17",B26="24",B26="25"),"15172425",B26))),IF(V26="CEBAS","UNICO",IF(VALUE(B26)<=11,"AMBA","INTERIOR")))) | X26: =+IF(V26="","-",CONCATENATE(V26,"_",W26)) -> - | Y26: 0.031 | Z26: =IFERROR(IFERROR(VLOOKUP(G26,'IVSET-Escuelas'!A:F,4,FALSE),VLOOKUP(M26,'IVSET-Fines'!F:L,7,FALSE)),"-") -> 0.6404568
A27: Un.Serv. | B27: 08 | C27: 100 | D27: Morón | E27: 613021 | F27: 1 | G27: 0100DC0709 | H27: Oficial | I27: CENTRO DE EDUCACIÓN PRIMARIA DE ADULTOS | J27: EXTENSION | K27: 0100DE0703 | L27: CENTRO DE ADULTOS Nº709/03 | N27: Urbano | O27: No | P27: Educación de Jóvenes y Adultos | Q27: Nivel Primario | R27: 42 | S27: 3 | T27: 0 | U27: Prim. NO EPA | W27: =+IF(V27="","",IF(V27="FINES",CONCATENATE("R",IF(OR(B27="16",B27="21",B27="22",B27="23"),"16212223",IF(OR(B27="15",B27="17",B27="24",B27="25"),"15172425",B27))),IF(V27="CEBAS","UNICO",IF(VALUE(B27)<=11,"AMBA","INTERIOR")))) | X27: =+IF(V27="","-",CONCATENATE(V27,"_",W27)) -> - | Y27: 0.032 | Z27: =IFERROR(IFERROR(VLOOKUP(G27,'IVSET-Escuelas'!A:F,4,FALSE),VLOOKUP(M27,'IVSET-Fines'!F:L,7,FALSE)),"-") -> 0.47159892
A28: Un.Serv. | B28: 11 | C28: 047 | D28: Zárate | E28: 605769 | F28: 2 | G28: 0047DC0710 | H28: Oficial | I28: CENTRO DE EDUCACIÓN PRIMARIA DE ADULTOS | J28: EXTENSION | K28: 0047DE0703 | L28: CENTRO DE ADULTOS Nº710/03 | N28: Urbano | O28: No | P28: Educación de Jóvenes y Adultos | Q28: Nivel Primario | R28: 13 | S28: 1 | T28: 0 | U28: Prim. NO EPA | W28: =+IF(V28="","",IF(V28="FINES",CONCATENATE("R",IF(OR(B28="16",B28="21",B28="22",B28="23"),"16212223",IF(OR(B28="15",B28="17",B28="24",B28="25"),"15172425",B28))),IF(V28="CEBAS","UNICO",IF(VALUE(B28)<=11,"AMBA","INTERIOR")))) | X28: =+IF(V28="","-",CONCATENATE(V28,"_",W28)) -> - | Y28: 0.036 | Z28: =IFERROR(IFERROR(VLOOKUP(G28,'IVSET-Escuelas'!A:F,4,FALSE),VLOOKUP(M28,'IVSET-Fines'!F:L,7,FALSE)),"-") -> 0.18618774
A29: Un.Serv. | B29: 20 | C29: 102 | D29: Tandil | E29: 610063 | F29: 2 | G29: 0102DC0707 | H29: Oficial | I29: CENTRO DE EDUCACIÓN PRIMARIA DE ADULTOS | J29: EXTENSION | K29: 0102DE0701 | L29: CENTRO DE ADULTOS Nº707 | N29: Urbano | O29: No | P29: Educación de Jóvenes y Adultos | Q29: Nivel Primario | R29: 9 | S29: 1 | T29: 0 | U29: Prim. NO EPA | W29: =+IF(V29="","",IF(V29="FINES",CONCATENATE("R",IF(OR(B29="16",B29="21",B29="22",B29="23"),"16212223",IF(OR(B29="15",B29="17",B29="24",B29="25"),"15172425",B29))),IF(V29="CEBAS","UNICO",IF(VALUE(B29)<=11,"AMBA","INTERIOR")))) | X29: =+IF(V29="","-",CONCATENATE(V29,"_",W29)) -> - | Y29: 0.037 | Z29: =IFERROR(IFERROR(VLOOKUP(G29,'IVSET-Escuelas'!A:F,4,FALSE),VLOOKUP(M29,'IVSET-Fines'!F:L,7,FALSE)),"-") -> 0.19442312
A30: Un.Serv. | B30: 07 | C30: 045 | D30: General San Martín | E30: 613580 | F30: 1 | G30: 0045DC0716 | H30: Oficial | I30: CENTRO DE EDUCACIÓN PRIMARIA DE ADULTOS | J30: EXTENSION | K30: 0045DE0705 | L30: CENTRO DE ADULTOS Nº716 | N30: Urbano | O30: No | P30: Educación de Jóvenes y Adultos | Q30: Nivel Primario | R30: 70 | S30: 4 | T30: 0 | U30: Prim. NO EPA | W30: =+IF(V30="","",IF(V30="FINES",CONCATENATE("R",IF(OR(B30="16",B30="21",B30="22",B30="23"),"16212223",IF(OR(B30="15",B30="17",B30="24",B30="25"),"15172425",B30))),IF(V30="CEBAS","UNICO",IF(VALUE(B30)<=11,"AMBA","INTERIOR")))) | X30: =+IF(V30="","-",CONCATENATE(V30,"_",W30)) -> - | Y30: 0.037 | Z30: =IFERROR(IFERROR(VLOOKUP(G30,'IVSET-Escuelas'!A:F,4,FALSE),VLOOKUP(M30,'IVSET-Fines'!F:L,7,FALSE)),"-") -> 0.2422518
A31: Un.Serv. | B31: 22 | C31: 078 | D31: Patagones | E31: 613144 | F31: 1 | G31: 0078DC0707 | H31: Oficial | I31: CENTRO DE EDUCACIÓN PRIMARIA DE ADULTOS | J31: EXTENSION | K31: 0078DE0709 | L31: CENTRO DE ADULTOS Nº707/09 | N31: Rural Disperso | O31: No | P31: Educación de Jóvenes y Adultos | Q31: Nivel Primario | R31: 41 | S31: 2 | T31: 0 | U31: Prim. NO EPA | W31: =+IF(V31="","",IF(V31="FINES",CONCATENATE("R",IF(OR(B31="16",B31="21",B31="22",B31="23"),"16212223",IF(OR(B31="15",B31="17",B31="24",B31="25"),"15172425",B31))),IF(V31="CEBAS","UNICO",IF(VALUE(B31)<=11,"AMBA","INTERIOR")))) | X31: =+IF(V31="","-",CONCATENATE(V31,"_",W31)) -> - | Y31: 0.038 | Z31: =IFERROR(IFERROR(VLOOKUP(G31,'IVSET-Escuelas'!A:F,4,FALSE),VLOOKUP(M31,'IVSET-Fines'!F:L,7,FALSE)),"-") -> 0.58696008
A32: Un.Serv. | B32: 02 | C32: 005 | D32: Avellaneda | E32: 600926 | F32: 1 | G32: 0005DC0719 | H32: Oficial | I32: CENTRO DE EDUCACIÓN PRIMARIA DE ADULTOS | J32: EXTENSION | K32: 0005DE0706 | L32: CENTRO DE ADULTOS Nº719/06 | N32: Urbano | O32: No | P32: Educación de Jóvenes y Adultos | Q32: Nivel Primario | R32: 19 | S32: 2 | T32: 0 | U32: Prim. NO EPA | W32: =+IF(V32="","",IF(V32="FINES",CONCATENATE("R",IF(OR(B32="16",B32="21",B32="22",B32="23"),"16212223",IF(OR(B32="15",B32="17",B32="24",B32="25"),"15172425",B32))),IF(V32="CEBAS","UNICO",IF(VALUE(B32)<=11,"AMBA","INTERIOR")))) | X32: =+IF(V32="","-",CONCATENATE(V32,"_",W32)) -> - | Y32: 0.043 | Z32: =IFERROR(IFERROR(VLOOKUP(G32,'IVSET-Escuelas'!A:F,4,FALSE),VLOOKUP(M32,'IVSET-Fines'!F:L,7,FALSE)),"-") -> 0.5362438
A33: Un.Serv. | B33: 18 | C33: 065 | D33: Maipú | E33: 613136 | F33: 0 | G33: 0065DC0702 | H33: Oficial | I33: CENTRO DE EDUCACIÓN PRIMARIA DE ADULTOS | J33: SEDE | L33: CENTRO DE ADULTOS Nº702"CECILIA MARCHETTI DE BASUALDO SILVA" | N33: Rural Agrupado | O33: No | P33: Educación de Jóvenes y Adultos | Q33: Nivel Primario | R33: 36 | S33: 5 | T33: 0 | U33: Prim. NO EPA | W33: =+IF(V33="","",IF(V33="FINES",CONCATENATE("R",IF(OR(B33="16",B33="21",B33="22",B33="23"),"16212223",IF(OR(B33="15",B33="17",B33="24",B33="25"),"15172425",B33))),IF(V33="CEBAS","UNICO",IF(VALUE(B33)<=11,"AMBA","INTERIOR")))) | X33: =+IF(V33="","-",CONCATENATE(V33,"_",W33)) -> - | Y33: 0.045 | Z33: =IFERROR(IFERROR(VLOOKUP(G33,'IVSET-Escuelas'!A:F,4,FALSE),VLOOKUP(M33,'IVSET-Fines'!F:L,7,FALSE)),"-") -> 0.27966228
A34: Un.Serv. | B34: 04 | C34: 032 | D34: Florencio Varela | E34: 608848 | F34: 1 | G34: 0032DC0710 | H34: Oficial | I34: CENTRO DE EDUCACIÓN PRIMARIA DE ADULTOS | J34: EXTENSION | K34: 0032DE0702 | L34: CENTRO DE ADULTOS Nº710/02 | N34: Urbano | O34: No | P34: Educación de Jóvenes y Adultos | Q34: Nivel Primario | R34: 38 | S34: 3 | T34: 0 | U34: Prim. NO EPA | W34: =+IF(V34="","",IF(V34="FINES",CONCATENATE("R",IF(OR(B34="16",B34="21",B34="22",B34="23"),"16212223",IF(OR(B34="15",B34="17",B34="24",B34="25"),"15172425",B34))),IF(V34="CEBAS","UNICO",IF(VALUE(B34)<=11,"AMBA","INTERIOR")))) | X34: =+IF(V34="","-",CONCATENATE(V34,"_",W34)) -> - | Y34: 0.046 | Z34: =IFERROR(IFERROR(VLOOKUP(G34,'IVSET-Escuelas'!A:F,4,FALSE),VLOOKUP(M34,'IVSET-Fines'!F:L,7,FALSE)),"-") -> 0.42184237
A35: Un.Serv. | B35: 03 | C35: 069 | D35: La Matanza | E35: 614422 | F35: 0 | G35: 0069DA0064 | H35: Oficial | I35: CENTRO DE ALFABETIZACIÓN | J35: SEDE | L35: CENTRO DE ALFABETIZACION Nº64 | N35: Urbano | O35: Sí | P35: Educación de Jóvenes y Adultos | Q35: Nivel Primario | R35: 6 | S35: 1 | T35: 0 | U35: Prim. NO EPA | W35: =+IF(V35="","",IF(V35="FINES",CONCATENATE("R",IF(OR(B35="16",B35="21",B35="22",B35="23"),"16212223",IF(OR(B35="15",B35="17",B35="24",B35="25"),"15172425",B35))),IF(V35="CEBAS","UNICO",IF(VALUE(B35)<=11,"AMBA","INTERIOR")))) | X35: =+IF(V35="","-",CONCATENATE(V35,"_",W35)) -> - | Y35: 0.05 | Z35: =IFERROR(IFERROR(VLOOKUP(G35,'IVSET-Escuelas'!A:F,4,FALSE),VLOOKUP(M35,'IVSET-Fines'!F:L,7,FALSE)),"-") -> 0.70109749
A36: Un.Serv. | B36: 06 | C36: 109 | D36: Vicente López | E36: 614402 | F36: 0 | G36: 0109DA0043 | H36: Oficial | I36: CENTRO DE ALFABETIZACIÓN | J36: SEDE | L36: CENTRO DE ALFABETIZACIÓN Nº 43 | N36: Urbano | O36: No | P36: Educación de Jóvenes y Adultos | Q36: Nivel Primario | R36: 14 | S36: 1 | T36: 0 | U36: Prim. NO EPA | W36: =+IF(V36="","",IF(V36="FINES",CONCATENATE("R",IF(OR(B36="16",B36="21",B36="22",B36="23"),"16212223",IF(OR(B36="15",B36="17",B36="24",B36="25"),"15172425",B36))),IF(V36="CEBAS","UNICO",IF(VALUE(B36)<=11,"AMBA","INTERIOR")))) | X36: =+IF(V36="","-",CONCATENATE(V36,"_",W36)) -> - | Y36: 0.05 | Z36: =IFERROR(IFERROR(VLOOKUP(G36,'IVSET-Escuelas'!A:F,4,FALSE),VLOOKUP(M36,'IVSET-Fines'!F:L,7,FALSE)),"-") -> 0.47727916
A37: Un.Serv. | B37: 06 | C37: 096 | D37: San Isidro | E37: 612075 | F37: 3 | G37: 0096DC0712 | H37: Oficial | I37: CENTRO DE EDUCACIÓN PRIMARIA DE ADULTOS | J37: EXTENSION | K37: 0096DE0702 | L37: CENTRO DE ADULTOS Nº712/02 | N37: Urbano | O37: No | P37: Educación de Jóvenes y Adultos | Q37: Nivel Primario | R37: 31 | S37: 2 | T37: 0 | U37: Prim. NO EPA | W37: =+IF(V37="","",IF(V37="FINES",CONCATENATE("R",IF(OR(B37="16",B37="21",B37="22",B37="23"),"16212223",IF(OR(B37="15",B37="17",B37="24",B37="25"),"15172425",B37))),IF(V37="CEBAS","UNICO",IF(VALUE(B37)<=11,"AMBA","INTERIOR")))) | X37: =+IF(V37="","-",CONCATENATE(V37,"_",W37)) -> - | Y37: 0.05 | Z37: =IFERROR(IFERROR(VLOOKUP(G37,'IVSET-Escuelas'!A:F,4,FALSE),VLOOKUP(M37,'IVSET-Fines'!F:L,7,FALSE)),"-") -> 0.12360836
A38: Un.Serv. | B38: 03 | C38: 069 | D38: La Matanza | E38: 612438 | F38: 1 | G38: 0069DC0701 | H38: Oficial | I38: CENTRO DE EDUCACIÓN PRIMARIA DE ADULTOS | J38: EXTENSION | K38: 0069DE0717 | L38: CENTRO DE ADULTOS Nº701/17 | N38: Urbano | O38: No | P38: Educación de Jóvenes y Adultos | Q38: Nivel Primario | R38: 24 | S38: 2 | T38: 0 | U38: Prim. NO EPA | W38: =+IF(V38="","",IF(V38="FINES",CONCATENATE("R",IF(OR(B38="16",B38="21",B38="22",B38="23"),"16212223",IF(OR(B38="15",B38="17",B38="24",B38="25"),"15172425",B38))),IF(V38="CEBAS","UNICO",IF(VALUE(B38)<=11,"AMBA","INTERIOR")))) | X38: =+IF(V38="","-",CONCATENATE(V38,"_",W38)) -> - | Y38: 0.051 | Z38: =IFERROR(IFERROR(VLOOKUP(G38,'IVSET-Escuelas'!A:F,4,FALSE),VLOOKUP(M38,'IVSET-Fines'!F:L,7,FALSE)),"-") -> 0.7205869
A39: Un.Serv. | B39: 03 | C39: 069 | D39: La Matanza | E39: 614426 | F39: 0 | G39: 0069DA0066 | H39: Oficial | I39: CENTRO DE ALFABETIZACIÓN | J39: SEDE | L39: CENTRO DE ALFABETIZACION Nº66 | N39: Urbano | O39: Sí | P39: Educación de Jóvenes y Adultos | Q39: Nivel Primario | R39: 15 | S39: 1 | T39: 0 | U39: Prim. NO EPA | W39: =+IF(V39="","",IF(V39="FINES",CONCATENATE("R",IF(OR(B39="16",B39="21",B39="22",B39="23"),"16212223",IF(OR(B39="15",B39="17",B39="24",B39="25"),"15172425",B39))),IF(V39="CEBAS","UNICO",IF(VALUE(B39)<=11,"AMBA","INTERIOR")))) | X39: =+IF(V39="","-",CONCATENATE(V39,"_",W39)) -> - | Y39: 0.051 | Z39: =IFERROR(IFERROR(VLOOKUP(G39,'IVSET-Escuelas'!A:F,4,FALSE),VLOOKUP(M39,'IVSET-Fines'!F:L,7,FALSE)),"-") -> 0.52353752
A40: Un.Serv. | B40: 05 | C40: 004 | D40: Almirante Brown | E40: 604372 | F40: 1 | G40: 0004DC0718 | H40: Oficial | I40: CENTRO DE EDUCACIÓN PRIMARIA DE ADULTOS | J40: EXTENSION | K40: 0004DE0704 | L40: CENTRO DE ADULTOS Nº718/04 | N40: Urbano | O40: No | P40: Educación de Jóvenes y Adultos | Q40: Nivel Primario | R40: 43 | S40: 2 | T40: 0 | U40: Prim. NO EPA | W40: =+IF(V40="","",IF(V40="FINES",CONCATENATE("R",IF(OR(B40="16",B40="21",B40="22",B40="23"),"16212223",IF(OR(B40="15",B40="17",B40="24",B40="25"),"15172425",B40))),IF(V40="CEBAS","UNICO",IF(VALUE(B40)<=11,"AMBA","INTERIOR")))) | X40: =+IF(V40="","-",CONCATENATE(V40,"_",W40)) -> - | Y40: 0.052 | Z40: =IFERROR(IFERROR(VLOOKUP(G40,'IVSET-Escuelas'!A:F,4,FALSE),VLOOKUP(M40,'IVSET-Fines'!F:L,7,FALSE)),"-") -> 0.27493885
...

Sheet IVSET-Escuelas
A1: clave | B1: latitud | C1: longitud | D1: Punto_raster_IVSE-t | E1: media_250m_IVSE-T | F1: Porcentaje_AUH
A2: 0001AD0003 | B2: -34.917432 | C2: -57.947606 | D2: 0.13444868 | E2: 0.093181876
A3: 0001AE0001 | B3: -34.914041 | C3: -57.957036 | D3: 0.0029242446 | E3: 0.016143949
A4: 0001AE0002 | B4: -34.934052 | C4: -57.924258 | D4: 0.35604137 | E4: 0.32585426
A5: 0001AM0001 | B5: -34.898111 | C5: -57.985056 | D5: 0.19307984 | E5: 0.26257108
A6: 0001AT0004 | B6: -34.911834 | C6: -57.945508 | D6: 0.10234319 | E6: 0.088648967
A7: 0001AZ0002 | B7: -34.917104 | C7: -57.969299 | D7: 0.084368311 | E7: 0.076364624
A8: 0001DC0705 | B8: -34.88878 | C8: -57.997967 | D8: 0.30924478 | E8: 0.23738976
A9: 0001DC0707 | B9: -34.872305 | C9: -58.116934 | D9: 0.39586118 | E9: 0.34502352
A10: 0001DC0711 | B10: -34.937468 | C10: -57.95327 | D10: 0.14532167 | E10: 0.080896558
A11: 0001DC0714 | B11: -34.984366 | C11: -58.088904 | D11: 0.58266002 | E11: 0.5947441
A12: 0001DC0715 | B12: -34.945717 | C12: -57.984382 | D12: 0.40709412 | E12: 0.40624795
A13: 0001DC0716 | B13: -34.953909 | C13: -57.887246 | D13: 0.74700058 | E13: 0.76729916
... A47: 0032DE0751 | B47: -34.938737 | C47: -58.262247 | D47: 0.75733387 | E47: 0.75037428
A48: 0001EE0503 | B48: -34.921832 | C48: -57.945208 | D48: 0.11648656 | E48: 0.12060837 | F48: 6.25
A49: 0001EE0509 | B49: -34.932187 | C49: -57.942834 | D49: 0.13560428 | E49: 0.16712956 | F49: 83.333333
A50: 0001EE0514 | B50: -34.897047 | C50: -57.962622 | D50: 0.1963584 | E50: 0.20344988 | F50: 15.47619
A51: 0001EE0515 | B51: -34.877393 | C51: -58.022081 | D51: 0.26609826 | E51: 0.2656987 | F51: 20.689655
A52: 0001EE0516 | B52: -34.937197 | C52: -58.043643 | D52: 0.71902817 | E52: 0.75216341 | F52: 25
A53: 0001EE0517 | B53: -34.915703 | C53: -57.958872 | D53: 0.077151783 | E53: 0.037127915 | F53: 16
A54: 0001EE0518 | B54: -34.917726 | C54: -57.961633 | D54: 0.048630156 | E54: 0.049050317
A55: 0001EE0524 | B55: -34.930772 | C55: -57.986787 | D55: 0.18906626 | E55: 0.16341141 | F55: 23.529412
A56: 0001EE0526 | B56: -34.923172 | C56: -57.940152 | D56: 0.20765352 | E56: 0.17901233 | F56: 10.416667
A57: 0001EE0527 | B57: -34.923361 | C57: -57.920333 | D57: 0.077023514 | E57: 0.15912183 | F57: 13.684211
A58: 0001EE0528 | B58: -34.939286 | C58: -57.966703 | D58: 0.031081999 | E58: 0.063239697 | F58: 42.857143
A59: 0001EE0529 | B59: -34.953523 | C59: -58.049251 | D59: 0.63018316 | E59: 0.63787164 | F59: 33
A60: 0001EE0531 | B60: -34.931516 | C60: -57.930067 | D60: 0.11542718 | E60: 0.11403315 | F60: 18.181818
A61: 0001EE0532 | B61: -34.949727 | C61: -57.930911 | D61: 0.56450373 | E61: 0.53287317 | F61: 34.782609
A62: 0001EE0533 | B62: -34.940804 | C62: -57.989908 | D62: 0.43035525 | E62: 0.43473143 | F62: 26.153846
A63: 0001EE0534 | B63: -34.892291 | C63: -57.949838 | D63: 0.40114614 | E63: 0.41970083 | F63: 25
A64: 0001EE0535 | B64: -34.959536 | C64: -57.972355 | D64: 0.24563694 | E64: 0.29873483 | F64: 31.746032
A65: 0001EE0536 | B65: -34.854153 | C65: -58.070634 | D65: 0.31553918 | E65: 0.36964738 | F65: 22.222222
A66: 0001EE0538 | B66: -34.912292 | C66: -57.99375 | D66: 0.6018517 | E66: 0.52342825 | F66: 7.3170732
... A68: 0001EL0003 | B68: -34.952495 | C68: -58.054703 | D68: 0.61787945 | E68: 0.62081539 | F68: 22.95082
A69: 0001FC0002 | B69: -34.914354 | C69: -57.98627 | D69: 0.49772549 | E69: 0.41403588
A70: 0001IS0008 | B70: -34.919934 | C70: -57.955448 | D70: 0.010914281 | E70: 0.041145138
A71: 0001IS0009 | B71: -34.908187 | C71: -57.947537 | D71: 0.13760553 | E71: 0.13750143
A72: 0001IS0012 | B72: -34.933972 | C72: -57.924282 | D72: 0.35001025 | E72: 0.32585426
A73: 0001IS0017 | B73: -34.931359 | C73: -57.938021 | D73: 0.13952422 | E73: 0.14034021
A74: 0001IS0094 | B74: -34.879748 | C74: -58.060214 | D74: 0.13452512 | E74: 0.10997262
...

Sheet IVSET-Fines
A1: Región | B1: Distrito | C1: Clave | D1: Código de Sede | E1: Nombre Sede | F1: Nombre-Distrito | G1: Tipo Organización | H1: Dirección Sede | I1: Dirección sede Georreferenciada | J1: lat_final | K1: long_final | L1: IVSET
A2: 1 | B2: La Plata | C2: 0001DM0452 | D2: 1739 ( 1-452/1739 ) | E2: Felipe Vallese (ex Olimpia, Unidad Basica) | F2: =CONCATENATE(E2,B2) -> Felipe Vallese (ex Olimpia, Unidad Basica)La Plata | G2: Social | H2: Calle 71 2919 e/ 153 y 154 La Plata Los Hornos | I2: Calle 71 2919 e/ 153 y 154 La Plata Los Hornos, Provincia de Buenos Aires, Argentina | J2: -34.973677 | K2: -57.976805 | L2: 0.513351
A3: 1 | B3: La Plata | C3: 0001DM0452 | D3: 717 ( 1-452/717 ) | E3: La Patriada (centro Comunal Integrador La Patriada | F3: =CONCATENATE(E3,B3) -> La Patriada (centro Comunal Integrador La PatriadaLa Plata | G3: Otros | H3: Calle 27 e/ 89 y 90 La Plata Altos De San Lorenzo | I3: Calle 27 e/ 89 y 90 La Plata Altos De San Lorenzo, Provincia de Buenos Aires, Argentina | J3: -34.943266 | K3: -57.910604 | L3: 0.273197
A4: 1 | B4: La Plata | C4: 0001DM0452 | D4: 3103 ( 1-452/3103 ) | E4: Oga Guazu | F4: =CONCATENATE(E4,B4) -> Oga GuazuLa Plata | G4: Asociacion Civil | H4: Calle 609 e/ 118 La Plata Villa Elvira | I4: Calle 609 e/ 118 La Plata Villa Elvira, Provincia de Buenos Aires, Argentina | J4: -34.944367 | K4: -57.880542 | L4: 0.800593
A5: 1 | B5: La Plata | C5: 0001DM0452 | D5: 3770 ( 1-452/3770 ) | E5: Néstor Y Cristina | F5: =CONCATENATE(E5,B5) -> Néstor Y CristinaLa Plata | H5: Calle 82 S)N e/ 1 y 115 La Plata Villa Elvira | I5: Calle 82 S)N e/ 1 y 115 La Plata Villa Elvira, Provincia de Buenos Aires, Argentina | J5: -34.946408 | K5: -57.925671 | L5: 0.635275
A6: 1 | B6: La Plata | C6: 0001DM0452 | D6: 1323 ( 1-452/1323 ) | E6: Comedor Futuro La Capitana | F6: =CONCATENATE(E6,B6) -> Comedor Futuro La CapitanaLa Plata | G6: Social | H6: Calle 80 e/ Entre 16 y 17 La Plata La Plata | I6: Calle 80 e/ Entre 16 y 17 La Plata La Plata, Provincia de Buenos Aires, Argentina | J6: -34.945546 | K6: -57.928822 | L6: 0.497603
A7: 1 | B7: La Plata | C7: 0001DM0452 | D7: 793 ( 1-452/793 ) | E7: EducaciÓn Nacional Y Popular | F7: =CONCATENATE(E7,B7) -> EducaciÓn Nacional Y PopularLa Plata | G7: Otros | H7: Calle 601 e/ 7 y 8 La Plata Aeropuerto | I7: Calle 601 e/ 7 y 8 La Plata Aeropuerto, Provincia de Buenos Aires, Argentina | J7: -34.951532 | K7: -57.901375 | L7: 0.695643
A8: 1 | B8: La Plata | C8: 0001DM0452 | D8: 984 ( 1-452/984 ) | E8: Por Un Futuro Mejor | F8: =CONCATENATE(E8,B8) -> Por Un Futuro MejorLa Plata | G8: Asociacion Civil | H8: Calle 20 e/ Esq. 84 La Plata Altos De San Lorenzo | I8: Calle 20 e/ Esq. 84 La Plata Altos De San Lorenzo, Provincia de Buenos Aires, Argentina | J8: -34.953986 | K8: -57.926865 | L8: 0.60812
A9: 1 | B9: La Plata | C9: 0001DM0452 | D9: 1105 ( 1-452/1105 ) | E9: Hospital San Martin/la Campora | F9: =CONCATENATE(E9,B9) -> Hospital San Martin/la CamporaLa Plata | G9: Otros | H9: Calle 1 e/ 70 y 71 La Plata Villa Elvira | I9: Calle 1 e/ 70 y 71 La Plata Villa Elvira, Provincia de Buenos Aires, Argentina | J9: -34.92378 | K9: -57.924186 | L9: 0.310424
A10: 1 | B10: La Plata | C10: 0001DM0452 | D10: 718 ( 1-452/718 ) | E10: Kuña Joaju | F10: =CONCATENATE(E10,B10) -> Kuña JoajuLa Plata | G10: Otros | H10: Calle 7 e/ 601 La Plata Villa Elvira | I10: Calle 7 e/ 601 La Plata Villa Elvira, Provincia de Buenos Aires, Argentina | J10: -34.951532 | K10: -57.901375 | L10: 0.695643
A11: 1 | B11: La Plata | C11: 0001DM0452 | D11: 1279 ( 1-452/1279 ) | E11: Amet La Plata (sindicato Amet) | F11: =CONCATENATE(E11,B11) -> Amet La Plata (sindicato Amet)La Plata | G11: EducativaGremial/Sindical | H11: Calle 56 1048 e/ Esquina 16 La Plata La Plata | I11: Calle 56 1048 e/ Esquina 16 La Plata La Plata, Provincia de Buenos Aires, Argentina | J11: -34.92626 | K11: -57.95472 | L11: 0.16347
A12: 1 | B12: La Plata | C12: 0001DM0452 | D12: 1218 ( 1-452/1218 ) | E12: Cosmiko Shirley La Bombon | F12: =CONCATENATE(E12,B12) -> Cosmiko Shirley La BombonLa Plata | G12: Social | H12: Cale 10 e/ Calle Esquina 71 La Plata La Plata | I12: Cale 10 e/ Calle Esquina 71 La Plata La Plata, Provincia de Buenos Aires, Argentina | J12: -34.933025 | K12: -57.93225 | L12: 0.134272
A13: 1 | B13: La Plata | C13: 0001DM0452 | D13: 622 ( 1-452/622 ) | E13: Casa Nuestramerica | F13: =CONCATENATE(E13,B13) -> Casa NuestramericaLa Plata | G13: Otros | H13: Diagonal 75 378 e/ 4 y 58 La Plata Centro | I13: Diagonal 75 378 e/ 4 y 58 La Plata Centro, Provincia de Buenos Aires, Argentina | J13: -34.93186 | K13: -57.951313 | L13: 0.044786
A14: 1 | B14: La Plata | C14: 0001DM0453 | D14: 1240 ( 1-453/1240 ) | E14: Bachillerato Popular Letra Libre Hornos | F14: =CONCATENATE(E14,B14) -> Bachillerato Popular Letra Libre HornosLa Plata | G14: Otros | H14: Calle 66 3313 La Plata Los Hornos | I14: Calle 66 3313 La Plata Los Hornos, Provincia de Buenos Aires, Argentina | J14: -35.0143 | K14: -58.031779 | L14: 0.713492
A15: 1 | B15: La Plata | C15: 0001DM0453 | D15: 1773 ( 1-453/1773 ) | E15: Gimnasia Y Esgrima La Plata | F15: =CONCATENATE(E15,B15) -> Gimnasia Y Esgrima La PlataLa Plata | G15: Social | H15: Calle 58 e/ Esquina 123 La Plata La Plata | I15: Calle 58 e/ Esquina 123 La Plata La Plata, Provincia de Buenos Aires, Argentina | J15: -35.022966 | K15: -58.057882 | L15: 0.713492
A16: 1 | B16: La Plata | C16: 0001DM0453 | D16: 1082 ( 1-453/1082 ) | E16: Facultad De Periodismo | F16: =CONCATENATE(E16,B16) -> Facultad De PeriodismoLa Plata | G16: EducativaGremial/Sindical | H16: Diag. 113 N° 291 La Plata La Plata | I16: Diag. 113 N° 291 La Plata La Plata, Provincia de Buenos Aires, Argentina | J16: -34.913001 | K16: -57.927895 | L16: 0.175325
A17: 1 | B17: La Plata | C17: 0001DM0453 | D17: 1239 ( 1-453/1239 ) | E17: Centro Cultural Jei | F17: =CONCATENATE(E17,B17) -> Centro Cultural JeiLa Plata | G17: Social | H17: Calle 140 e/ Esquina 525 La Plata San Carlos | I17: Calle 140 e/ Esquina 525 La Plata San Carlos, Provincia de Buenos Aires, Argentina | J17: -34.92601 | K17: -58.011341 | L17: 0.813556
... A21: 1 | B21: La Plata | C21: 0001DM0453 | D21: 3862 ( 1-453/3862 ) | E21: Ctat (fines Movimiento Mayo) | F21: =CONCATENATE(E21,B21) -> Ctat (fines Movimiento Mayo)La Plata | G21: Gremial/Sindical | H21: Calle 51 e/ 10 y 11 La Plata Centro | I21: Calle 51 e/ 10 y 11 La Plata Centro, Provincia de Buenos Aires, Argentina | J21: -34.918113 | K21: -57.952185 | L21: 0.107468
A22: 1 | B22: La Plata | C22: 0001DM0453 | D22: 1273 ( 1-453/1273 ) | E22: Hospital Reencuentro | F22: =CONCATENATE(E22,B22) -> Hospital ReencuentroLa Plata | G22: Gubernamental | H22: Calle 64 e/ 5 y 6 La Plata Centro | I22: Calle 64 e/ 5 y 6 La Plata Centro, Provincia de Buenos Aires, Argentina | J22: -34.922166481237625 | K22: -57.93499282541837 | L22: 0.205068
A23: 1 | B23: La Plata | C23: 0001DM0453 | D23: 3861 ( 1-453/3861 ) | E23: Club Los Abuelos | F23: =CONCATENATE(E23,B23) -> Club Los AbuelosLa Plata | G23: Otros | H23: Calle 20 e/ 20 y 21 La Plata La Plata | I23: Calle 20 e/ 20 y 21 La Plata La Plata, Provincia de Buenos Aires, Argentina | J23: -34.967202 | K23: -57.908896 | L23: 0.685072
A24: 1 | B24: La Plata | C24: 0001DM0453 | D24: 1241 ( 1-453/1241 ) | E24: Bachillerato Popular Letra Libre Futuro | F24: =CONCATENATE(E24,B24) -> Bachillerato Popular Letra Libre FuturoLa Plata | G24: Otros | H24: Calle 32 e/ 156 y 157 La Plata Melchor Romero | I24: Calle 32 e/ 156 y 157 La Plata Melchor Romero, Provincia de Buenos Aires, Argentina | J24: -34.946841 | K24: -58.019738 | L24: 0.775656
A25: 1 | B25: La Plata | C25: 0001DM0453 | D25: 3285 ( 1-453/3285 ) | E25: El Subsuelo | F25: =CONCATENATE(E25,B25) -> El SubsueloLa Plata | G25: Otros | H25: Calle 1 441 La Plata Centro | I25: Calle 1 441 La Plata Centro, Provincia de Buenos Aires, Argentina | J25: -34.902385442964786 | K25: -57.952976082694946 | L25: 0.079649
A26: 1 | B26: La Plata | C26: 0001DM0453 | D26: 1234 ( 1-453/1234 ) | E26: Comunidad Ferroviaria | F26: =CONCATENATE(E26,B26) -> Comunidad FerroviariaLa Plata | G26: Social | H26: Calle 3 e/ Esquina 526 La Plata Tolosa | I26: Calle 3 e/ Esquina 526 La Plata Tolosa, Provincia de Buenos Aires, Argentina | J26: -34.896384 | K26: -57.965824 | L26: 0.256084
A27: 1 | B27: La Plata | C27: 0001DM0457 | D27: 17 ( 1-457/17 ) | E27: Construyendo Nuevos Horizontes (mup) | F27: =CONCATENATE(E27,B27) -> Construyendo Nuevos Horizontes (mup)La Plata | G27: Social | H27: Calle 63 e/ 153 y 154 La Plata Los Hornos | I27: Calle 63 e/ 153 y 154 La Plata Los Hornos, Provincia de Buenos Aires, Argentina | J27: -34.915026 | K27: -57.929222 | L27: 0.135024
A28: 1 | B28: La Plata | C28: 0001DM0457 | D28: 15 ( 1-457/15 ) | E28: Infernales | F28: =CONCATENATE(E28,B28) -> InfernalesLa Plata | G28: EducativaGremial/Sindical | H28: Calle 157 1611 e/ 65 y 66 La Plata Los Hornos | I28: Calle 157 1611 e/ 65 y 66 La Plata Los Hornos, Provincia de Buenos Aires, Argentina | J28: -34.972336 | K28: -57.987769 | L28: 0.404633
A29: 1 | B29: La Plata | C29: 0001DM0457 | D29: 18 ( 1-457/18 ) | E29: Creciendo Juntos (mup) | F29: =CONCATENATE(E29,B29) -> Creciendo Juntos (mup)La Plata | G29: Social | H29: Calle 147 e/ 61 y 62 La Plata Los Hornos | I29: Calle 147 e/ 61 y 62 La Plata Los Hornos, Provincia de Buenos Aires, Argentina | J29: -34.939453 | K29: -58.009124 | L29: 0.641204
A30: 1 | B30: La Plata | C30: 0001DM0457 | D30: 10 ( 1-457/10 ) | E30: Hogar De Dia San Cayetano | F30: =CONCATENATE(E30,B30) -> Hogar De Dia San CayetanoLa Plata | G30: Religiosa | H30: Calle 37 e/ 135 y 136 La Plata San Carlos | I30: Calle 37 e/ 135 y 136 La Plata San Carlos, Provincia de Buenos Aires, Argentina | J30: -34.930553 | K30: -57.996121 | L30: 0.517265
A31: 1 | B31: La Plata | C31: 0001DM0457 | D31: 1216 ( 1-457/1216 ) | E31: Los Libros No Muerden | F31: =CONCATENATE(E31,B31) -> Los Libros No MuerdenLa Plata | G31: Otros | H31: Calle 60 e/ Calle 144 Club San Martin La Plata Los Hornos | I31: Calle 60 e/ Calle 144 Club San Martin La Plata Los Hornos, Provincia de Buenos Aires, Argentina | J31: -34.956426 | K31: -57.980732 | L31: 0.405463
A32: 1 | B32: La Plata | C32: 0001DM0457 | D32: 1291 ( 1-457/1291 ) | E32: Los Libros No Muerden | F32: =CONCATENATE(E32,B32) -> Los Libros No MuerdenLa Plata | G32: Social | H32: Calle 60 e/ 144 La Plata Los Hornos | I32: Calle 60 e/ 144 La Plata Los Hornos, Provincia de Buenos Aires, Argentina | J32: -34.956426 | K32: -57.980732 | L32: 0.405463
A33: 1 | B33: La Plata | C33: 0001DM0462 | D33: 3146 ( 1-462/3146 ) | E33: Corazones Unidos De Tolosa | F33: =CONCATENATE(E33,B33) -> Corazones Unidos De TolosaLa Plata | G33: Social | H33: Calle 4 e/ Y Calle 521 La Plata Tolosa | I33: Calle 4 e/ Y Calle 521 La Plata Tolosa, Provincia de Buenos Aires, Argentina | J33: -34.8882279012719 | K33: -57.97839579844126 | L33: 0.286463
A34: 1 | B34: La Plata | C34: 0001DM0457 | D34: 3871 ( 1-457/3871 ) | E34: Polideportivo Los Hornos | F34: =CONCATENATE(E34,B34) -> Polideportivo Los HornosLa Plata | G34: Deportiva | H34: Calle 66 2851 e/ 152 y 153 La Plata Los Hornos | I34: Calle 66 2851 e/ 152 y 153 La Plata Los Hornos, Provincia de Buenos Aires, Argentina | J34: -34.987825 | K34: -58.002714 | L34: 0.489598
A35: 1 | B35: La Plata | C35: 0001DM0457 | D35: 3991 ( 1-457/3991 ) | E35: PantalÓn Cortito | F35: =CONCATENATE(E35,B35) -> PantalÓn CortitoLa Plata | G35: Asociacion Civil | H35: Calle 139 425 La Plata Los Hornos | I35: Calle 139 425 La Plata Los Hornos, Provincia de Buenos Aires, Argentina | J35: -34.901522 | K35: -58.06177 | L35: 0.43346
A36: 1 | B36: La Plata | C36: 0001DM0457 | D36: 3715 ( 1-457/3715 ) | E36: Ex Planeadores | F36: =CONCATENATE(E36,B36) -> Ex PlaneadoresLa Plata | G36: Social | H36: 147bis e/ 77 y 78 La Plata Los Hornos | I36: 147bis e/ 77 y 78 La Plata Los Hornos, Provincia de Buenos Aires, Argentina | J36: -35.028202 | K36: -57.942611 | L36: 0.697339
A37: 1 | B37: La Plata | C37: 0001DM0460 | D37: 1707 ( 1-460/1707 ) | E37: Club Corazones Del Retiro | F37: =CONCATENATE(E37,B37) -> Club Corazones Del RetiroLa Plata | G37: Otros | H37: Calle 160 e/ 48 y 49 La Plata Olmos | I37: Calle 160 e/ 48 y 49 La Plata Olmos, Provincia de Buenos Aires, Argentina | J37: -35.007142 | K37: -58.052979 | L37: 0.895143
A38: 1 | B38: La Plata | C38: 0001DM0460 | D38: 1710 ( 1-460/1710 ) | E38: Centro De Formación Profesional N 411 | F38: =CONCATENATE(E38,B38) -> Centro De Formación Profesional N 411La Plata | G38: Otros | H38: Calle 518 e/ 170 y 171 La Plata Melchor Romero | I38: Calle 518 e/ 170 y 171 La Plata Melchor Romero, Provincia de Buenos Aires, Argentina | J38: -34.949171 | K38: -58.051613 | L38: 0.607981
A39: 1 | B39: La Plata | C39: 0001DM0460 | D39: 1714 ( 1-460/1714 ) | E39: Cib Las Rosas | F39: =CONCATENATE(E39,B39) -> Cib Las RosasLa Plata | G39: Otros | H39: Calle 516 e/ 158 y 159 La Plata Melchor Romero | I39: Calle 516 e/ 158 y 159 La Plata Melchor Romero, Provincia de Buenos Aires, Argentina | J39: -34.935472 | K39: -58.041854 | L39: 0.855044
A40: 1 | B40: La Plata | C40: 0001DM0460 | D40: 1716 ( 1-460/1716 ) | E40: La Abanderada | F40: =CONCATENATE(E40,B40) -> La AbanderadaLa Plata | G40: Otros | H40: Calle 54 e/ 193 y 194 La Plata Olmos | I40: Calle 54 e/ 193 y 194 La Plata Olmos, Provincia de Buenos Aires, Argentina | J40: -34.997609 | K40: -58.036108 | L40: 0.577688
A41: 1 | B41: La Plata | C41: 0001DM0460 | D41: 3179 ( 1-460/3179 ) | E41: Asociacion Civil Los Mimosos Del Centinela | F41: =CONCATENATE(E41,B41) -> Asociacion Civil Los Mimosos Del CentinelaLa Plata | G41: Asociacion Civil | H41: Calle 47 e/ 171 y 172 La Plata Olmos | I41: Calle 47 e/ 171 y 172 La Plata Olmos, Provincia de Buenos Aires, Argentina | J41: -34.973568 | K41: -58.018069 | L41: 0.627637
A42: 1 | B42: La Plata | C42: 0001DM0460 | D42: 3716 ( 1-460/3716 ) | E42: La Usina (la Cámpora) | F42: =CONCATENATE(E42,B42) -> La Usina (la Cámpora)La Plata | H42: Calle 138 e/ 32 y 33 La Plata San Carlos | I42: Calle 138 e/ 32 y 33 La Plata San Carlos, Provincia de Buenos Aires, Argentina | J42: -34.901402 | K42: -58.056489 | L42: 0.492823
A43: 1 | B43: La Plata | C43: 0001DM0460 | D43: 3718 ( 1-460/3718 ) | E43: Facundo Cabral | F43: =CONCATENATE(E43,B43) -> Facundo CabralLa Plata | H43: Calle 42 3279 e/ 160 Bis y 161 La Plata Olmos | I43: Calle 42 3279 e/ 160 Bis y 161 La Plata Olmos, Provincia de Buenos Aires, Argentina | J43: -34.958991 | K43: -58.01246 | L43: 0.66369
...

Sheet Estratos
K1: Oferta | L1: Muestra (estud.) por estrato geográfico | N1: Universo | Q1: Muestra (Aprox.)
B2: unidades | C2: secciones | D2: matrícula | E2: error_% | F2: deff | G2: secciones (5 ExS) | H2: unidades | I2: tamaño muestra (z=90%, p=50%, deff=2) | N2: Unidades de Servicio | O2: Secciones | P2: Estudiantes | Q2: Unidades de Servicio | R2: Secciones | S2: Estudiantes
A3: EPA_AMBA | B3: =+COUNTIF(Nómina!X:X,A3) -> 225 | C3: =+SUMIF(Nómina!X:X,A3,Nómina!S:S) -> 2238 | D3: =+SUMIF(Nómina!X:X,A3,Nómina!R:R) -> 31241 | E3: 3 | F3: 2 | G3: =+MIN(C3,I3/5) -> 293.61434 | H3: =MIN(B3,G3/C3*B3) -> 29.518868 | I3: =+(D3*POWER(1.645,2)*(0.5*0.5))/(POWER(E3/100,2)*(D3-1)+POWER(1.645,2)*(0.5*0.5))*F3 -> 1468.0717 | K3: EPA | L3: x Zona (2) | M3: 1500 | N3: =+COUNTIF(Nómina!V:V,Estratos!K3) -> 334 | O3: =+SUMIF(Nómina!V:V,Estratos!K3,Nómina!S:S) -> 2921 | P3: =+SUMIF(Nómina!V:V,Estratos!K3,Nómina!R:R) -> 40995 | Q3: =+H3+H4 -> 74.073748 | R3: =+G3+G4 -> 572.79767 | S3: =+I3+I4 -> 2863.9883
A4: EPA_INTERIOR | B4: =+COUNTIF(Nómina!X:X,A4) -> 109 | C4: =+SUMIF(Nómina!X:X,A4,Nómina!S:S) -> 683 | D4: =+SUMIF(Nómina!X:X,A4,Nómina!R:R) -> 9754 | E4: 3 | F4: 2 | G4: =+MIN(C4,I4/5) -> 279.18333 | H4: =MIN(B4,G4/C4*B4) -> 44.55488 | I4: =+(D4*POWER(1.645,2)*(0.5*0.5))/(POWER(E4/100,2)*(D4-1)+POWER(1.645,2)*(0.5*0.5))*F4 -> 1395.9167 | K4: CEBAS | L4: Único | M4: 500 | N4: =+COUNTIF(Nómina!V:V,Estratos!K4) -> 20 | O4: =+SUMIF(Nómina!V:V,Estratos!K4,Nómina!S:S) -> 90 | P4: =+SUMIF(Nómina!V:V,Estratos!K4,Nómina!R:R) -> 1590 | Q4: =+H5 -> 20 | R4: =+G5 -> 90 | S4: =+I5 -> 765.90839
A5: CEBAS_UNICO | B5: =+COUNTIF(Nómina!X:X,A5) -> 20 | C5: =+SUMIF(Nómina!X:X,A5,Nómina!S:S) -> 90 | D5: =+SUMIF(Nómina!X:X,A5,Nómina!R:R) -> 1590 | E5: 3 | F5: 1.5 | G5: =+MIN(C5,I5/5) -> 90 | H5: =MIN(B5,G5/C5*B5) -> 20 | I5: =+(D5*POWER(1.645,2)*(0.5*0.5))/(POWER(E5/100,2)*(D5-1)+POWER(1.645,2)*(0.5*0.5))*F5 -> 765.90839 | K5: CENS | L5: x Zona (2) | M5: 1500 | N5: =+COUNTIF(Nómina!V:V,Estratos!K5) -> 534 | O5: =+SUMIF(Nómina!V:V,Estratos!K5,Nómina!S:S) -> 4404 | P5: =+SUMIF(Nómina!V:V,Estratos!K5,Nómina!R:R) -> 80793 | Q5: =+H6+H7 -> 75.005257 | R5: =+G6+G7 -> 587.91427 | S5: =+I6+I7 -> 2939.5714
A6: CENS_AMBA | B6: =+COUNTIF(Nómina!X:X,A6) -> 354 | C6: =+SUMIF(Nómina!X:X,A6,Nómina!S:S) -> 3144 | D6: =+SUMIF(Nómina!X:X,A6,Nómina!R:R) -> 57989 | E6: 3 | F6: 2 | G6: =+MIN(C6,I6/5) -> 296.82699 | H6: =MIN(B6,G6/C6*B6) -> 33.421359 | I6: =+(D6*POWER(1.645,2)*(0.5*0.5))/(POWER(E6/100,2)*(D6-1)+POWER(1.645,2)*(0.5*0.5))*F6 -> 1484.1349 | K6: FINES | L6: x Región (17)- Grupo (2) | M6: 370-530 | N6: =+COUNTIF(Nómina!V:V,Estratos!K6) -> 2190 | O6: =+SUMIF(Nómina!V:V,Estratos!K6,Nómina!S:S) -> 3728 | P6: =+SUMIF(Nómina!V:V,Estratos!K6,Nómina!R:R) -> 75049 | Q6: =+SUM(H8:H26) -> 911.41662 | R6: =+SUM(G8:G26) -> 1454.6634 | S6: =+SUM(I8:I26) -> 7321.0965
A7: CENS_INTERIOR | B7: =+COUNTIF(Nómina!X:X,A7) -> 180 | C7: =+SUMIF(Nómina!X:X,A7,Nómina!S:S) -> 1260 | D7: =+SUMIF(Nómina!X:X,A7,Nómina!R:R) -> 22804 | E7: 3 | F7: 2 | G7: =+MIN(C7,I7/5) -> 291.08729 | H7: =MIN(B7,G7/C7*B7) -> 41.583898 | I7: =+(D7*POWER(1.645,2)*(0.5*0.5))/(POWER(E7/100,2)*(D7-1)+POWER(1.645,2)*(0.5*0.5))*F7 -> 1455.4364 | K7: Total | L7: - | M7: - | N7: =+SUM(N3:N6) -> 3078 | O7: =+SUM(O3:O6) -> 11143 | P7: =+SUM(P3:P6) -> 198427 | Q7: =+SUM(Q3:Q6) -> 1080.4956 | R7: =+SUM(R3:R6) -> 2705.3754 | S7: =+SUM(S3:S6) -> 13890.565
A8: FINES_R01 | B8: =+COUNTIF(Nómina!X:X,A8) -> 172 | C8: =+SUMIF(Nómina!X:X,A8,Nómina!S:S) -> 250 | D8: =+SUMIF(Nómina!X:X,A8,Nómina!R:R) -> 4188 | E8: 5 | F8: 1.5 | G8: =+MIN(C8,I8/5) -> 76.270816 | H8: =MIN(B8,G8/C8*B8) -> 52.474322 | I8: =+(D8*POWER(1.645,2)*(0.5*0.5))/(POWER(E8/100,2)*(D8-1)+POWER(1.645,2)*(0.5*0.5))*F8 -> 381.35408
A9: FINES_R02 | B9: =+COUNTIF(Nómina!X:X,A9) -> 191 | C9: =+SUMIF(Nómina!X:X,A9,Nómina!S:S) -> 308 | D9: =+SUMIF(Nómina!X:X,A9,Nómina!R:R) -> 5612 | E9: 5 | F9: 1.5 | G9: =+MIN(C9,I9/5) -> 77.459565 | H9: =MIN(B9,G9/C9*B9) -> 48.03499 | I9: =+(D9*POWER(1.645,2)*(0.5*0.5))/(POWER(E9/100,2)*(D9-1)+POWER(1.645,2)*(0.5*0.5))*F9 -> 387.29782
A10: FINES_R03 | B10: =+COUNTIF(Nómina!X:X,A10) -> 234 | C10: =+SUMIF(Nómina!X:X,A10,Nómina!S:S) -> 482 | D10: =+SUMIF(Nómina!X:X,A10,Nómina!R:R) -> 10911 | E10: 5 | F10: 1.5 | G10: =+MIN(C10,I10/5) -> 79.223205 | H10: =MIN(B10,G10/C10*B10) -> 38.461058 | I10: =+(D10*POWER(1.645,2)*(0.5*0.5))/(POWER(E10/100,2)*(D10-1)+POWER(1.645,2)*(0.5*0.5))*F10 -> 396.11602
A11: FINES_R04 | B11: =+COUNTIF(Nómina!X:X,A11) -> 181 | C11: =+SUMIF(Nómina!X:X,A11,Nómina!S:S) -> 317 | D11: =+SUMIF(Nómina!X:X,A11,Nómina!R:R) -> 6828 | E11: 5 | F11: 1.5 | G11: =+MIN(C11,I11/5) -> 78.097098 | H11: =MIN(B11,G11/C11*B11) -> 44.591719 | I11: =+(D11*POWER(1.645,2)*(0.5*0.5))/(POWER(E11/100,2)*(D11-1)+POWER(1.645,2)*(0.5*0.5))*F11 -> 390.48549
A12: FINES_R05 | B12: =+COUNTIF(Nómina!X:X,A12) -> 215 | C12: =+SUMIF(Nómina!X:X,A12,Nómina!S:S) -> 471 | D12: =+SUMIF(Nómina!X:X,A12,Nómina!R:R) -> 10881 | E12: 5 | F12: 1.5 | G12: =+MIN(C12,I12/5) -> 79.217938 | H12: =MIN(B12,G12/C12*B12) -> 36.161055 | I12: =+(D12*POWER(1.645,2)*(0.5*0.5))/(POWER(E12/100,2)*(D12-1)+POWER(1.645,2)*(0.5*0.5))*F12 -> 396.08969
A13: FINES_R06 | B13: =+COUNTIF(Nómina!X:X,A13) -> 57 | C13: =+SUMIF(Nómina!X:X,A13,Nómina!S:S) -> 80 | D13: =+SUMIF(Nómina!X:X,A13,Nómina!R:R) -> 1212 | E13: 5 | F13: 1.5 | G13: =+MIN(C13,I13/5) -> 66.408547 | H13: =MIN(B13,G13/C13*B13) -> 47.31609 | I13: =+(D13*POWER(1.645,2)*(0.5*0.5))/(POWER(E13/100,2)*(D13-1)+POWER(1.645,2)*(0.5*0.5))*F13 -> 332.04273
A14: FINES_R07 | B14: =+COUNTIF(Nómina!X:X,A14) -> 87 | C14: =+SUMIF(Nómina!X:X,A14,Nómina!S:S) -> 119 | D14: =+SUMIF(Nómina!X:X,A14,Nómina!R:R) -> 1867 | E14: 5 | F14: 1.5 | G14: =+MIN(C14,I14/5) -> 70.937135 | H14: =MIN(B14,G14/C14*B14) -> 51.861603 | I14: =+(D14*POWER(1.645,2)*(0.5*0.5))/(POWER(E14/100,2)*(D14-1)+POWER(1.645,2)*(0.5*0.5))*F14 -> 354.68568
A15: FINES_R08 | B15: =+COUNTIF(Nómina!X:X,A15) -> 102 | C15: =+SUMIF(Nómina!X:X,A15,Nómina!S:S) -> 221 | D15: =+SUMIF(Nómina!X:X,A15,Nómina!R:R) -> 4512 | E15: 5 | F15: 1.5 | G15: =+MIN(C15,I15/5) -> 76.603512 | H15: =MIN(B15,G15/C15*B15) -> 35.355467 | I15: =+(D15*POWER(1.645,2)*(0.5*0.5))/(POWER(E15/100,2)*(D15-1)+POWER(1.645,2)*(0.5*0.5))*F15 -> 383.01756
A16: FINES_R09 | B16: =+COUNTIF(Nómina!X:X,A16) -> 109 | C16: =+SUMIF(Nómina!X:X,A16,Nómina!S:S) -> 188 | D16: =+SUMIF(Nómina!X:X,A16,Nómina!R:R) -> 4902 | E16: 5 | F16: 1.5 | G16: =+MIN(C16,I16/5) -> 76.94869 | H16: =MIN(B16,G16/C16*B16) -> 44.613868 | I16: =+(D16*POWER(1.645,2)*(0.5*0.5))/(POWER(E16/100,2)*(D16-1)+POWER(1.645,2)*(0.5*0.5))*F16 -> 384.74345
A17: FINES_R10 | B17: =+COUNTIF(Nómina!X:X,A17) -> 136 | C17: =+SUMIF(Nómina!X:X,A17,Nómina!S:S) -> 185 | D17: =+SUMIF(Nómina!X:X,A17,Nómina!R:R) -> 3176 | E17: 5 | F17: 1.5 | G17: =+MIN(C17,I17/5) -> 74.828731 | H17: =MIN(B17,G17/C17*B17) -> 55.009229 | I17: =+(D17*POWER(1.645,2)*(0.5*0.5))/(POWER(E17/100,2)*(D17-1)+POWER(1.645,2)*(0.5*0.5))*F17 -> 374.14365
A18: FINES_R11 | B18: =+COUNTIF(Nómina!X:X,A18) -> 104 | C18: =+SUMIF(Nómina!X:X,A18,Nómina!S:S) -> 215 | D18: =+SUMIF(Nómina!X:X,A18,Nómina!R:R) -> 4932 | E18: 5 | F18: 1.5 | G18: =+MIN(C18,I18/5) -> 76.973098 | H18: =MIN(B18,G18/C18*B18) -> 37.233499 | I18: =+(D18*POWER(1.645,2)*(0.5*0.5))/(POWER(E18/100,2)*(D18-1)+POWER(1.645,2)*(0.5*0.5))*F18 -> 384.86549
A19: FINES_R12 | B19: =+COUNTIF(Nómina!X:X,A19) -> 48 | C19: =+SUMIF(Nómina!X:X,A19,Nómina!S:S) -> 68 | D19: =+SUMIF(Nómina!X:X,A19,Nómina!R:R) -> 1374 | E19: 5 | F19: 1.5 | G19: =+MIN(C19,I19/5) -> 67.864554 | H19: =MIN(B19,G19/C19*B19) -> 47.904391 | I19: =+(D19*POWER(1.645,2)*(0.5*0.5))/(POWER(E19/100,2)*(D19-1)+POWER(1.645,2)*(0.5*0.5))*F19 -> 339.32277
... A26: FINES_R15172425 | B26: =+COUNTIF(Nómina!X:X,A26) -> 114 | C26: =+SUMIF(Nómina!X:X,A26,Nómina!S:S) -> 153 | D26: =+SUMIF(Nómina!X:X,A26,Nómina!R:R) -> 2445 | E26: 4 | F26: 1.5 | G26: =+MIN(C26,I26/5) -> 108.18127 | H26: =MIN(B26,G26/C26*B26) -> 80.605651 | I26: =+(D26*POWER(1.645,2)*(0.5*0.5))/(POWER(E26/100,2)*(D26-1)+POWER(1.645,2)*(0.5*0.5))*F26 -> 540.90634

Sheet Fines-Sedes
A1: Región Educativa | B1: Código Distrito DGCyE | C1: Nombre de Distrito - Partido | D1: Sede | E1: COMISIONES | F1: ESTUDIANTES | G1: R | H1: Distrito | K1: distrito | L1: Región Educativa | M1: Código Distrito DGCyE | N1: Nombre de Distrito - Partido
A2: =+VLOOKUP(H2,$K:$N,2,FALSE) -> 01 | B2: =+VLOOKUP(H2,$K:$N,3,FALSE) -> 113 | C2: =+VLOOKUP(H2,$K:$N,4,FALSE) -> Berisso | D2: AGRUPACIÓN MARÍA ROLDÁN | E2: 1 | F2: 18 | G2: 1 | H2: BERISSO | K2: BERISSO | L2: 01 | M2: 113 | N2: Berisso
A3: =+VLOOKUP(H3,$K:$N,2,FALSE) -> 01 | B3: =+VLOOKUP(H3,$K:$N,3,FALSE) -> 113 | C3: =+VLOOKUP(H3,$K:$N,4,FALSE) -> Berisso | D3: C.Cultural y Polideportvo Papa Francisco S/N Berisso | E3: 1 | F3: 17 | G3: 1 | H3: BERISSO | K3: Coronel Brandsen | L3: 01 | M3: 014 | N3: Brandsen
A4: =+VLOOKUP(H4,$K:$N,2,FALSE) -> 01 | B4: =+VLOOKUP(H4,$K:$N,3,FALSE) -> 113 | C4: =+VLOOKUP(H4,$K:$N,4,FALSE) -> Berisso | D4: Casa Nuestra Patria | E4: 3 | F4: 69 | G4: 1 | H4: BERISSO | K4: Ensenada | L4: 01 | M4: 114 | N4: Ensenada
A5: =+VLOOKUP(H5,$K:$N,2,FALSE) -> 01 | B5: =+VLOOKUP(H5,$K:$N,3,FALSE) -> 113 | C5: =+VLOOKUP(H5,$K:$N,4,FALSE) -> Berisso | D5: CENTRO CULTURAL LA 163 | E5: 1 | F5: 22 | G5: 1 | H5: BERISSO | K5: La Plata | L5: 01 | M5: 001 | N5: La Plata
A6: =+VLOOKUP(H6,$K:$N,2,FALSE) -> 01 | B6: =+VLOOKUP(H6,$K:$N,3,FALSE) -> 113 | C6: =+VLOOKUP(H6,$K:$N,4,FALSE) -> Berisso | D6: CIC Barrio Obrero | E6: 1 | F6: 19 | G6: 1 | H6: BERISSO | K6: Magdalena | L6: 01 | M6: 064 | N6: Magdalena
A7: =+VLOOKUP(H7,$K:$N,2,FALSE) -> 01 | B7: =+VLOOKUP(H7,$K:$N,3,FALSE) -> 113 | C7: =+VLOOKUP(H7,$K:$N,4,FALSE) -> Berisso | D7: Club El Carmen | E7: 1 | F7: 13 | G7: 1 | H7: BERISSO | K7: Punta Indio | L7: 01 | M7: 134 | N7: Punta Indio
A8: =+VLOOKUP(H8,$K:$N,2,FALSE) -> 01 | B8: =+VLOOKUP(H8,$K:$N,3,FALSE) -> 113 | C8: =+VLOOKUP(H8,$K:$N,4,FALSE) -> Berisso | D8: Club Villa Nueva | E8: 1 | F8: 18 | G8: 1 | H8: BERISSO | K8: Avellaneda | L8: 02 | M8: 005 | N8: Avellaneda
A9: =+VLOOKUP(H9,$K:$N,2,FALSE) -> 01 | B9: =+VLOOKUP(H9,$K:$N,3,FALSE) -> 113 | C9: =+VLOOKUP(H9,$K:$N,4,FALSE) -> Berisso | D9: Club Villa Paula s/n Berisso | E9: 1 | F9: 27 | G9: 1 | H9: BERISSO | K9: Lanús | L9: 02 | M9: 111 | N9: Lanús
A10: =+VLOOKUP(H10,$K:$N,2,FALSE) -> 01 | B10: =+VLOOKUP(H10,$K:$N,3,FALSE) -> 113 | C10: =+VLOOKUP(H10,$K:$N,4,FALSE) -> Berisso | D10: CLUB VILLA PROGRESO | E10: 1 | F10: 14 | G10: 1 | H10: BERISSO | K10: Lomas de Zamora | L10: 02 | M10: 062 | N10: Lomas de Zamora
A11: =+VLOOKUP(H11,$K:$N,2,FALSE) -> 01 | B11: =+VLOOKUP(H11,$K:$N,3,FALSE) -> 113 | C11: =+VLOOKUP(H11,$K:$N,4,FALSE) -> Berisso | D11: COMEDOR LOS PEQUES S/N Berisso | E11: 1 | F11: 20 | G11: 1 | H11: BERISSO | K11: La Matanza 1 | L11: 03 | M11: 069 | N11: La Matanza
