Workbook

Sheet Nómina
A1: Tipo | B1: Región Educativa | C1: Código Distrito DGCyE | D1: Nombre de Distrito - Partido | E1: CUE | F1: Anexo | G1: Clave Provincial | H1: Dependencia | I1: Tipo de Organización | J1: Sede Anexo Extensión | K1: Escuela Sede | L1: Nombre del Establecimiento | M1: Ámbito Geográfico | N1: Matrícula Estimada | O1: Modalidad | P1: Nivel | Q1: Matricula Total | R1: Secciones | S1: Universo | T1: Universo_Excl. | U1: Estrato_Oferta | V1: Estrato_GEO | W1: Estrato | X1: IVSE_T
A2: Un.Serv. | B2: 01 | C2: 113 | D2: Berisso | E2: 602838 | F2: 2 | G2: 0113DC0708 | H2: Oficial | I2: CENTRO DE EDUCACIÓN PRIMARIA DE ADULTOS | J2: EXTENSION | K2: 0113DE0703 | L2: CENTRO DE ADULTOS Nº708/03 "DARDO ROCHA" | M2: Urbano | N2: No | O2: Educación de Jóvenes y Adultos | P2: Nivel Primario | Q2: 24 | R2: 2 | S2: 0 | T2: Prim. NO EPA | V2: =+IF(U2="","",IF(U2="FINES",CONCATENATE("R",IF(OR(B2="16",B2="21",B2="22",B2="23"),"16212223",IF(OR(B2="15",B2="17",B2="24",B2="25"),"15172425",B2))),IF(U2="CEBAS","UNICO",IF(VALUE(B2)<=11,"AMBA","INTERIOR")))) | W2: =+IF(U2="","-",CONCATENATE(U2,"_",V2)) -> - | X2: 0
A3: Un.Serv. | B3: 04 | C3: 032 | D3: Florencio Varela | E3: 608473 | F3: 1 | G3: 0032DC0717 | H3: Oficial | I3: CENTRO DE EDUCACIÓN PRIMARIA DE ADULTOS | J3: EXTENSION | K3: 0032DE0721 | L3: CENTRO DE ADULTOS Nº717/21 | M3: Urbano | N3: No | O3: Educación de Jóvenes y Adultos | P3: Nivel Primario | Q3: 55 | R3: 4 | S3: 0 | T3: Prim. NO EPA | V3: =+IF(U3="","",IF(U3="FINES",CONCATENATE("R",IF(OR(B3="16",B3="21",B3="22",B3="23"),"16212223",IF(OR(B3="15",B3="17",B3="24",B3="25"),"15172425",B3))),IF(U3="CEBAS","UNICO",IF(VALUE(B3)<=11,"AMBA","INTERIOR")))) | W3: =+IF(U3="","-",CONCATENATE(U3,"_",V3)) -> - | X3: 0
A4: Un.Serv. | B4: 20 | C4: 060 | D4: Lobería | E4: 600691 | F4: 0 | G4: 0060DC0703 | H4: Oficial | I4: CENTRO DE EDUCACIÓN PRIMARIA DE ADULTOS | J4: SEDE | L4: CENTRO DE ADULTOS Nº703 "VILLA ERCILIA" | M4: Urbano | N4: No | O4: Educación de Jóvenes y Adultos | P4: Nivel Primario | Q4: 11 | R4: 1 | S4: 0 | T4: Prim. NO EPA | V4: =+IF(U4="","",IF(U4="FINES",CONCATENATE("R",IF(OR(B4="16",B4="21",B4="22",B4="23"),"16212223",IF(OR(B4="15",B4="17",B4="24",B4="25"),"15172425",B4))),IF(U4="CEBAS","UNICO",IF(VALUE(B4)<=11,"AMBA","INTERIOR")))) | W4: =+IF(U4="","-",CONCATENATE(U4,"_",V4)) -> - | X4: 0.001
A5: Un.Serv. | B5: 02 | C5: 111 | D5: Lanús | E5: 608243 | F5: 1 | G5: 0111DC0727 | H5: Oficial | I5: CENTRO DE EDUCACIÓN PRIMARIA DE ADULTOS | J5: EXTENSION | K5: 0111DE0712 | L5: CENTRO DE ADULTOS Nº727/12 | M5: Urbano | N5: No | O5: Educación de Jóvenes y Adultos | P5: Nivel Primario | Q5: 46 | R5: 3 | S5: 0 | T5: Prim. NO EPA | V5: =+IF(U5="","",IF(U5="FINES",CONCATENATE("R",IF(OR(B5="16",B5="21",B5="22",B5="23"),"16212223",IF(OR(B5="15",B5="17",B5="24",B5="25"),"15172425",B5))),IF(U5="CEBAS","UNICO",IF(VALUE(B5)<=11,"AMBA","INTERIOR")))) | W5: =+IF(U5="","-",CONCATENATE(U5,"_",V5)) -> - | X5: 0.001
A6: Un.Serv. | B6: 19 | C6: 043 | D6: General Pueyrredón | E6: 613572 | F6: 1 | G6: 0043DC0739 | H6: Oficial | I6: CENTRO DE EDUCACIÓN PRIMARIA DE ADULTOS | J6: EXTENSION | K6: 0043DE0743 | L6: CENTRO DE ADULTOS Nº739/06 | M6: Urbano | N6: No | O6: Educación de Jóvenes y Adultos | P6: Nivel Primario | Q6: 36 | R6: 3 | S6: 0 | T6: Prim. NO EPA | V6: =+IF(U6="","",IF(U6="FINES",CONCATENATE("R",IF(OR(B6="16",B6="21",B6="22",B6="23"),"16212223",IF(OR(B6="15",B6="17",B6="24",B6="25"),"15172425",B6))),IF(U6="CEBAS","UNICO",IF(VALUE(B6)<=11,"AMBA","INTERIOR")))) | W6: =+IF(U6="","-",CONCATENATE(U6,"_",V6)) -> - | X6: 0.002
A7: Un.Serv. | B7: 08 | C7: 071 | D7: Merlo | E7: 609955 | F7: 4 | G7: 0071DC0714 | H7: Oficial | I7: CENTRO DE EDUCACIÓN PRIMARIA DE ADULTOS | J7: EXTENSION | K7: 0071DE0703 | L7: CENTRO DE ADULTOS Nº714/03 | M7: Urbano | N7: No | O7: Educación de Jóvenes y Adultos | P7: Nivel Primario | Q7: 40 | R7: 3 | S7: 0 | T7: Prim. NO EPA | V7: =+IF(U7="","",IF(U7="FINES",CONCATENATE("R",IF(OR(B7="16",B7="21",B7="22",B7="23"),"16212223",IF(OR(B7="15",B7="17",B7="24",B7="25"),"15172425",B7))),IF(U7="CEBAS","UNICO",IF(VALUE(B7)<=11,"AMBA","INTERIOR")))) | W7: =+IF(U7="","-",CONCATENATE(U7,"_",V7)) -> - | X7: 0.004
A8: Un.Serv. | B8: 04 | C8: 032 | D8: Florencio Varela | E8: 608473 | F8: 2 | G8: 0032DC0718 | H8: Oficial | I8: CENTRO DE EDUCACIÓN PRIMARIA DE ADULTOS | J8: EXTENSION | K8: 0032DE0721 | L8: CENTRO DE ADULTOS Nº718/21 | M8: Urbano | N8: No | O8: Educación de Jóvenes y Adultos | P8: Nivel Primario | Q8: 38 | R8: 3 | S8: 0 | T8: Prim. NO EPA | V8: =+IF(U8="","",IF(U8="FINES",CONCATENATE("R",IF(OR(B8="16",B8="21",B8="22",B8="23"),"16212223",IF(OR(B8="15",B8="17",B8="24",B8="25"),"15172425",B8))),IF(U8="CEBAS","UNICO",IF(VALUE(B8)<=11,"AMBA","INTERIOR")))) | W8: =+IF(U8="","-",CONCATENATE(U8,"_",V8)) -> - | X8: 0.004
A9: Un.Serv. | B9: 11 | C9: 047 | D9: Zárate | E9: 605769 | F9: 1 | G9: 0047DC0708 | H9: Oficial | I9: CENTRO DE EDUCACIÓN PRIMARIA DE ADULTOS | J9: EXTENSION | K9: 0047DE0703 | L9: CENTRO DE ADULTOS Nº708/03 | M9: Urbano | N9: No | O9: Educación de Jóvenes y Adultos | P9: Nivel Primario | Q9: 32 | R9: 2 | S9: 0 | T9: Prim. NO EPA | V9: =+IF(U9="","",IF(U9="FINES",CONCATENATE("R",IF(OR(B9="16",B9="21",B9="22",B9="23"),"16212223",IF(OR(B9="15",B9="17",B9="24",B9="25"),"15172425",B9))),IF(U9="CEBAS","UNICO",IF(VALUE(B9)<=11,"AMBA","INTERIOR")))) | W9: =+IF(U9="","-",CONCATENATE(U9,"_",V9)) -> - | X9: 0.006
A10: Un.Serv. | B10: 07 | C10: 135 | D10: Hurlingham | E10: 600021 | F10: 1 | G10: 0135DC0707 | H10: Oficial | I10: CENTRO DE EDUCACIÓN PRIMARIA DE ADULTOS | J10: EXTENSION | K10: 0135DE0701 | L10: CENTRO DE ADULTOS Nº707/01 | M10: Urbano | N10: No | O10: Educación de Jóvenes y Adultos | P10: Nivel Primario | Q10: 30 | R10: 2 | S10: 0 | T10: Prim. NO EPA | V10: =+IF(U10="","",IF(U10="FINES",CONCATENATE("R",IF(OR(B10="16",B10="21",B10="22",B10="23"),"16212223",IF(OR(B10="15",B10="17",B10="24",B10="25"),"15172425",B10))),IF(U10="CEBAS","UNICO",IF(VALUE(B10)<=11,"AMBA","INTERIOR")))) | W10: =+IF(U10="","-",CONCATENATE(U10,"_",V10)) -> - | X10: 0.007
A11: Un.Serv. | B11: 22 | C11: 078 | D11: Patagones | E11: 603157 | F11: 3 | G11: 0078DC0704 | H11: Oficial | I11: CENTRO DE EDUCACIÓN PRIMARIA DE ADULTOS | J11: EXTENSION | K11: 0078DE0701 | L11: CENTRO DE ADULTOS Nº704/01 | M11: Urbano | N11: No | O11: Educación de Jóvenes y Adultos | P11: Nivel Primario | Q11: 36 | R11: 3 | S11: 0 | T11: Prim. NO EPA | V11: =+IF(U11="","",IF(U11="FINES",CONCATENATE("R",IF(OR(B11="16",B11="21",B11="22",B11="23"),"16212223",IF(OR(B11="15",B11="17",B11="24",B11="25"),"15172425",B11))),IF(U11="CEBAS","UNICO",IF(VALUE(B11)<=11,"AMBA","INTERIOR")))) | W11: =+IF(U11="","-",CONCATENATE(U11,"_",V11)) -> - | X11: 0.009
A12: Un.Serv. | B12: 18 | C12: 125 | D12: Villa Gesell | E12: 613151 | F12: 1 | G12: 0125DC0702 | H12: Oficial | I12: CENTRO DE EDUCACIÓN PRIMARIA DE ADULTOS | J12: EXTENSION | K12: 0125DE0701 | L12: CENTRO DE ADULTOS Nº702/01 | M12: Urbano | N12: No | O12: Educación de Jóvenes y Adultos | P12: Nivel Primario | Q12: 38 | R12: 3 | S12: 0 | T12: Prim. NO EPA | V12: =+IF(U12="","",IF(U12="FINES",CONCATENATE("R",IF(OR(B12="16",B12="21",B12="22",B12="23"),"16212223",IF(OR(B12="15",B12="17",B12="24",B12="25"),"15172425",B12))),IF(U12="CEBAS","UNICO",IF(VALUE(B12)<=11,"AMBA","INTERIOR")))) | W12: =+IF(U12="","-",CONCATENATE(U12,"_",V12)) -> - | X12: 0.013
A13: Un.Serv. | B13: 03 | C13: 069 | D13: La Matanza | E13: 602154 | F13: 1 | G13: 0069DC0715 | H13: Oficial | I13: CENTRO DE EDUCACIÓN PRIMARIA DE ADULTOS | J13: EXTENSION | K13: 0069DE0716 | L13: CENTRO DE ADULTOS Nº715/16 | M13: Urbano | N13: No | O13: Educación de Jóvenes y Adultos | P13: Nivel Primario | Q13: 21 | R13: 2 | S13: 0 | T13: Prim. NO EPA | V13: =+IF(U13="","",IF(U13="FINES",CONCATENATE("R",IF(OR(B13="16",B13="21",B13="22",B13="23"),"16212223",IF(OR(B13="15",B13="17",B13="24",B13="25"),"15172425",B13))),IF(U13="CEBAS","UNICO",IF(VALUE(B13)<=11,"AMBA","INTERIOR")))) | W13: =+IF(U13="","-",CONCATENATE(U13,"_",V13)) -> - | X13: 0.016
A14: Un.Serv. | B14: 05 | C14: 004 | D14: Almirante Brown | E14: 613277 | F14: 3 | G14: 0004DC0738 | H14: Oficial | I14: CENTRO DE EDUCACIÓN PRIMARIA DE ADULTOS | J14: EXTENSION | K14: 0004DE0701 | L14: CENTRO DE ADULTOS Nº738/01 | M14: Urbano | N14: No | O14: Educación de Jóvenes y Adultos | P14: Nivel Primario | Q14: 32 | R14: 2 | S14: 0 | T14: Prim. NO EPA | V14: =+IF(U14="","",IF(U14="FINES",CONCATENATE("R",IF(OR(B14="16",B14="21",B14="22",B14="23"),"16212223",IF(OR(B14="15",B14="17",B14="24",B14="25"),"15172425",B14))),IF(U14="CEBAS","UNICO",IF(VALUE(B14)<=11,"AMBA","INTERIOR")))) | W14: =+IF(U14="","-",CONCATENATE(U14,"_",V14)) -> - | X14: 0.017
A15: Un.Serv. | B15: 02 | C15: 005 | D15: Avellaneda | E15: 624498 | F15: 0 | G15: 2005DM9000 | H15: Nacional | I15: CENTRO EDUCATIVO DE NIVEL SECUNDARIO (C.E.N.S.) | J15: SEDE | L15: ESCUELA SECUNDARIA DE JÓVENES Y ADULTOS DE LA UNIVERSIDAD NACIONAL DE AVELLANEDA | M15: Urbano | N15: Sí | O15: Educación de Jóvenes y Adultos | P15: Nivel Secundario | Q15: 36 | R15: 2 | S15: 0 | T15: No Oficial | V15: =+IF(U15="","",IF(U15="FINES",CONCATENATE("R",IF(OR(B15="16",B15="21",B15="22",B15="23"),"16212223",IF(OR(B15="15",B15="17",B15="24",B15="25"),"15172425",B15))),IF(U15="CEBAS","UNICO",IF(VALUE(B15)<=11,"AMBA","INTERIOR")))) | W15: =+IF(U15="","-",CONCATENATE(U15,"_",V15)) -> - | X15: 0.017
A16: Un.Serv. | B16: 11 | C16: 015 | D16: Campana | E16: 605809 | F16: 1 | G16: 0015DC0703 | H16: Oficial | I16: CENTRO DE EDUCACIÓN PRIMARIA DE ADULTOS | J16: EXTENSION | K16: 0015DE0701 | L16: CENTRO DE ADULTOS Nº703/01 "RAFAEL OBLIGADO" | M16: Urbano | N16: No | O16: Educación de Jóvenes y Adultos | P16: Nivel Primario | Q16: 60 | R16: 4 | S16: 0 | T16: Prim. NO EPA | V16: =+IF(U16="","",IF(U16="FINES",CONCATENATE("R",IF(OR(B16="16",B16="21",B16="22",B16="23"),"16212223",IF(OR(B16="15",B16="17",B16="24",B16="25"),"15172425",B16))),IF(U16="CEBAS","UNICO",IF(VALUE(B16)<=11,"AMBA","INTERIOR")))) | W16: =+IF(U16="","-",CONCATENATE(U16,"_",V16)) -> - | X16: 0.018
A17: Un.Serv. | B17: 08 | C17: 071 | D17: Merlo | E17: 614527 | F17: 0 | G17: 0071DA0099 | H17: Oficial | I17: CENTRO DE ALFABETIZACIÓN | J17: SEDE | L17: CENTRO DE ALFABETIZACION Nº799/99 | M17: Urbano | N17: No | O17: Educación de Jóvenes y Adultos | P17: Nivel Primario | Q17: 10 | R17: 1 | S17: 0 | T17: Prim. NO EPA | V17: =+IF(U17="","",IF(U17="FINES",CONCATENATE("R",IF(OR(B17="16",B17="21",B17="22",B17="23"),"16212223",IF(OR(B17="15",B17="17",B17="24",B17="25"),"15172425",B17))),IF(U17="CEBAS","UNICO",IF(VALUE(B17)<=11,"AMBA","INTERIOR")))) | W17: =+IF(U17="","-",CONCATENATE(U17,"_",V17)) -> - | X17: 0.019
A18: Un.Serv. | B18: 05 | C18: 030 | D18: Esteban Echeverría | E18: 609164 | F18: 2 | G18: 0030DC0707 | H18: Oficial | I18: CENTRO DE EDUCACIÓN PRIMARIA DE ADULTOS | J18: EXTENSION | K18: 0030DE0701 | L18: CENTRO DE ADULTOS Nº707/01 | M18: Urbano | N18: No | O18: Educación de Jóvenes y Adultos | P18: Nivel Primario | Q18: 42 | R18: 3 | S18: 0 | T18: Prim. NO EPA | V18: =+IF(U18="","",IF(U18="FINES",CONCATENATE("R",IF(OR(B18="16",B18="21",B18="22",B18="23"),"16212223",IF(OR(B18="15",B18="17",B18="24",B18="25"),"15172425",B18))),IF(U18="CEBAS","UNICO",IF(VALUE(B18)<=11,"AMBA","INTERIOR")))) | W18: =+IF(U18="","-",CONCATENATE(U18,"_",V18)) -> - | X18: 0.021
A19: Un.Serv. | B19: 01 | C19: 001 | D19: La Plata | E19: 609115 | F19: 2 | G19: 0001DC0720 | H19: Oficial | I19: CENTRO DE EDUCACIÓN PRIMARIA DE ADULTOS | J19: EXTENSION | K19: 0001DE0713 | L19: CENTRO DE ADULTOS Nº720/13 | M19: Urbano | N19: No | O19: Educación de Jóvenes y Adultos | P19: Nivel Primario | Q19: 28 | R19: 2 | S19: 0 | T19: Prim. NO EPA | V19: =+IF(U19="","",IF(U19="FINES",CONCATENATE("R",IF(OR(B19="16",B19="21",B19="22",B19="23"),"16212223",IF(OR(B19="15",B19="17",B19="24",B19="25"),"15172425",B19))),IF(U19="CEBAS","UNICO",IF(VALUE(B19)<=11,"AMBA","INTERIOR")))) | W19: =+IF(U19="","-",CONCATENATE(U19,"_",V19)) -> - | X19: 0.021
A20: Un.Serv. | B20: 12 | C20: 098 | D20: San Pedro | E20: 613674 | F20: 0 | G20: 0098DC0702 | H20: Oficial | I20: CENTRO DE EDUCACIÓN PRIMARIA DE ADULTOS | J20: SEDE | L20: CENTRO DE ADULTOS Nº702 | M20: Urbano | N20: No | O20: Educación de Jóvenes y Adultos | P20: Nivel Primario | Q20: 21 | R20: 2 | S20: 0 | T20: Prim. NO EPA | V20: =+IF(U20="","",IF(U20="FINES",CONCATENATE("R",IF(OR(B20="16",B20="21",B20="22",B20="23"),"16212223",IF(OR(B20="15",B20="17",B20="24",B20="25"),"15172425",B20))),IF(U20="CEBAS","UNICO",IF(VALUE(B20)<=11,"AMBA","INTERIOR")))) | W20: =+IF(U20="","-",CONCATENATE(U20,"_",V20)) -> - | X20: 0.022
A21: Un.Serv. | B21: 02 | C21: 111 | D21: Lanús | E21: 608243 | F21: 4 | G21: 0111DC0715 | H21: Oficial | I21: CENTRO DE EDUCACIÓN PRIMARIA DE ADULTOS | J21: EXTENSION | K21: 0111DE0712 | L21: CENTRO DE ADULTOS Nº715/12 | M21: Urbano | N21: No | O21: Educación de Jóvenes y Adultos | P21: Nivel Primario | Q21: 31 | R21: 2 | S21: 0 | T21: Prim. NO EPA | V21: =+IF(U21="","",IF(U21="FINES",CONCATENATE("R",IF(OR(B21="16",B21="21",B21="22",B21="23"),"16212223",IF(OR(B21="15",B21="17",B21="24",B21="25"),"15172425",B21))),IF(U21="CEBAS","UNICO",IF(VALUE(B21)<=11,"AMBA","INTERIOR")))) | W21: =+IF(U21="","-",CONCATENATE(U21,"_",V21)) -> - | X21: 0.023
A22: Un.Serv. | B22: 12 | C22: 097 | D22: San Nicolás | E22: 600849 | F22: 1 | G22: 0097DC0711 | H22: Oficial | I22: CENTRO DE EDUCACIÓN PRIMARIA DE ADULTOS | J22: EXTENSION | K22: 0097DE0704 | L22: CENTRO DE ADULTOS Nº711/04 | M22: Urbano | N22: No | O22: Educación de Jóvenes y Adultos | P22: Nivel Primario | Q22: 23 | R22: 2 | S22: 0 | T22: Prim. NO EPA | V22: =+IF(U22="","",IF(U22="FINES",CONCATENATE("R",IF(OR(B22="16",B22="21",B22="22",B22="23"),"16212223",IF(OR(B22="15",B22="17",B22="24",B22="25"),"15172425",B22))),IF(U22="CEBAS","UNICO",IF(VALUE(B22)<=11,"AMBA","INTERIOR")))) | W22: =+IF(U22="","-",CONCATENATE(U22,"_",V22)) -> - | X22: 0.027
A23: Un.Serv. | B23: 03 | C23: 069 | D23: La Matanza | E23: 608696 | F23: 1 | G23: 0069DC0751 | H23: Oficial | I23: CENTRO DE EDUCACIÓN PRIMARIA DE ADULTOS | J23: EXTENSION | K23: 0069DE0705 | L23: CENTRO DE ADULTOS Nº751/05 | M23: Urbano | N23: No | O23: Educación de Jóvenes y Adultos | P23: Nivel Primario | Q23: 38 | R23: 3 | S23: 0 | T23: Prim. NO EPA | V23: =+IF(U23="","",IF(U23="FINES",CONCATENATE("R",IF(OR(B23="16",B23="21",B23="22",B23="23"),"16212223",IF(OR(B23="15",B23="17",B23="24",B23="25"),"15172425",B23))),IF(U23="CEBAS","UNICO",IF(VALUE(B23)<=11,"AMBA","INTERIOR")))) | W23: =+IF(U23="","-",CONCATENATE(U23,"_",V23)) -> - | X23: 0.028
A24: Un.Serv. | B24: 19 | C24: 033 | D24: General Alvarado | E24: 609292 | F24: 4 | G24: 0033DC0703 | H24: Oficial | I24: CENTRO DE EDUCACIÓN PRIMARIA DE ADULTOS | J24: EXTENSION | K24: 0033DE0701 | L24: CENTRO DE ADULTOS Nº703 "DR. EMILIO GALLINA" | M24: Urbano | N24: No | O24: Educación de Jóvenes y Adultos | P24: Nivel Primario | Q24: 35 | R24: 2 | S24: 0 | T24: Prim. NO EPA | V24: =+IF(U24="","",IF(U24="FINES",CONCATENATE("R",IF(OR(B24="16",B24="21",B24="22",B24="23"),"16212223",IF(OR(B24="15",B24="17",B24="24",B24="25"),"15172425",B24))),IF(U24="CEBAS","UNICO",IF(VALUE(B24)<=11,"AMBA","INTERIOR")))) | W24: =+IF(U24="","-",CONCATENATE(U24,"_",V24)) -> - | X24: 0.029
A25: Un.Serv. | B25: 13 | C25: 022 | D25: Colón | E25: 606543 | F25: 2 | G25: 0022DC0706 | H25: Oficial | I25: CENTRO DE EDUCACIÓN PRIMARIA DE ADULTOS | J25: EXTENSION | K25: 0022DE0701 | L25: CENTRO DE ADULTOS Nº706/01 | M25: Urbano | N25: No | O25: Educación de Jóvenes y Adultos | P25: Nivel Primario | Q25: 30 | R25: 3 | S25: 0 | T25: Prim. NO EPA | V25: =+IF(U25="","",IF(U25="FINES",CONCATENATE("R",IF(OR(B25="16",B25="21",B25="22",B25="23"),"16212223",IF(OR(B25="15",B25="17",B25="24",B25="25"),"15172425",B25))),IF(U25="CEBAS","UNICO",IF(VALUE(B25)<=11,"AMBA","INTERIOR")))) | W25: =+IF(U25="","-",CONCATENATE(U25,"_",V25)) -> - | X25: 0.03
A26: Un.Serv. | B26: 20 | C26: 075 | D26: Necochea | E26: 611210 | F26: 2 | G26: 0075DC0708 | H26: Oficial | I26: CENTRO DE EDUCACIÓN PRIMARIA DE ADULTOS | J26: EXTENSION | K26: 0075DE0702 | L26: CENTRO DE ADULTOS Nº708/02 | M26: Urbano | N26: No | O26: Educación de Jóvenes y Adultos | P26: Nivel Primario | Q26: 17 | R26: 1 | S26: 0 | T26: Prim. NO EPA | V26: =+IF(U26="","",IF(U26="FINES",CONCATENATE("R",IF(OR(B26="16",B26="21",B26="22",B26="23"),"16212223",IF(OR(B26="15",B26="17",B26="24",B26="25"),"15172425",B26))),IF(U26="CEBAS","UNICO",IF(VALUE(B26)<=11,"AMBA","INTERIOR")))) | W26: =+IF(U26="","-",CONCATENATE(U26,"_",V26)) -> - | X26: 0.031
A27: Un.Serv. | B27: 08 | C27: 100 | D27: Morón | E27: 613021 | F27: 1 | G27: 0100DC0709 | H27: Oficial | I27: CENTRO DE EDUCACIÓN PRIMARIA DE ADULTOS | J27: EXTENSION | K27: 0100DE0703 | L27: CENTRO DE ADULTOS Nº709/03 | M27: Urbano | N27: No | O27: Educación de Jóvenes y Adultos | P27: Nivel Primario | Q27: 42 | R27: 3 | S27: 0 | T27: Prim. NO EPA | V27: =+IF(U27="","",IF(U27="FINES",CONCATENATE("R",IF(OR(B27="16",B27="21",B27="22",B27="23"),"16212223",IF(OR(B27="15",B27="17",B27="24",B27="25"),"15172425",B27))),IF(U27="CEBAS","UNICO",IF(VALUE(B27)<=11,"AMBA","INTERIOR")))) | W27: =+IF(U27="","-",CONCATENATE(U27,"_",V27)) -> - | X27: 0.032
A28: Un.Serv. | B28: 11 | C28: 047 | D28: Zárate | E28: 605769 | F28: 2 | G28: 0047DC0710 | H28: Oficial | I28: CENTRO DE EDUCACIÓN PRIMARIA DE ADULTOS | J28: EXTENSION | K28: 0047DE0703 | L28: CENTRO DE ADULTOS Nº710/03 | M28: Urbano | N28: No | O28: Educación de Jóvenes y Adultos | P28: Nivel Primario | Q28: 13 | R28: 1 | S28: 0 | T28: Prim. NO EPA | V28: =+IF(U28="","",IF(U28="FINES",CONCATENATE("R",IF(OR(B28="16",B28="21",B28="22",B28="23"),"16212223",IF(OR(B28="15",B28="17",B28="24",B28="25"),"15172425",B28))),IF(U28="CEBAS","UNICO",IF(VALUE(B28)<=11,"AMBA","INTERIOR")))) | W28: =+IF(U28="","-",CONCATENATE(U28,"_",V28)) -> - | X28: 0.036
A29: Un.Serv. | B29: 20 | C29: 102 | D29: Tandil | E29: 610063 | F29: 2 | G29: 0102DC0707 | H29: Oficial | I29: CENTRO DE EDUCACIÓN PRIMARIA DE ADULTOS | J29: EXTENSION | K29: 0102DE0701 | L29: CENTRO DE ADULTOS Nº707 | M29: Urbano | N29: No | O29: Educación de Jóvenes y Adultos | P29: Nivel Primario | Q29: 9 | R29: 1 | S29: 0 | T29: Prim. NO EPA | V29: =+IF(U29="","",IF(U29="FINES",CONCATENATE("R",IF(OR(B29="16",B29="21",B29="22",B29="23"),"16212223",IF(OR(B29="15",B29="17",B29="24",B29="25"),"15172425",B29))),IF(U29="CEBAS","UNICO",IF(VALUE(B29)<=11,"AMBA","INTERIOR")))) | W29: =+IF(U29="","-",CONCATENATE(U29,"_",V29)) -> - | X29: 0.037
A30: Un.Serv. | B30: 07 | C30: 045 | D30: General San Martín | E30: 613580 | F30: 1 | G30: 0045DC0716 | H30: Oficial | I30: CENTRO DE EDUCACIÓN PRIMARIA DE ADULTOS | J30: EXTENSION | K30: 0045DE0705 | L30: CENTRO DE ADULTOS Nº716 | M30: Urbano | N30: No | O30: Educación de Jóvenes y Adultos | P30: Nivel Primario | Q30: 70 | R30: 4 | S30: 0 | T30: Prim. NO EPA | V30: =+IF(U30="","",IF(U30="FINES",CONCATENATE("R",IF(OR(B30="16",B30="21",B30="22",B30="23"),"16212223",IF(OR(B30="15",B30="17",B30="24",B30="25"),"15172425",B30))),IF(U30="CEBAS","UNICO",IF(VALUE(B30)<=11,"AMBA","INTERIOR")))) | W30: =+IF(U30="","-",CONCATENATE(U30,"_",V30)) -> - | X30: 0.037
A31: Un.Serv. | B31: 22 | C31: 078 | D31: Patagones | E31: 613144 | F31: 1 | G31: 0078DC0707 | H31: Oficial | I31: CENTRO DE EDUCACIÓN PRIMARIA DE ADULTOS | J31: EXTENSION | K31: 0078DE0709 | L31: CENTRO DE ADULTOS Nº707/09 | M31: Rural Disperso | N31: No | O31: Educación de Jóvenes y Adultos | P31: Nivel Primario | Q31: 41 | R31: 2 | S31: 0 | T31: Prim. NO EPA | V31: =+IF(U31="","",IF(U31="FINES",CONCATENATE("R",IF(OR(B31="16",B31="21",B31="22",B31="23"),"16212223",IF(OR(B31="15",B31="17",B31="24",B31="25"),"15172425",B31))),IF(U31="CEBAS","UNICO",IF(VALUE(B31)<=11,"AMBA","INTERIOR")))) | W31: =+IF(U31="","-",CONCATENATE(U31,"_",V31)) -> - | X31: 0.038
A32: Un.Serv. | B32: 02 | C32: 005 | D32: Avellaneda | E32: 600926 | F32: 1 | G32: 0005DC0719 | H32: Oficial | I32: CENTRO DE EDUCACIÓN PRIMARIA DE ADULTOS | J32: EXTENSION | K32: 0005DE0706 | L32: CENTRO DE ADULTOS Nº719/06 | M32: Urbano | N32: No | O32: Educación de Jóvenes y Adultos | P32: Nivel Primario | Q32: 19 | R32: 2 | S32: 0 | T32: Prim. NO EPA | V32: =+IF(U32="","",IF(U32="FINES",CONCATENATE("R",IF(OR(B32="16",B32="21",B32="22",B32="23"),"16212223",IF(OR(B32="15",B32="17",B32="24",B32="25"),"15172425",B32))),IF(U32="CEBAS","UNICO",IF(VALUE(B32)<=11,"AMBA","INTERIOR")))) | W32: =+IF(U32="","-",CONCATENATE(U32,"_",V32)) -> - | X32: 0.043
A33: Un.Serv. | B33: 18 | C33: 065 | D33: Maipú | E33: 613136 | F33: 0 | G33: 0065DC0702 | H33: Oficial | I33: CENTRO DE EDUCACIÓN PRIMARIA DE ADULTOS | J33: SEDE | L33: CENTRO DE ADULTOS Nº702"CECILIA MARCHETTI DE BASUALDO SILVA" | M33: Rural Agrupado | N33: No | O33: Educación de Jóvenes y Adultos | P33: Nivel Primario | Q33: 36 | R33: 5 | S33: 0 | T33: Prim. NO EPA | V33: =+IF(U33="","",IF(U33="FINES",CONCATENATE("R",IF(OR(B33="16",B33="21",B33="22",B33="23"),"16212223",IF(OR(B33="15",B33="17",B33="24",B33="25"),"15172425",B33))),IF(U33="CEBAS","UNICO",IF(VALUE(B33)<=11,"AMBA","INTERIOR")))) | W33: =+IF(U33="","-",CONCATENATE(U33,"_",V33)) -> - | X33: 0.045
A34: Un.Serv. | B34: 04 | C34: 032 | D34: Florencio Varela | E34: 608848 | F34: 1 | G34: 0032DC0710 | H34: Oficial | I34: CENTRO DE EDUCACIÓN PRIMARIA DE ADULTOS | J34: EXTENSION | K34: 0032DE0702 | L34: CENTRO DE ADULTOS Nº710/02 | M34: Urbano | N34: No | O34: Educación de Jóvenes y Adultos | P34: Nivel Primario | Q34: 38 | R34: 3 | S34: 0 | T34: Prim. NO EPA | V34: =+IF(U34="","",IF(U34="FINES",CONCATENATE("R",IF(OR(B34="16",B34="21",B34="22",B34="23"),"16212223",IF(OR(B34="15",B34="17",B34="24",B34="25"),"15172425",B34))),IF(U34="CEBAS","UNICO",IF(VALUE(B34)<=11,"AMBA","INTERIOR")))) | W34: =+IF(U34="","-",CONCATENATE(U34,"_",V34)) -> - | X34: 0.046
A35: Un.Serv. | B35: 03 | C35: 069 | D35: La Matanza | E35: 614422 | F35: 0 | G35: 0069DA0064 | H35: Oficial | I35: CENTRO DE ALFABETIZACIÓN | J35: SEDE | L35: CENTRO DE ALFABETIZACION Nº64 | M35: Urbano | N35: Sí | O35: Educación de Jóvenes y Adultos | P35: Nivel Primario | Q35: 6 | R35: 1 | S35: 0 | T35: Prim. NO EPA | V35: =+IF(U35="","",IF(U35="FINES",CONCATENATE("R",IF(OR(B35="16",B35="21",B35="22",B35="23"),"16212223",IF(OR(B35="15",B35="17",B35="24",B35="25"),"15172425",B35))),IF(U35="CEBAS","UNICO",IF(VALUE(B35)<=11,"AMBA","INTERIOR")))) | W35: =+IF(U35="","-",CONCATENATE(U35,"_",V35)) -> - | X35: 0.05
A36: Un.Serv. | B36: 06 | C36: 109 | D36: Vicente López | E36: 614402 | F36: 0 | G36: 0109DA0043 | H36: Oficial | I36: CENTRO DE ALFABETIZACIÓN | J36: SEDE | L36: CENTRO DE ALFABETIZACIÓN Nº 43 | M36: Urbano | N36: No | O36: Educación de Jóvenes y Adultos | P36: Nivel Primario | Q36: 14 | R36: 1 | S36: 0 | T36: Prim. NO EPA | V36: =+IF(U36="","",IF(U36="FINES",CONCATENATE("R",IF(OR(B36="16",B36="21",B36="22",B36="23"),"16212223",IF(OR(B36="15",B36="17",B36="24",B36="25"),"15172425",B36))),IF(U36="CEBAS","UNICO",IF(VALUE(B36)<=11,"AMBA","INTERIOR")))) | W36: =+IF(U36="","-",CONCATENATE(U36,"_",V36)) -> - | X36: 0.05
A37: Un.Serv. | B37: 06 | C37: 096 | D37: San Isidro | E37: 612075 | F37: 3 | G37: 0096DC0712 | H37: Oficial | I37: CENTRO DE EDUCACIÓN PRIMARIA DE ADULTOS | J37: EXTENSION | K37: 0096DE0702 | L37: CENTRO DE ADULTOS Nº712/02 | M37: Urbano | N37: No | O37: Educación de Jóvenes y Adultos | P37: Nivel Primario | Q37: 31 | R37: 2 | S37: 0 | T37: Prim. NO EPA | V37: =+IF(U37="","",IF(U37="FINES",CONCATENATE("R",IF(OR(B37="16",B37="21",B37="22",B37="23"),"16212223",IF(OR(B37="15",B37="17",B37="24",B37="25"),"15172425",B37))),IF(U37="CEBAS","UNICO",IF(VALUE(B37)<=11,"AMBA","INTERIOR")))) | W37: =+IF(U37="","-",CONCATENATE(U37,"_",V37)) -> - | X37: 0.05
A38: Un.Serv. | B38: 03 | C38: 069 | D38: La Matanza | E38: 612438 | F38: 1 | G38: 0069DC0701 | H38: Oficial | I38: CENTRO DE EDUCACIÓN PRIMARIA DE ADULTOS | J38: EXTENSION | K38: 0069DE0717 | L38: CENTRO DE ADULTOS Nº701/17 | M38: Urbano | N38: No | O38: Educación de Jóvenes y Adultos | P38: Nivel Primario | Q38: 24 | R38: 2 | S38: 0 | T38: Prim. NO EPA | V38: =+IF(U38="","",IF(U38="FINES",CONCATENATE("R",IF(OR(B38="16",B38="21",B38="22",B38="23"),"16212223",IF(OR(B38="15",B38="17",B38="24",B38="25"),"15172425",B38))),IF(U38="CEBAS","UNICO",IF(VALUE(B38)<=11,"AMBA","INTERIOR")))) | W38: =+IF(U38="","-",CONCATENATE(U38,"_",V38)) -> - | X38: 0.051
A39: Un.Serv. | B39: 03 | C39: 069 | D39: La Matanza | E39: 614426 | F39: 0 | G39: 0069DA0066 | H39: Oficial | I39: CENTRO DE ALFABETIZACIÓN | J39: SEDE | L39: CENTRO DE ALFABETIZACION Nº66 | M39: Urbano | N39: Sí | O39: Educación de Jóvenes y Adultos | P39: Nivel Primario | Q39: 15 | R39: 1 | S39: 0 | T39: Prim. NO EPA | V39: =+IF(U39="","",IF(U39="FINES",CONCATENATE("R",IF(OR(B39="16",B39="21",B39="22",B39="23"),"16212223",IF(OR(B39="15",B39="17",B39="24",B39="25"),"15172425",B39))),IF(U39="CEBAS","UNICO",IF(VALUE(B39)<=11,"AMBA","INTERIOR")))) | W39: =+IF(U39="","-",CONCATENATE(U39,"_",V39)) -> - | X39: 0.051
A40: Un.Serv. | B40: 05 | C40: 004 | D40: Almirante Brown | E40: 604372 | F40: 1 | G40: 0004DC0718 | H40: Oficial | I40: CENTRO DE EDUCACIÓN PRIMARIA DE ADULTOS | J40: EXTENSION | K40: 0004DE0704 | L40: CENTRO DE ADULTOS Nº718/04 | M40: Urbano | N40: No | O40: Educación de Jóvenes y Adultos | P40: Nivel Primario | Q40: 43 | R40: 2 | S40: 0 | T40: Prim. NO EPA | V40: =+IF(U40="","",IF(U40="FINES",CONCATENATE("R",IF(OR(B40="16",B40="21",B40="22",B40="23"),"16212223",IF(OR(B40="15",B40="17",B40="24",B40="25"),"15172425",B40))),IF(U40="CEBAS","UNICO",IF(VALUE(B40)<=11,"AMBA","INTERIOR")))) | W40: =+IF(U40="","-",CONCATENATE(U40,"_",V40)) -> - | X40: 0.052
...

Sheet Estratos
K1: Oferta | L1: Muestra (estud.) por estrato geográfico | N1: Universo | Q1: Muestra (Aprox.)
B2: unidades | C2: secciones | D2: matrícula | E2: error_% | F2: deff | G2: secciones (5 ExS) | H2: unidades | I2: tamaño muestra (z=90%, p=50%, deff=2) | N2: Unidades de Servicio | O2: Secciones | P2: Estudiantes | Q2: Unidades de Servicio | R2: Secciones | S2: Estudiantes
A3: EPA_AMBA | B3: =+COUNTIF(Nómina!W:W,A3) -> 225 | C3: =+SUMIF(Nómina!W:W,A3,Nómina!R:R) -> 2238 | D3: =+SUMIF(Nómina!W:W,A3,Nómina!Q:Q) -> 31241 | E3: 3 | F3: 2 | G3: =+MIN(C3,I3/5) -> 293.61434 | H3: =MIN(B3,G3/C3*B3) -> 29.518868 | I3: =+(D3*POWER(1.645,2)*(0.5*0.5))/(POWER(E3/100,2)*(D3-1)+POWER(1.645,2)*(0.5*0.5))*F3 -> 1468.0717 | K3: EPA | L3: x Zona (2) | M3: 1500 | N3: =+COUNTIF(Nómina!U:U,Estratos!K3) -> 334 | O3: =+SUMIF(Nómina!U:U,Estratos!K3,Nómina!R:R) -> 2921 | P3: =+SUMIF(Nómina!U:U,Estratos!K3,Nómina!Q:Q) -> 40995 | Q3: =+H3+H4 -> 74.073748 | R3: =+G3+G4 -> 572.79767 | S3: =+I3+I4 -> 2863.9883
A4: EPA_INTERIOR | B4: =+COUNTIF(Nómina!W:W,A4) -> 109 | C4: =+SUMIF(Nómina!W:W,A4,Nómina!R:R) -> 683 | D4: =+SUMIF(Nómina!W:W,A4,Nómina!Q:Q) -> 9754 | E4: 3 | F4: 2 | G4: =+MIN(C4,I4/5) -> 279.18333 | H4: =MIN(B4,G4/C4*B4) -> 44.55488 | I4: =+(D4*POWER(1.645,2)*(0.5*0.5))/(POWER(E4/100,2)*(D4-1)+POWER(1.645,2)*(0.5*0.5))*F4 -> 1395.9167 | K4: CEBAS | L4: Único | M4: 500 | N4: =+COUNTIF(Nómina!U:U,Estratos!K4) -> 20 | O4: =+SUMIF(Nómina!U:U,Estratos!K4,Nómina!R:R) -> 90 | P4: =+SUMIF(Nómina!U:U,Estratos!K4,Nómina!Q:Q) -> 1590 | Q4: =+H5 -> 20 | R4: =+G5 -> 90 | S4: =+I5 -> 765.90839
A5: CEBAS_UNICO | B5: =+COUNTIF(Nómina!W:W,A5) -> 20 | C5: =+SUMIF(Nómina!W:W,A5,Nómina!R:R) -> 90 | D5: =+SUMIF(Nómina!W:W,A5,Nómina!Q:Q) -> 1590 | E5: 3 | F5: 1.5 | G5: =+MIN(C5,I5/5) -> 90 | H5: =MIN(B5,G5/C5*B5) -> 20 | I5: =+(D5*POWER(1.645,2)*(0.5*0.5))/(POWER(E5/100,2)*(D5-1)+POWER(1.645,2)*(0.5*0.5))*F5 -> 765.90839 | K5: CENS | L5: x Zona (2) | M5: 1500 | N5: =+COUNTIF(Nómina!U:U,Estratos!K5) -> 534 | O5: =+SUMIF(Nómina!U:U,Estratos!K5,Nómina!R:R) -> 4404 | P5: =+SUMIF(Nómina!U:U,Estratos!K5,Nómina!Q:Q) -> 80793 | Q5: =+H6+H7 -> 75.005257 | R5: =+G6+G7 -> 587.91427 | S5: =+I6+I7 -> 2939.5714
A6: CENS_AMBA | B6: =+COUNTIF(Nómina!W:W,A6) -> 354 | C6: =+SUMIF(Nómina!W:W,A6,Nómina!R:R) -> 3144 | D6: =+SUMIF(Nómina!W:W,A6,Nómina!Q:Q) -> 57989 | E6: 3 | F6: 2 | G6: =+MIN(C6,I6/5) -> 296.82699 | H6: =MIN(B6,G6/C6*B6) -> 33.421359 | I6: =+(D6*POWER(1.645,2)*(0.5*0.5))/(POWER(E6/100,2)*(D6-1)+POWER(1.645,2)*(0.5*0.5))*F6 -> 1484.1349 | K6: FINES | L6: x Región (17)- Grupo (2) | M6: 370-530 | N6: =+COUNTIF(Nómina!U:U,Estratos!K6) -> 2190 | O6: =+SUMIF(Nómina!U:U,Estratos!K6,Nómina!R:R) -> 3728 | P6: =+SUMIF(Nómina!U:U,Estratos!K6,Nómina!Q:Q) -> 75049 | Q6: =+SUM(H8:H26) -> 911.41662 | R6: =+SUM(G8:G26) -> 1454.6634 | S6: =+SUM(I8:I26) -> 7321.0965
A7: CENS_INTERIOR | B7: =+COUNTIF(Nómina!W:W,A7) -> 180 | C7: =+SUMIF(Nómina!W:W,A7,Nómina!R:R) -> 1260 | D7: =+SUMIF(Nómina!W:W,A7,Nómina!Q:Q) -> 22804 | E7: 3 | F7: 2 | G7: =+MIN(C7,I7/5) -> 291.08729 | H7: =MIN(B7,G7/C7*B7) -> 41.583898 | I7: =+(D7*POWER(1.645,2)*(0.5*0.5))/(POWER(E7/100,2)*(D7-1)+POWER(1.645,2)*(0.5*0.5))*F7 -> 1455.4364 | K7: Total | L7: - | M7: - | N7: =+SUM(N3:N6) -> 3078 | O7: =+SUM(O3:O6) -> 11143 | P7: =+SUM(P3:P6) -> 198427 | Q7: =+SUM(Q3:Q6) -> 1080.4956 | R7: =+SUM(R3:R6) -> 2705.3754 | S7: =+SUM(S3:S6) -> 13890.565
A8: FINES_R01 | B8: =+COUNTIF(Nómina!W:W,A8) -> 172 | C8: =+SUMIF(Nómina!W:W,A8,Nómina!R:R) -> 250 | D8: =+SUMIF(Nómina!W:W,A8,Nómina!Q:Q) -> 4188 | E8: 5 | F8: 1.5 | G8: =+MIN(C8,I8/5) -> 76.270816 | H8: =MIN(B8,G8/C8*B8) -> 52.474322 | I8: =+(D8*POWER(1.645,2)*(0.5*0.5))/(POWER(E8/100,2)*(D8-1)+POWER(1.645,2)*(0.5*0.5))*F8 -> 381.35408
A9: FINES_R02 | B9: =+COUNTIF(Nómina!W:W,A9) -> 191 | C9: =+SUMIF(Nómina!W:W,A9,Nómina!R:R) -> 308 | D9: =+SUMIF(Nómina!W:W,A9,Nómina!Q:Q) -> 5612 | E9: 5 | F9: 1.5 | G9: =+MIN(C9,I9/5) -> 77.459565 | H9: =MIN(B9,G9/C9*B9) -> 48.03499 | I9: =+(D9*POWER(1.645,2)*(0.5*0.5))/(POWER(E9/100,2)*(D9-1)+POWER(1.645,2)*(0.5*0.5))*F9 -> 387.29782
A10: FINES_R03 | B10: =+COUNTIF(Nómina!W:W,A10) -> 234 | C10: =+SUMIF(Nómina!W:W,A10,Nómina!R:R) -> 482 | D10: =+SUMIF(Nómina!W:W,A10,Nómina!Q:Q) -> 10911 | E10: 5 | F10: 1.5 | G10: =+MIN(C10,I10/5) -> 79.223205 | H10: =MIN(B10,G10/C10*B10) -> 38.461058 | I10: =+(D10*POWER(1.645,2)*(0.5*0.5))/(POWER(E10/100,2)*(D10-1)+POWER(1.645,2)*(0.5*0.5))*F10 -> 396.11602
A11: FINES_R04 | B11: =+COUNTIF(Nómina!W:W,A11) -> 181 | C11: =+SUMIF(Nómina!W:W,A11,Nómina!R:R) -> 317 | D11: =+SUMIF(Nómina!W:W,A11,Nómina!Q:Q) -> 6828 | E11: 5 | F11: 1.5 | G11: =+MIN(C11,I11/5) -> 78.097098 | H11: =MIN(B11,G11/C11*B11) -> 44.591719 | I11: =+(D11*POWER(1.645,2)*(0.5*0.5))/(POWER(E11/100,2)*(D11-1)+POWER(1.645,2)*(0.5*0.5))*F11 -> 390.48549
A12: FINES_R05 | B12: =+COUNTIF(Nómina!W:W,A12) -> 215 | C12: =+SUMIF(Nómina!W:W,A12,Nómina!R:R) -> 471 | D12: =+SUMIF(Nómina!W:W,A12,Nómina!Q:Q) -> 10881 | E12: 5 | F12: 1.5 | G12: =+MIN(C12,I12/5) -> 79.217938 | H12: =MIN(B12,G12/C12*B12) -> 36.161055 | I12: =+(D12*POWER(1.645,2)*(0.5*0.5))/(POWER(E12/100,2)*(D12-1)+POWER(1.645,2)*(0.5*0.5))*F12 -> 396.08969
A13: FINES_R06 | B13: =+COUNTIF(Nómina!W:W,A13) -> 57 | C13: =+SUMIF(Nómina!W:W,A13,Nómina!R:R) -> 80 | D13: =+SUMIF(Nómina!W:W,A13,Nómina!Q:Q) -> 1212 | E13: 5 | F13: 1.5 | G13: =+MIN(C13,I13/5) -> 66.408547 | H13: =MIN(B13,G13/C13*B13) -> 47.31609 | I13: =+(D13*POWER(1.645,2)*(0.5*0.5))/(POWER(E13/100,2)*(D13-1)+POWER(1.645,2)*(0.5*0.5))*F13 -> 332.04273
A14: FINES_R07 | B14: =+COUNTIF(Nómina!W:W,A14) -> 87 | C14: =+SUMIF(Nómina!W:W,A14,Nómina!R:R) -> 119 | D14: =+SUMIF(Nómina!W:W,A14,Nómina!Q:Q) -> 1867 | E14: 5 | F14: 1.5 | G14: =+MIN(C14,I14/5) -> 70.937135 | H14: =MIN(B14,G14/C14*B14) -> 51.861603 | I14: =+(D14*POWER(1.645,2)*(0.5*0.5))/(POWER(E14/100,2)*(D14-1)+POWER(1.645,2)*(0.5*0.5))*F14 -> 354.68568
A15: FINES_R08 | B15: =+COUNTIF(Nómina!W:W,A15) -> 102 | C15: =+SUMIF(Nómina!W:W,A15,Nómina!R:R) -> 221 | D15: =+SUMIF(Nómina!W:W,A15,Nómina!Q:Q) -> 4512 | E15: 5 | F15: 1.5 | G15: =+MIN(C15,I15/5) -> 76.603512 | H15: =MIN(B15,G15/C15*B15) -> 35.355467 | I15: =+(D15*POWER(1.645,2)*(0.5*0.5))/(POWER(E15/100,2)*(D15-1)+POWER(1.645,2)*(0.5*0.5))*F15 -> 383.01756
A16: FINES_R09 | B16: =+COUNTIF(Nómina!W:W,A16) -> 109 | C16: =+SUMIF(Nómina!W:W,A16,Nómina!R:R) -> 188 | D16: =+SUMIF(Nómina!W:W,A16,Nómina!Q:Q) -> 4902 | E16: 5 | F16: 1.5 | G16: =+MIN(C16,I16/5) -> 76.94869 | H16: =MIN(B16,G16/C16*B16) -> 44.613868 | I16: =+(D16*POWER(1.645,2)*(0.5*0.5))/(POWER(E16/100,2)*(D16-1)+POWER(1.645,2)*(0.5*0.5))*F16 -> 384.74345
A17: FINES_R10 | B17: =+COUNTIF(Nómina!W:W,A17) -> 136 | C17: =+SUMIF(Nómina!W:W,A17,Nómina!R:R) -> 185 | D17: =+SUMIF(Nómina!W:W,A17,Nómina!Q:Q) -> 3176 | E17: 5 | F17: 1.5 | G17: =+MIN(C17,I17/5) -> 74.828731 | H17: =MIN(B17,G17/C17*B17) -> 55.009229 | I17: =+(D17*POWER(1.645,2)*(0.5*0.5))/(POWER(E17/100,2)*(D17-1)+POWER(1.645,2)*(0.5*0.5))*F17 -> 374.14365
A18: FINES_R11 | B18: =+COUNTIF(Nómina!W:W,A18) -> 104 | C18: =+SUMIF(Nómina!W:W,A18,Nómina!R:R) -> 215 | D18: =+SUMIF(Nómina!W:W,A18,Nómina!Q:Q) -> 4932 | E18: 5 | F18: 1.5 | G18: =+MIN(C18,I18/5) -> 76.973098 | H18: =MIN(B18,G18/C18*B18) -> 37.233499 | I18: =+(D18*POWER(1.645,2)*(0.5*0.5))/(POWER(E18/100,2)*(D18-1)+POWER(1.645,2)*(0.5*0.5))*F18 -> 384.86549
A19: FINES_R12 | B19: =+COUNTIF(Nómina!W:W,A19) -> 48 | C19: =+SUMIF(Nómina!W:W,A19,Nómina!R:R) -> 68 | D19: =+SUMIF(Nómina!W:W,A19,Nómina!Q:Q) -> 1374 | E19: 5 | F19: 1.5 | G19: =+MIN(C19,I19/5) -> 67.864554 | H19: =MIN(B19,G19/C19*B19) -> 47.904391 | I19: =+(D19*POWER(1.645,2)*(0.5*0.5))/(POWER(E19/100,2)*(D19-1)+POWER(1.645,2)*(0.5*0.5))*F19 -> 339.32277
... A26: FINES_R15172425 | B26: =+COUNTIF(Nómina!W:W,A26) -> 114 | C26: =+SUMIF(Nómina!W:W,A26,Nómina!R:R) -> 153 | D26: =+SUMIF(Nómina!W:W,A26,Nómina!Q:Q) -> 2445 | E26: 4 | F26: 1.5 | G26: =+MIN(C26,I26/5) -> 108.18127 | H26: =MIN(B26,G26/C26*B26) -> 80.605651 | I26: =+(D26*POWER(1.645,2)*(0.5*0.5))/(POWER(E26/100,2)*(D26-1)+POWER(1.645,2)*(0.5*0.5))*F26 -> 540.90634

Sheet Fines-Sedes
A1: Región Educativa | B1: Código Distrito DGCyE | C1: Nombre de Distrito - Partido | D1: Sede | E1: COMISIONES | F1: ESTUDIANTES | G1: R | H1: Distrito | K1: distrito | L1: Región Educativa | M1: Código Distrito DGCyE | N1: Nombre de Distrito - Partido
A2: =+VLOOKUP(H2,$K:$N,2,FALSE) -> 01 | B2: =+VLOOKUP(H2,$K:$N,3,FALSE) -> 113 | C2: =+VLOOKUP(H2,$K:$N,4,FALSE) -> Berisso | D2: AGRUPACIÓN MARÍA ROLDÁN | E2: 1 | F2: 18 | G2: 1 | H2: BERISSO | K2: BERISSO | L2: 01 | M2: 113 | N2: Berisso
A3: =+VLOOKUP(H3,$K:$N,2,FALSE) -> 01 | B3: =+VLOOKUP(H3,$K:$N,3,FALSE) -> 113 | C3: =+VLOOKUP(H3,$K:$N,4,FALSE) -> Berisso | D3: C.Cultural y Polideportvo Papa Francisco S/N Berisso | E3: 1 | F3: 17 | G3: 1 | H3: BERISSO | K3: Coronel Brandsen | L3: 01 | M3: 014 | N3: Brandsen
A4: =+VLOOKUP(H4,$K:$N,2,FALSE) -> 01 | B4: =+VLOOKUP(H4,$K:$N,3,FALSE) -> 113 | C4: =+VLOOKUP(H4,$K:$N,4,FALSE) -> Berisso | D4: Casa Nuestra Patria | E4: 3 | F4: 69 | G4: 1 | H4: BERISSO | K4: Ensenada | L4: 01 | M4: 114 | N4: Ensenada
A5: =+VLOOKUP(H5,$K:$N,2,FALSE) -> 01 | B5: =+VLOOKUP(H5,$K:$N,3,FALSE) -> 113 | C5: =+VLOOKUP(H5,$K:$N,4,FALSE) -> Berisso | D5: CENTRO CULTURAL LA 163 | E5: 1 | F5: 22 | G5: 1 | H5: BERISSO | K5: La Plata | L5: 01 | M5: 001 | N5: La Plata
A6: =+VLOOKUP(H6,$K:$N,2,FALSE) -> 01 | B6: =+VLOOKUP(H6,$K:$N,3,FALSE) -> 113 | C6: =+VLOOKUP(H6,$K:$N,4,FALSE) -> Berisso | D6: CIC Barrio Obrero | E6: 1 | F6: 19 | G6: 1 | H6: BERISSO | K6: Magdalena | L6: 01 | M6: 064 | N6: Magdalena
A7: =+VLOOKUP(H7,$K:$N,2,FALSE) -> 01 | B7: =+VLOOKUP(H7,$K:$N,3,FALSE) -> 113 | C7: =+VLOOKUP(H7,$K:$N,4,FALSE) -> Berisso | D7: Club El Carmen | E7: 1 | F7: 13 | G7: 1 | H7: BERISSO | K7: Punta Indio | L7: 01 | M7: 134 | N7: Punta Indio
A8: =+VLOOKUP(H8,$K:$N,2,FALSE) -> 01 | B8: =+VLOOKUP(H8,$K:$N,3,FALSE) -> 113 | C8: =+VLOOKUP(H8,$K:$N,4,FALSE) -> Berisso | D8: Club Villa Nueva | E8: 1 | F8: 18 | G8: 1 | H8: BERISSO | K8: Avellaneda | L8: 02 | M8: 005 | N8: Avellaneda
A9: =+VLOOKUP(H9,$K:$N,2,FALSE) -> 01 | B9: =+VLOOKUP(H9,$K:$N,3,FALSE) -> 113 | C9: =+VLOOKUP(H9,$K:$N,4,FALSE) -> Berisso | D9: Club Villa Paula s/n Berisso | E9: 1 | F9: 27 | G9: 1 | H9: BERISSO | K9: Lanús | L9: 02 | M9: 111 | N9: Lanús
A10: =+VLOOKUP(H10,$K:$N,2,FALSE) -> 01 | B10: =+VLOOKUP(H10,$K:$N,3,FALSE) -> 113 | C10: =+VLOOKUP(H10,$K:$N,4,FALSE) -> Berisso | D10: CLUB VILLA PROGRESO | E10: 1 | F10: 14 | G10: 1 | H10: BERISSO | K10: Lomas de Zamora | L10: 02 | M10: 062 | N10: Lomas de Zamora
A11: =+VLOOKUP(H11,$K:$N,2,FALSE) -> 01 | B11: =+VLOOKUP(H11,$K:$N,3,FALSE) -> 113 | C11: =+VLOOKUP(H11,$K:$N,4,FALSE) -> Berisso | D11: COMEDOR LOS PEQUES S/N Berisso | E11: 1 | F11: 20 | G11: 1 | H11: BERISSO | K11: La Matanza 1 | L11: 03 | M11: 069 | N11: La Matanza
A12: =+VLOOKUP(H12,$K:$N,2,FALSE) -> 01 | B12: =+VLOOKUP(H12,$K:$N,3,FALSE) -> 113 | C12: =+VLOOKUP(H12,$K:$N,4,FALSE) -> Berisso | D12: Comedor Rayito de Luz | E12: 2 | F12: 37 | G12: 1 | H12: BERISSO | K12: La Matanza 2 | L12: 03 | M12: 069 | N12: La Matanza
A13: =+VLOOKUP(H13,$K:$N,2,FALSE) -> 01 | B13: =+VLOOKUP(H13,$K:$N,3,FALSE) -> 113 | C13: =+VLOOKUP(H13,$K:$N,4,FALSE) -> Berisso | D13: Construyendo Futuro | E13: 2 | F13: 26 | G13: 1 | H13: BERISSO | K13: La Matanza 3 | L13: 03 | M13: 069 | N13: La Matanza
... A78: =+VLOOKUP(H78,$K:$N,2,FALSE) -> 01 | B78: =+VLOOKUP(H78,$K:$N,3,FALSE) -> 001 | C78: =+VLOOKUP(H78,$K:$N,4,FALSE) -> La Plata | D78: Centro Sicardi S/N La Plata Parque Sicardi | E78: 1 | F78: 0 | G78: 1 | H78: La Plata | K78: General Villegas | L78: 16 | M78: 049 | N78: General Villegas
A79: =+VLOOKUP(H79,$K:$N,2,FALSE) -> 01 | B79: =+VLOOKUP(H79,$K:$N,3,FALSE) -> 001 | C79: =+VLOOKUP(H79,$K:$N,4,FALSE) -> La Plata | D79: CFL 428 | E79: 1 | F79: 13 | G79: 1 | H79: La Plata | L79: 16 | M79: 080 | N79: Pellegrini
A80: =+VLOOKUP(H80,$K:$N,2,FALSE) -> 01 | B80: =+VLOOKUP(H80,$K:$N,3,FALSE) -> 001 | C80: =+VLOOKUP(H80,$K:$N,4,FALSE) -> La Plata | D80: CFL N°424 S/N LA PLATA CENTRO | E80: 1 | F80: 0 | G80: 1 | H80: La Plata | K80: Rivadavia | L80: 16 | M80: 088 | N80: Rivadavia
A81: =+VLOOKUP(H81,$K:$N,2,FALSE) -> 01 | B81: =+VLOOKUP(H81,$K:$N,3,FALSE) -> 001 | C81: =+VLOOKUP(H81,$K:$N,4,FALSE) -> La Plata | D81: CFP 428 (Centro de Formación Profesional 428) | E81: 2 | F81: 35 | G81: 1 | H81: La Plata | K81: Saliquello | L81: 16 | M81: 120 | N81: Salliqueló
A82: =+VLOOKUP(H82,$K:$N,2,FALSE) -> 01 | B82: =+VLOOKUP(H82,$K:$N,3,FALSE) -> 001 | C82: =+VLOOKUP(H82,$K:$N,4,FALSE) -> La Plata | D82: CIC El Retiro | E82: 1 | F82: 5 | G82: 1 | H82: La Plata | K82: Trenque Lauquen | L82: 16 | M82: 106 | N82: Trenque Lauquen
A83: =+VLOOKUP(H83,$K:$N,2,FALSE) -> 01 | B83: =+VLOOKUP(H83,$K:$N,3,FALSE) -> 001 | C83: =+VLOOKUP(H83,$K:$N,4,FALSE) -> La Plata | D83: Club Corazones del Retiro S/N La Plata Olmos | E83: 1 | F83: 24 | G83: 1 | H83: La Plata | K83: Tres Lomas | L83: 16 | M83: 127 | N83: Tres Lomas
A84: =+VLOOKUP(H84,$K:$N,2,FALSE) -> 01 | B84: =+VLOOKUP(H84,$K:$N,3,FALSE) -> 001 | C84: =+VLOOKUP(H84,$K:$N,4,FALSE) -> La Plata | D84: CLUB DEPORTIVO Y BIBLIOTECA POPULAR ROMERENSE | E84: 1 | F84: 20 | G84: 1 | H84: La Plata | K84: Chascomús | L84: 17 | M84: 027 | N84: Chascomús
A85: =+VLOOKUP(H85,$K:$N,2,FALSE) -> 01 | B85: =+VLOOKUP(H85,$K:$N,3,FALSE) -> 001 | C85: =+VLOOKUP(H85,$K:$N,4,FALSE) -> La Plata | D85: CLUB LAS QUINTAS | E85: 2 | F85: 19 | G85: 1 | H85: La Plata | K85: General Belgrano | L85: 17 | M85: 036 | N85: General Belgrano
A86: =+VLOOKUP(H86,$K:$N,2,FALSE) -> 01 | B86: =+VLOOKUP(H86,$K:$N,3,FALSE) -> 001 | C86: =+VLOOKUP(H86,$K:$N,4,FALSE) -> La Plata | D86: CLUB LOS ABUELOS | E86: 1 | F86: 27 | G86: 1 | H86: La Plata | K86: General Paz | L86: 17 | M86: 041 | N86: General Paz
A87: =+VLOOKUP(H87,$K:$N,2,FALSE) -> 01 | B87: =+VLOOKUP(H87,$K:$N,3,FALSE) -> 001 | C87: =+VLOOKUP(H87,$K:$N,4,FALSE) -> La Plata | D87: Club Provincia | E87: 3 | F87: 65 | G87: 1 | H87: La Plata | K87: Lezama | L87: 17 | M87: 137 | N87: Lezama
A88: =+VLOOKUP(H88,$K:$N,2,FALSE) -> 01 | B88: =+VLOOKUP(H88,$K:$N,3,FALSE) -> 001 | C88: =+VLOOKUP(H88,$K:$N,4,FALSE) -> La Plata | D88: COLECTIVO LA CASA | E88: 1 | F88: 17 | G88: 1 | H88: La Plata | K88: Monte | L88: 17 | M88: 072 | N88: Monte
A89: =+VLOOKUP(H89,$K:$N,2,FALSE) -> 01 | B89: =+VLOOKUP(H89,$K:$N,3,FALSE) -> 001 | C89: =+VLOOKUP(H89,$K:$N,4,FALSE) -> La Plata | D89: COMEDOR CORAZONES CONTENTOS DEL KM 52 | E89: 1 | F89: 8 | G89: 1 | H89: La Plata | K89: Pila | L89: 17 | M89: 082 | N89: Pila
A90: =+VLOOKUP(H90,$K:$N,2,FALSE) -> 01 | B90: =+VLOOKUP(H90,$K:$N,3,FALSE) -> 001 | C90: =+VLOOKUP(H90,$K:$N,4,FALSE) -> La Plata | D90: COMEDOR LOS PIRULINES | E90: 1 | F90: 11 | G90: 1 | H90: La Plata | K90: Rauch | L90: 17 | M90: 087 | N90: Rauch
A91: =+VLOOKUP(H91,$K:$N,2,FALSE) -> 01 | B91: =+VLOOKUP(H91,$K:$N,3,FALSE) -> 001 | C91: =+VLOOKUP(H91,$K:$N,4,FALSE) -> La Plata | D91: COMEDOR PAN DE VIDA | E91: 1 | F91: 10 | G91: 1 | H91: La Plata | K91: Ayacucho | L91: 18 | M91: 006 | N91: Ayacucho
... A117: =+VLOOKUP(H117,$K:$N,2,FALSE) -> 01 | B117: =+VLOOKUP(H117,$K:$N,3,FALSE) -> 001 | C117: =+VLOOKUP(H117,$K:$N,4,FALSE) -> La Plata | D117: GIMNASIA Y ESGRIMA LA PLATA | E117: 3 | F117: 68 | G117: 1 | H117: La Plata | K117: Coronel Rosales | L117: 22 | M117: 112 | N117: Coronel de Marina L. Rosales
A118: =+VLOOKUP(H118,$K:$N,2,FALSE) -> 01 | B118: =+VLOOKUP(H118,$K:$N,3,FALSE) -> 001 | C118: =+VLOOKUP(H118,$K:$N,4,FALSE) -> La Plata | D118: HOSPITAL REENCUENTRO | E118: 1 | F118: 11 | G118: 1 | H118: La Plata | L118: 22 | M118: 126 | N118: Monte Hermoso
A119: =+VLOOKUP(H119,$K:$N,2,FALSE) -> 01 | B119: =+VLOOKUP(H119,$K:$N,3,FALSE) -> 001 | C119: =+VLOOKUP(H119,$K:$N,4,FALSE) -> La Plata | D119: JIRONES DE MI BARRIO - CLUB PARAGUAYO | E119: 3 | F119: 64 | G119: 1 | H119: La Plata | K119: Cármen de Patagones | L119: 22 | M119: 078 | N119: Patagones
A120: =+VLOOKUP(H120,$K:$N,2,FALSE) -> 01 | B120: =+VLOOKUP(H120,$K:$N,3,FALSE) -> 001 | C120: =+VLOOKUP(H120,$K:$N,4,FALSE) -> La Plata | D120: LA CASITA | E120: 1 | F120: 36 | G120: 1 | H120: La Plata | K120: Villarino | L120: 22 | M120: 110 | N120: Villarino
A121: =+VLOOKUP(H121,$K:$N,2,FALSE) -> 01 | B121: =+VLOOKUP(H121,$K:$N,3,FALSE) -> 001 | C121: =+VLOOKUP(H121,$K:$N,4,FALSE) -> La Plata | D121: LA HERMOSURA S/N La Plata La Hermosura | E121: 1 | F121: 0 | G121: 1 | H121: La Plata | K121: Adolfo Alsina | L121: 23 | M121: 002 | N121: Adolfo Alsina
A122: =+VLOOKUP(H122,$K:$N,2,FALSE) -> 01 | B122: =+VLOOKUP(H122,$K:$N,3,FALSE) -> 001 | C122: =+VLOOKUP(H122,$K:$N,4,FALSE) -> La Plata | D122: LA LIBERTAD FUTURA MOVIMIENTO UNIDAD POPULAR (MUP) | E122: 1 | F122: 16 | G122: 1 | H122: La Plata | K122: Coronel Suarez | L122: 23 | M122: 025 | N122: Coronel Suárez
A123: =+VLOOKUP(H123,$K:$N,2,FALSE) -> 01 | B123: =+VLOOKUP(H123,$K:$N,3,FALSE) -> 001 | C123: =+VLOOKUP(H123,$K:$N,4,FALSE) -> La Plata | D123: LA MILITANTE | E123: 2 | F123: 45 | G123: 1 | H123: La Plata | K123: Daireaux | L123: 23 | M123: 020 | N123: Daireaux
A124: =+VLOOKUP(H124,$K:$N,2,FALSE) -> 01 | B124: =+VLOOKUP(H124,$K:$N,3,FALSE) -> 001 | C124: =+VLOOKUP(H124,$K:$N,4,FALSE) -> La Plata | D124: LOS LIBROS NO MUERDEN | E124: 1 | F124: 15 | G124: 1 | H124: La Plata | K124: General Lamadrid | L124: 23 | M124: 038 | N124: General La Madrid
A125: =+VLOOKUP(H125,$K:$N,2,FALSE) -> 01 | B125: =+VLOOKUP(H125,$K:$N,3,FALSE) -> 001 | C125: =+VLOOKUP(H125,$K:$N,4,FALSE) -> La Plata | D125: MALVINAS ARGENTINAS S/N La Plata Los Hornos | E125: 1 | F125: 16 | G125: 1 | H125: La Plata | K125: Guamini | L125: 23 | M125: 051 | N125: Guaminí
A126: =+VLOOKUP(H126,$K:$N,2,FALSE) -> 01 | B126: =+VLOOKUP(H126,$K:$N,3,FALSE) -> 001 | C126: =+VLOOKUP(H126,$K:$N,4,FALSE) -> La Plata | D126: Mary Sanchez | E126: 3 | F126: 62 | G126: 1 | H126: La Plata | K126: Puan | L126: 23 | M126: 084 | N126: Puan
A127: =+VLOOKUP(H127,$K:$N,2,FALSE) -> 01 | B127: =+VLOOKUP(H127,$K:$N,3,FALSE) -> 001 | C127: =+VLOOKUP(H127,$K:$N,4,FALSE) -> La Plata | D127: Mary Sanchez S/N La Plata El Rincón | E127: 1 | F127: 14 | G127: 1 | H127: La Plata | K127: Saavedra | L127: 23 | M127: 091 | N127: Saavedra
A128: =+VLOOKUP(H128,$K:$N,2,FALSE) -> 01 | B128: =+VLOOKUP(H128,$K:$N,3,FALSE) -> 001 | C128: =+VLOOKUP(H128,$K:$N,4,FALSE) -> La Plata | D128: ME VERÁS VOLVER | E128: 1 | F128: 21 | G128: 1 | H128: La Plata | K128: Tornquist | L128: 23 | M128: 105 | N128: Tornquist
A129: =+VLOOKUP(H129,$K:$N,2,FALSE) -> 01 | B129: =+VLOOKUP(H129,$K:$N,3,FALSE) -> 001 | C129: =+VLOOKUP(H129,$K:$N,4,FALSE) -> La Plata | D129: Néstor y Cristina | E129: 1 | F129: 16 | G129: 1 | H129: La Plata | K129: 25 de mayo | L129: 24 | M129: 108 | N129: 25 de Mayo
...
